Workbook
Name \E: #REF!
Name \E: #REF!
Name \E: #REF!
Name \E: #REF!
Name \E: #REF!
Name _____________________MS798: #REF!
Name _____________________MS798: #REF!
Name _____________________tab1: #REF!
Name _____________________tab2: #REF!
Name _____________________tab6798: #REF!
Name ____________________MS798: #REF!
Name ____________________tab1: #REF!
Name ____________________tab2: #REF!
Name ____________________tab6798: #REF!
Name ___________________MS798: #REF!
Name ___________________tab1: #REF!
Name ___________________tab2: #REF!
Name ___________________tab6798: #REF!
Name __________________MS798: #REF!
Name __________________tab1: #REF!
Name __________________tab2: #REF!
Name __________________tab6798: #REF!
Name _________________MS798: #REF!
Name _________________prt1: #N/A
Name _________________prt2: #N/A
Name _________________prt3: #N/A
Name _________________prt4: #N/A
Name _________________prt5: #N/A
Name _________________prt6: #N/A
Name _________________prt7: #N/A
Name _________________prt8: #N/A
Name _________________tab1: #REF!
Name _________________tab2: #REF!
Name _________________tab6798: #REF!
Name ________________MS798: #REF!
Name ________________prt1: #N/A
Name ________________prt2: #N/A
Name ________________prt3: #N/A
Name ________________prt4: #N/A
Name ________________prt5: #N/A
Name ________________prt6: #N/A
Name ________________prt7: #N/A
Name ________________prt8: #N/A
Name ________________tab1: #REF!
Name ________________tab2: #REF!
Name ________________tab6798: #REF!
Name _______________MS798: #REF!
Name _______________prt1: #N/A
Name _______________prt2: #N/A
Name _______________prt3: #N/A
Name _______________prt4: #N/A
Name _______________prt5: #N/A
Name _______________prt6: #N/A
Name _______________prt7: #N/A
Name _______________prt8: #N/A
Name _______________tab1: #REF!
Name _______________tab2: #REF!
Name _______________tab6798: #REF!
Name ______________MS798: #REF!
Name ______________prt1: #N/A

Sheet табл 1
A1: 1-кесте | J1: Таблица 1
A3: НЕГІЗГІ МАКРОЭКОНОМИКАЛЫҚ ИНДИКАТОРЛАР/
A4: ОСНОВНЫЕ МАКРОЭКОНОМИЧЕСКИЕ ИНДИКАТОРЫ
A6: Атауы | B6: 2019 жыл/ 2019 год | C6: 2020 жыл/ 2020 год | D6: 2021 жыл/ 2021 год | E6: 2022 жыл/ 2022 год | F6: 2023 жыл/ 2023 год | G6: 2024 жыл/ 2024 год | H6: 2025 жыл/ 2025 год | I6: 2026 ж. 1 маусымдағы есеп/ отчет на 1 июня 2026 г. | J6: Наименование
A7: 1 | B7: 2 | C7: 3 | D7: 4 | E7: 5 | F7: 6 | G7: 7 | H7: 8 | I7: 9 | J7: 10
A8: Жалпы ішкi өнiм, млрд. теңге | B8: 69532.626 | C8: 70649 | D8: 83951.587 | E8: 65487.797 | F8: 120561.1 | G8: 84962.621 | H8: 99724.898 | I8: 34102.358 | J8: Валовой внутренний продукт, млрд.тенге январь-март 2026 года (оперативные данные)
A9: өткен жылдың тиiстi кезеңiндегi нақты есептеудегi %-бен | B9: 104.5 | C9: 97.5 | D9: 103.3 | E9: 103 | F9: 105.1 | G9: 104.1 | H9: 106.3 | I9: 112.1 | J9: в % к соответствующему периоду предыдущего года
A10: Өнеркәсiп өнiмiнiң көлемi, млрд. теңге | B10: 29380.342 | C10: 26743.4 | D10: 37047.6 | E10: 4157.4 | F10: 46401.716 | G10: 50124.86 | H10: 61560.646 | I10: 27940.9 | J10: Объем промышленного производства, млрд.тенге (январь-май 2026г.)
A11: өткен жылдың тиiстi кезеңiне %-бен | B11: 104.1 | C11: 99.3 | D11: 103.8 | E11: 97.2 | F11: 104.3 | G11: 102.8 | H11: 107.5 | I11: 117.4 | J11: % май 2026г. к маю 2025г.
A12: Мембюджетке кірістер, млрд. теңге | B12: 12758.479 | C12: 14521.191 | D12: 15847.431 | E12: 20248.101 | F12: 24917.246 | G12: ='[46]табл 2 '!C8/1000 -> 27132.165 | H12: ='[47]табл 2 '!C8/1000 -> 29871.048 | I12: ='табл 3'!F8/1000 -> 12850.266 | J12: Доходы в госбюджет, млрд.тенге
A13: ЖIӨ-ге %-бен | B13: 18.502241 | C13: 20.535071 | D13: =D12/D8*100 -> 18.876869 | E13: =E12/E8*100 -> 30.918891 | G13: =G12/G8*100 -> 31.934237 | H13: =H12/H8*100 -> 29.95345 | I13: =I12/I8*100 -> 37.681458 | J13: в % к ВВП
A14: Мембюджеттен шығындар, млрд. теңге | B14: 13535.581 | C14: 16725.097 | D14: 17951.888 | E14: 21532.543 | F14: 26760 | G14: ='[46]табл 2 '!C18/1000 -> 30318.236 | H14: ='[47]табл 2 '!C18/1000 -> 33442.829 | I14: ='табл 3'!F19/1000 -> 13931.236 | J14: Затраты из госбюджета, млрд. тенге
A15: ЖIӨ-ге %-бен | B15: 19.629188 | C15: 23.651714 | D15: =D14/D8*100 -> 21.38362 | E15: =E14/E8*100 -> 32.880238 | F15: 35.421743 | G15: =G14/G8*100 -> 35.684206 | H15: =H14/H8*100 -> 33.535084 | I15: =I14/I8*100 -> 40.85124 | J15: в % к ВВП
A16: Таза бюджеттік кредит беру, млрд. теңге | B16: 262.88084 | C16: 261.98101 | D16: 267.33754 | E16: 592.68034 | F16: 466.44174 | G16: ='[46]табл 2 '!C34/1000 -> 198.40855 | H16: ='[47]табл 3'!E34/1000 -> 286.23027 | I16: ='табл 3'!F34/1000 -> 72.885574 | J16: Чистое бюджетное кредитование, млрд. тенге
A17: ЖIӨ-ге %-бен | B17: 0.38122761 | C17: 0.37047917 | D17: =D16/D8*100 -> 0.31844251 | E17: =E16/E8*100 -> 0.9050241 | F17: 0.61742075 | G17: =G16/G8*100 -> 0.23352452 | H17: =H16/H8*100 -> 0.28701987 | I17: =I16/I8*100 -> 0.21372591 | J17: в % к ВВП
A18: Қаржылық активтермен болатын операциялар бойынша сальдо, млрд. теңге | B18: 245.32373 | C18: 340.26326 | D18: 163.01136 | E18: 292.00158 | F18: 501.9047 | G18: ='[46]табл 2 '!C37/1000 -> 201.56181 | H18: ='[47]табл 3'!E37/1000 -> 525.85985 | I18: ='табл 3'!F37/1000 -> 368.00864 | J18: Сальдо по операциям с финансовыми активами, млрд.тенге
A19: ЖIӨ-ге %-бен | B19: 0.35576643 | C19: 0.48118163 | D19: =D18/D8*100 -> 0.19417306 | E19: =E18/E8*100 -> 0.44588701 | F19: 0.66436244 | G19: =G18/G8*100 -> 0.23723586 | H19: =H18/H8*100 -> 0.52731049 | I19: =I18/I8*100 -> 1.0791296 | J19: в % к ВВП
A20: Мембюджеттiң тапшылығы (-) / профицитi (+), млрд. теңге | B20: -1285.3067 | C20: -2806.1502 | D20: -2534.8062 | E20: -2169.1247 | F20: -2811.1006 | G20: ='[46]табл 2 '!C40/1000 -> -3586.0419 | H20: ='[47]табл 3'!E40/1000 -> -4383.8711 | I20: ='табл 3'!F40/1000 -> -1521.8643 | J20: Дефицит (-) / профицит (+) госбюджета, млрд.тенге
A21: ЖIӨ-ге %-бен | B21: -1.8639412 | C21: -3.9683036 | D21: =D20/D8*100 -> -3.0193666 | E21: =E20/E8*100 -> -3.3122579 | F21: -3.7210045 | G21: =G20/G8*100 -> -4.2207288 | H21: =H20/H8*100 -> -4.3959645 | I21: =I20/I8*100 -> -4.4626366 | J21: в % к ВВП
A22: Тұтыну бағаларының индексі өткен жылдың айына, %-бен | B22: 105.4 | C22: 107.5 | D22: 108.4 | E22: 120.3 | F22: 109.5 | G22: 108.9 | H22: 112.2 | I22: 100.7 | J22: Индекс потребительских цен май 2026 к апрелю 2026, в %
A23: Тұтыну бағасының индексі 2026 жылғы мамыр 2025 жылғы мамырға % | B23: 105.3 | C23: 106.8 | D23: 108 | E23: 115 | G23: 108.6 | H23: 103.9 | I23: 110.4 | J23: Индекс потребительских цен в % май 2026г. к маю 2025г.
A24: Орташа айлық атаулы жалақы 1 қызметкердың, теңге | B24: 186815 | C24: 220848 | D24: 268051 | E24: 303055 | F24: 350542 | G24: 390328 | H24: 429368 | I24: 461486 | J24: Среднемесячная номинальная заработная плата 1 работника, тенге (1 квартал 2026г.)
A25: өткен жылдың тиiстi кезеңiне %-бен | B25: 114.8 | C25: 104.4 | D25: 115.3 | E25: 112.2 | F25: 116.9 | G25: 111.3 | H25: 110 | I25: =I24/'[48]табл 1'!$H$24*100 -> 109.06405 | J25: в % к соответствующему периоду предыдущего года
A26: Экспорт, млн. АҚШ долл. | B26: 58065.6 | C26: 46 949,7 2 | D26: 54549.5 | E26: ____ | F26: 71274.7 | G26: 73884.5 | H26: 71135.7 | I26: 24005.8 | J26: Экспорт, млн. долл. США (январь -апрель 2026г.)
A27: Импорт, млн. АҚШ долл. | B27: 39709.3 | C27: 38 081,4 2 | D27: 36825.9 | E27: ____ | F27: 54643.5 | G27: 53590.3 | H27: 57666.9 | I27: 20860.1 | J27: Импорт, млн. долл. США (январь -апрель 2026г.)
A28: Сауда балансының сальдосы, млн. АҚШ долл. | B28: 18356.3 | C28: 8969 | D28: 17723.6 | E28: ____ | F28: 16631.2 | G28: =G26-G27 -> 20294.2 | H28: =H26-H27 -> 13468.8 | I28: =I26-I27 -> 3145.7 | J28: Сальдо торгового баланса, млн. долл. США
A29: Теңгенiң АҚШ долларына қарағандағы ресми айырбас бағамы: | J29: Официальный обменный курс тенге к доллару США:
A30: кезеңнiң аяғындағы | B30: 381.18 | C30: 420.71 | D30: 433.83 | E30: 459.92 | F30: 448.17 | G30: 525.11 | H30: 521.59 | I30: 485.95 | J30: на конец периода
A31: кезең бойынша орташа | B31: 382.75 | C31: 412.95 | D31: 433.66 | E31: 460.48 | F31: 451.28 | G31: 469.44 | H31: 502.57 | I31: 469.52 | J31: в среднем за апрель 2026 года
A33: Ақпарат көзi: / Источник:
A34: Қазақстан Республикасының Қаржы министрлiгi / Министерство финансов Республики Казахстан.
A35: Ұлттық статистика бюросы Қазақстан Республикасының Стратегиялық жоспарлау және реформалар агенттігі / Бюро национальной статистики Агентства по стратегическому планированию и реформам Республики Казахстан
A36: Қазақстан Республикасының Ұлттық Банкi / Национальный Банк Республики Казахстан.
A37: Ескерту: / Примечание:
A38: 1 - Ұлттық статистика бюросы Қазақстан Республикасының Стратегиялық жоспарлау және реформалар агенттігінің деректері бойынша /Объем ВВП по отчетным данным Бюро национальной статистики Агентства по стратегическому планированию и реформам Республики Казахстан
A39: 2 - Ұлттық статистика бюросы Қазақстан Республикасының Стратегиялық жоспарлау және реформалар агенттігінің деректері бойынша /По данным Бюро национальной статистики Агентства по стратегическому планированию и реформам Республики Казахстан
A40: 3 - Ұлттық статистика бюросы Қазақстан Республикасының Стратегиялық жоспарлау және реформалар агенттігінің деректері бойынша /По данным Бюро национальной статистики Агентства по стратегическому планированию и реформам Республики Казахстан

Sheet табл 2 
A1: 2-кесте | F1: Таблица - 2
A2: МЕМЛЕКЕТТІК ЖӘНЕ РЕСПУБЛИКАЛЫҚ | F2: СРАВНИТЕЛЬНЫЙ АНАЛИЗ ИСПОЛНЕНИЯ
A3: БЮДЖЕТТЕР АТҚАРЫЛУЫНЫҢ САЛЫСТЫРМА ТАЛДАУЫ | F3: ГОСУДАРСТВЕННОГО И РЕСПУБЛИКАНСКОГО БЮДЖЕТОВ
A5: Атауы | B5: Мемлекеттік бюджет / Государственный бюджет | F5: Республикалық бюджет / Республиканский бюджет | J5: Наименование
B6: 2026 жылға түзету енгізілген бюджет (млн. теңге)/ скорректированный бюджет на 2026 год (млн.тенге) | C6: 2026 жылғы қаңтар-мамыр атқарылуы (млн. теңге)/ исполнение за январь-май 2026 года (млн.тенге) | D6: бір жылға түзету енгізілген бюджеттің атқарылу %-ы/% исполнения к скорректированному бюджету на год | E6: 2025 ж. қаңтар-мамыр %-бен 2026 ж. қаңтар-мамырға/ 2026 г. январь-май в % к январю-маю 2025 г. | F6: 2026 жылға түзету енгізілген бюджет (млн. теңге)/ скорректированный бюджет на 2026 год (млн.тенге) | G6: 2026 жылғы қаңтар-мамыр атқарылуы (млн. теңге)/ исполнение за январь-май 2026 года (млн.тенге) | H6: бір жылға түзету енгізілген бюджеттің атқарылу %-ы/% исполнения к скорректированному бюджету на год | I6: 2025 ж. қаңтар-мамыр %-бен 2026 ж. қаңтар-мамырға/ 2026 г. январь-май в % к январю-маю 2025 г.
A7: 1 | B7: 2 | C7: 3 | D7: 4 | E7: 5 | F7: 6 | G7: 7 | H7: 8 | I7: 9 | J7: 10
A8: I. КІРІСТЕР | B8: 32595214 | C8: 12850266 | D8: 39.423781 | E8: 102.87612 | F8: 22889278 | G8: 9274897.4 | H8: 40.520707 | I8: 104.9946 | J8: I. ДОХОДЫ
A9: Салықтық түсімдер оның iшiнде: | B9: 28803380 | C9: 10934491 | D9: 37.962527 | E9: 118.00339 | F9: 18886019 | G9: 7235595.1 | H9: 38.311913 | I9: 130.77279 | J9: Налоговые поступления, в том числе:
A10: корпоративтік табыс салығы | B10: 7052619.7 | C10: 2792155.8 | D10: 39.590335 | E10: 107.2416 | F10: 5184046.5 | G10: 1989979.1 | H10: 38.386597 | I10: 115.96667 | J10: корпоративный подоходный налог
A11: жеке табыс салығы | B11: 3343772.5 | C11: 1181317.1 | D11: 35.328871 | E11: 101.37343 | F11: 0 | G11: 0 | H11: 0 | I11: 0 | J11: индивидуальный подоходный налог
A12: әлеуметтік салық | B12: 2083926.1 | C12: 750548.39 | D12: 36.016075 | E12: 98.96408 | F12: 0 | G12: 0 | H12: 0 | I12: 0 | J12: социальный налог
A13: қосылған құн салығы | B13: 10013329 | C13: 3478321.8 | D13: 34.736917 | E13: 145.08643 | F13: 10013329 | G13: 3478321.8 | H13: 34.736917 | I13: 145.08643 | J13: налог на добавленную стоимость
A14: акциздер | B14: 1507461 | C14: 460822.23 | D14: 30.56943 | E14: 126.01888 | F14: 151773.43 | G14: 40188.696 | H14: 26.479402 | I14: 92.43793 | J14: акцизы
A15: Салықтық емес түсімдер | B15: 527175.03 | C15: 348407.06 | D15: 66.089448 | E15: 64.97376 | F15: 330736.78 | G15: 166208.9 | H15: 50.254132 | I15: 45.955827 | J15: Неналоговые поступления
A16: Негізгі капиталды сатудан түсетін түсімдер | B16: 295162.2 | C16: 81992.019 | D16: 27.778631 | E16: 119.64271 | F16: 2200 | G16: 336.64101 | H16: 15.301864 | I16: 16.324382 | J16: Поступления от продажи основного капитала
A17: Арнаулы түсімдер | B17: 199496.78 | C17: 85375.84 | D17: 42.795599 | E17: 3.25862 | F17: 20375.447 | G17: 2956.7177 | H17: 14.51118 | I17: - | J17: Специальные поступления
A18: Трансферттердің түсімдері | B18: 2770000 | C18: 1400000 | D18: 50.541516 | F18: 3649947.1 | G18: 1869800 | H18: 51.228141 | I18: 64.005904 | J18: Поступление трансфертов
A19: II. ШЫҒЫНДАР | B19: 36127255 | C19: 13931236 | D19: 38.561568 | E19: 112.57501 | F19: 26229339 | G19: 10685592 | H19: 40.739081 | I19: 108.86884 | J19: II. ЗАТРАТЫ
A20: 1. Жалпы сипаттағы мемлекеттiк қызметтер | B20: 1847945.7 | C20: 738617.43 | D20: 39.96965 | E20: 109.3537 | F20: 1408505.7 | G20: 571419.31 | H20: 40.569187 | I20: 121.88474 | J20: 1. Государственные услуги общего характера
A21: 2. Қорғаныс | B21: 1533775.1 | C21: 622741.13 | D21: 40.601855 | E21: 164.51074 | F21: 1429833.1 | G21: 599415.83 | H21: 41.922083 | I21: 177.9997 | J21: 2. Оборона
A22: 3. Қоғамдық тәртіп, қауіпсіздік, құқықтық, сот, қылмыстық-атқару қызметі | B22: 2000594.7 | C22: 717030.51 | D22: 35.840868 | E22: 116.07031 | F22: 1508680.1 | G22: 552374.09 | H22: 36.61307 | I22: 115.85955 | J22: 3. Общественный порядок, безопасность, правовая, судебная, уголовно-исполнительная деятельность
A23: 4. Бiлiм беру | B23: 6977302.7 | C23: 2774244.2 | D23: 39.760983 | E23: 102.238 | F23: 812871.93 | G23: 366510.83 | H23: 45.088386 | I23: 63.55734 | J23: 4. Образование
A24: 5. Денсаулық сақтау | B24: 3136489.7 | C24: 830024.66 | D24: 26.463491 | E24: 99.80772 | F24: 2731840.1 | G24: 723858.65 | H24: 26.497109 | I24: 100.16304 | J24: 5. Здравоохранение
A25: 6. Әлеуметтiк көмек және әлеуметтiк қамсыздандыру | B25: 7655001.5 | C25: 3094131.7 | D25: 40.41974 | E25: 112.65131 | F25: 6833009.5 | G25: 2816153.4 | H25: 41.213954 | I25: 112.93067 | J25: 6. Социальная помощь и социальное обеспечение
A26: 7. Тұрғын үй-коммуналдық шаруашылық | B26: 2550842.1 | C26: 832391.34 | D26: 32.632022 | E26: 123.96272 | F26: 95156.925 | G26: 49346.534 | H26: 51.858059 | I26: 106.94321 | J26: 7. Жилищно-коммунальное хозяйство
A27: 8. Мәдениет, спорт, туризм және ақпараттық кеңістiк | B27: 1214367.5 | C27: 448527.42 | D27: 36.935066 | E27: 102.26704 | F27: 255564.15 | G27: 99073.716 | H27: 38.766672 | I27: 96.79936 | J27: 8. Культура, спорт, туризм и информационное пространство
A28: 9. Отын-энергетика кешенi және жер қойнауын пайдалану | B28: 272478.82 | C28: 114624.48 | D28: 42.067297 | E28: 89.5271 | F28: 128415.45 | G28: 55210.115 | H28: 42.993359 | I28: 206.42543 | J28: 9. Топливно-энергетический комплекс и недропользование
A29: 10. Ауыл, су, орман, балық шаруашылығы, ерекше қорғалатын табиғи аумақтар, қоршаған ортаны және жануарлар дүниесін қорғау, жер қатынастары | B29: 1670662 | C29: 647862.45 | D29: 38.778785 | E29: 118.5852 | F29: 726167.55 | G29: 143968.72 | H29: 19.825826 | I29: 77.64323 | J29: 10. Сельское, водное, лесное, рыбное хозяйство, особо охраняемые природные территории, охрана окружающей среды и животного мира, земельные отношения
A30: 11. Өнеркәсіп, сәулет, қала құрылысы және құрылыс қызметі | B30: 119643.71 | C30: 33910.076 | D30: 28.342548 | E30: 108.13405 | F30: 29050.311 | G30: 10133.974 | H30: 34.88422 | I30: 167.79044 | J30: 11. Промышленность, архитектурная, градостроительная и строительная деятельность
... A33: 14. Борышқа қызмет көрсету | B33: 3571288.8 | C33: 1929720.7 | D33: 54.034294 | E33: 121.98683 | F33: 3471233.6 | G33: 1919783.1 | H33: 55.305498 | I33: 121.66719 | J33: 14. Обслуживание долга
F34: 5171567.8 | G34: 2246604.3 | H34: 43.441454 | I34: 97.91699 | J34: 15. Трансферты
A35: III. ТАЗА БЮДЖЕТТІК КРЕДИТ БЕРУ | B35: 1075013.8 | C35: 72885.574 | D35: 6.7799662 | E35: 70.85502 | F35: 858213.36 | G35: 63234.322 | H35: 7.3681353 | I35: 263.10765 | J35: III. ЧИСТОЕ БЮДЖЕТНОЕ КРЕДИТОВАНИЕ
A36: Бюджеттік кредиттер | B36: 1344317.2 | C36: 218468.24 | D36: 16.251241 | E36: 100.79866 | F36: 1104500 | G36: 195550 | H36: 17.704844 | I36: 118.51515 | J36: Бюджетные кредиты
A37: Бюджеттік кредиттерді өтеу | B37: 269303.42 | C37: 145582.66 | D37: 54.058973 | E37: 127.84826 | F37: 246286.64 | G37: 132315.68 | H37: 53.724262 | I37: 106.08165 | J37: Погашение бюджетных кредитов
A38: IV. ҚАРЖЫ АКТИВТЕРІМЕН ОПЕРАЦИЯЛАР БОЙЫНША САЛЬДО - ҚАРЖЫ АК | B38: 600857.61 | C38: 368008.64 | D38: 61.24723 | E38: 180.83272 | F38: 396775.84 | G38: 215316.48 | H38: 54.266529 | I38: 1127.6382 | J38: IV. САЛЬДО ПО ОПЕРАЦИЯМ С ФИНАНСОВЫМИ АКТИВАМИ
A39: Қаржылық активтерді сатып алу | B39: 601350.99 | C39: 369712.47 | D39: 61.480312 | E39: 180.97895 | F39: 396775.84 | G39: 215316.48 | H39: 54.266529 | I39: 1127.6382 | J39: Приобретение финансовых активов
A40: Мемлекеттің қаржы активтерін сатудан түсетін түсімдер | B40: 493.382 | C40: 1703.8294 | D40: 345.33676 | E40: 219.27772 | F40: 0 | G40: 0 | H40: 0 | I40: - | J40: Поступления от продажи финансовых активов государства
A41: V. БЮДЖЕТ ТАПШЫЛЫҒЫ (ПРОФИЦИТІ) | B41: -5207912.7 | C41: -1521864.3 | D41: 29.222155 | E41: -799.1591 | F41: -4595050.1 | G41: -1689245.1 | H41: 36.762277 | I41: -163.64577 | J41: V. ДЕФИЦИТ (ПРОФИЦИТ) БЮДЖЕТА
A42: VI. БЮДЖЕТТІҢ МҰНАЙҒА ҚАТЫСТЫ ЕМЕС ТАПШЫЛЫҒЫ (ПРОФИЦИТІ) | B42: -9672432.7 | C42: -3547363 | D42: 36.674982 | E42: -104.88381 | F42: -9059570.1 | G42: -3714743.7 | H42: 41.003532 | I42: -87.94359 | J42: VI. НЕНЕФТЯНОЙ ДЕФИЦИТ (ПРОФИЦИТ) БЮДЖЕТА

Sheet табл 3
A1: 3-кесте | E1: Таблица 3
A2: МЕМЛЕКЕТТІК БЮДЖЕТТІҢ АТҚАРЫЛУЫ | E2: ИСПОЛНЕНИЕ ГОСУДАРСТВЕННОГО БЮДЖЕТА
A3: (млн.теңге) | E3: (млн. тенге)
A5: Атауы | B5: 2023 ж. есеп/ 2023 г. отчет | C5: 2024 ж. есеп/ 2024 г. отчет | D5: 2025 ж. есеп/ 2025 г. отчет | F5: 2026 ж. қантар-мамыр есеп/январь-май отчет 2026 г. | G5: Наименование
D6: жылдық/ годовой | E6: қантар-мамыр/январь-май
A7: 1 | B7: 2 | C7: 3 | D7: 4 | E7: 5 | F7: 6 | G7: 7
A8: I. КІРІСТЕР | B8: 24917246 | C8: 27132165 | D8: 29871048 | E8: 12491010 | F8: 12850266 | G8: I. ДОХОДЫ
A9: Салықтық түсімдер_x000D_ оның iшiнде: | B9: 18912204 | C9: 19700517 | D9: 23188179 | E9: 9266251.9 | F9: 10934491 | G9: Налоговые поступления,_x000D_ в том числе:
A10: корпоративтік табыс салығы | B10: 5045696.1 | C10: 5213291.4 | D10: 6322629 | E10: 2603612.6 | F10: 2792155.8 | G10: корпоративный подоходный налог
A11: жеке табыс салығы | B11: 1992384.9 | C11: 2451640 | D11: 2859192.4 | E11: 1165312.4 | F11: 1181317.1 | G11: индивидуальный подоходный налог
A12: әлеуметтік салық | B12: 1321272.8 | C12: 1579329.4 | D12: 1866744.5 | E12: 758404.89 | F12: 750548.39 | G12: социальный налог
A13: қосылған құн салығы | B13: 5674110.6 | C13: 5179378.1 | D13: 6111842.3 | E13: 2397413.6 | F13: 3478321.8 | G13: налог на добавленную стоимость
A14: акциздер | B14: 840215.7 | C14: 844909.98 | D14: 1039998.8 | E14: 365677.15 | F14: 460822.23 | G14: акцизы
A15: Салықтық емес түсімдер | B15: 1822932.9 | C15: 1630378.8 | D15: 1248358.7 | E15: 536227.33 | F15: 348407.06 | G15: Неналоговые поступления
A16: Негізгі капиталды сатудан түсетін түсімдер | B16: 182108.73 | C16: 201680.05 | D16: 184510.46 | E16: 68530.725 | F16: 81992.019 | G16: Поступления от продажи основного капитала
A17: Арнаулы түсімдер | B17: 0 | C17: 0 | D17: 0 | E17: 0 | F17: 85375.84 | G17: Специальные поступления
A18: Трансферттердің түсімдері | B18: 4000000 | C18: 6006003.1 | D18: 5250000 | E18: 2620000 | F18: 1400000 | G18: Поступления трансфертов
A19: II. ШЫҒЫНДАР | B19: 26760000 | C19: 30318236 | D19: 33442829 | E19: 12375070 | F19: 13931236 | G19: II. ЗАТРАТЫ
... A42: VII. БЮДЖЕТТІҢ ТАПШЫЛЫҒЫН ҚАРЖЫЛАНДЫРУ (ПРОФИЦИТТІ ПАЙДАЛАНУ | B42: 2811100.6 | C42: 3586041.9 | D42: 4383871.1 | E42: 190433.21 | F42: 1521864.3 | G42: VII. ФИНАНСИРОВАНИЕ ДЕФИЦИТА (ИСПОЛЬЗОВАНИЕ ПРОФИЦИТА) БЮДЖЕТА
A43: Ішкі | B43: 3221830.7 | C43: 3293971.1 | D43: 3860967 | E43: 334870.2 | F43: =F44-F45 -> 1870582.2 | G43: Внутреннее
A44: Түсімдер | B44: 5179541.7 | C44: 5785457.6 | D44: 6463366.7 | E44: 1825284.4 | F44: 2916535.1 | G44: Поступление
A45: Өтеу | B45: 1957711 | C45: 2491486.6 | D45: 2602399.7 | E45: 1490414.2 | F45: 1045952.8 | G45: Погашение
A46: Сыртқы | B46: -410730.11 | C46: 292070.8 | D46: 522904.09 | E46: -144436.99 | F46: =F47-F48 -> 79954.511 | G46: Внешнее
A47: Түсімдер | B47: 251872.16 | C47: 1447223.5 | D47: 2231117.1 | E47: 77013.789 | F47: 251761.07 | G47: Поступление
A48: Өтеу | B48: 662602.27 | C48: 1155152.7 | D48: 1708213 | E48: 221450.78 | F48: 171806.56 | G48: Погашение

Sheet табл 4
A1: 4-кесте | G1: Таблица 4
A3: МЕМЛЕКЕТТІК БЮДЖЕТКЕ ТҮСІМДЕР/_x000D_ ПОСТУПЛЕНИЯ В ГОСУДАРСТВЕННЫЙ БЮДЖЕТ
A5: (млн.теңге) | G5: (млн.тенге)
A7: Санаты/ Категория | B7: Сыныбы/ Класс | C7: Сыныпшасы/ Подкласс | D7: Ерешелігі/ Специфика | E7: Атауы | F7: 2026 ж. қаңтар-мамыр есеп/_x000D_ январь-май отчет 2026 г. | G7: Наименование
A8: 1 | B8: 2 | C8: 3 | D8: 4 | E8: 5 | F8: 6 | G8: 7
E9: ТҮСІМДЕР | F9: 12997552 | G9: ПОСТУПЛЕНИЯ
E10: оның ішінде: | G10: в том числе:
E11: КІРІСТЕР | F11: 12850266 | G11: ДОХОДЫ
A12: 1 | B12: L01 Класс дохода | C12: L01 Подкласс дохода | D12: L01 Специфика дохода | E12: Салықтық түсімдер | F12: 10934491 | G12: Налоговые поступления
A13: L01 Категория дохода | B13: 01 | C13: L01 Подкласс дохода | D13: L01 Специфика дохода | E13: Табыс салығы | F13: 3973472.8 | G13: Подоходный налог
A14: L01 Категория дохода | B14: L01 Класс дохода | C14: 1 | D14: L01 Специфика дохода | E14: Корпоративтік табыс салығы | F14: 2792155.8 | G14: Корпоративный подоходный налог
A15: 1 | B15: 01 | C15: 1 | D15: 10 | E15: Мұнай секторы ұйымдарынан түсетін түсімдерді қоспағанда, ірі кәсіпкерлік субъектілерінен – заңды тұлғалардан алынатын корпоративтік табыс салығы | F15: 1989979.1 | G15: Корпоративный подоходный налог с юридических лиц – субъектов крупного предпринимательства, за исключением поступлений от организаций нефтяного сектора
D16: 11 | E16: Ірі кәсіпкерлік субъектілерінен және мұнай секторы ұйымдарынан түсетін түсімдерді қоспағанда, заңды тұлғалардан алынатын корпоративтік табыс салығы | F16: 802176.71 | G16: Корпоративный подоходный налог с юридических лиц, за исключением поступлений от субъектов крупного предпринимательства и организаций нефтяного сектора
A17: L01 Категория дохода | B17: L01 Класс дохода | C17: 2 | D17: L01 Специфика дохода | E17: Жеке табыс салығы | F17: 1181317.1 | G17: Индивидуальный подоходный налог
C18: 2 | D18: 01 | E18: Төлем көзінен салық салынатын табыстардан ұсталатын жеке табыс салығы | F18: 856330.71 | G18: Индивидуальный подоходный налог с доходов, облагаемых у источника выплаты
D19: 02 | E19: Төлем көзінен салық салынбайтын табыстардан ұсталатын жеке табыс салығы | F19: 310089.31 | G19: Индивидуальный подоходный налог с доходов, не облагаемых у источника выплаты
D20: 05 | E20: Төлем көзінен салық салынбайтын шетелдік азаматтар табыстарынан ұсталатын жеке табыс салығы | F20: 14897.062 | G20: Индивидуальный подоходный налог с доходов иностранных граждан, не облагаемых у источника выплаты
A21: L01 Категория дохода | B21: 03 | C21: L01 Подкласс дохода | D21: L01 Специфика дохода | E21: Әлеуметтiк салық | F21: 750548.39 | G21: Социальный налог
A22: L01 Категория дохода | B22: L01 Класс дохода | C22: 1 | D22: L01 Специфика дохода | E22: Әлеуметтік салық | F22: 750548.39 | G22: Социальный налог
B23: 03 | C23: 1 | D23: 01 | E23: Әлеуметтік салық | F23: 750548.39 | G23: Социальный налог
A24: L01 Категория дохода | B24: 04 | C24: L01 Подкласс дохода | D24: L01 Специфика дохода | E24: Меншiкке салынатын салықтар | F24: 380713.25 | G24: Hалоги на собственность
A25: L01 Категория дохода | B25: L01 Класс дохода | C25: 1 | D25: L01 Специфика дохода | E25: Мүлiкке салынатын салықтар | F25: 257451.24 | G25: Налоги на имущество
B26: 04 | C26: 1 | D26: 01 | E26: Заңды тұлғалардың және жеке кәсіпкерлердің мүлкіне салынатын салық | F26: 254156.12 | G26: Налог на имущество юридических лиц и индивидуальных предпринимателей
D27: 02 | E27: Жеке тұлғалардың мүлкiне салынатын салық | F27: 3295.1211 | G27: Hалог на имущество физических лиц
A28: L01 Категория дохода | B28: L01 Класс дохода | C28: 3 | D28: L01 Специфика дохода | E28: Жер салығы | F28: 4872.2298 | G28: Земельный налог
C29: 3 | D29: 02 | E29: Жер салығы | F29: 4872.2298 | G29: Земельный налог
A30: L01 Категория дохода | B30: L01 Класс дохода | C30: 4 | D30: L01 Специфика дохода | E30: Көлiк құралдарына салынатын салық | F30: 114612.41 | G30: Налог на транспортные средства
C31: 4 | D31: 01 | E31: Заңды тұлғалардан көлік құралы салығы | F31: 1629.9171 | G31: Hалог на транспортные средства с юридических лиц
D32: 02 | E32: Жеке тұлғалардан көлік құралы салығы | F32: 112982.5 | G32: Hалог на транспортные средства с физических лиц
A33: L01 Категория дохода | B33: L01 Класс дохода | C33: 5 | D33: L01 Специфика дохода | E33: Бірыңғай жер салығы | F33: 3777.3625 | G33: Единый земельный налог
C34: 5 | D34: 01 | E34: Бірыңғай жер салығы | F34: 3777.3625 | G34: Единый земельный налог
A35: L01 Категория дохода | B35: 05 | C35: L01 Подкласс дохода | D35: L01 Специфика дохода | E35: Тауарларға, жұмыстарға және көрсетілетін қызметтерге салынатын iшкi салықтар | F35: 4875987.2 | G35: Внутренние налоги на товары, работы и услуги
A36: L01 Категория дохода | B36: L01 Класс дохода | C36: 1 | D36: L01 Специфика дохода | E36: Қосылған құн салығы | F36: 3478321.8 | G36: Налог на добавленную стоимость
B37: 05 | C37: 1 | D37: 01 | E37: Қазақстан Республикасының аумағында өндiрiлген тауарларға, орындалған жұмыстарға және көрсетілген қызметтерге салынатынқосылған құн салығы | F37: 1741399.1 | G37: Hалог на добавленную стоимость на произведенные товары, выполненные работы и оказанные услуги на территории Республики Казахстан
D38: 02 | E38: Ресей Федерациясы және Беларусь Республикасының аумағынан импортталатын тауарларға салынатын қосылған құн салығынан басқа, Қазақстан Республикасының аумағына импортталатын тауарларға салынатын қосылған құн салығы | F38: 902672.68 | G38: Hалог на добавленную стоимость на товары, импортируемые на территорию Республики Казахстан, кроме налога на добавленнуюстоимость на товары, импортируемые с территории Российской Федерации и Республики Беларусь
D39: 04 | E39: Резидент емес үшін қосылған құн салығы | F39: 139916.8 | G39: Налог на добавленную стоимость за нерезидента
D40: 14 | E40: Салық төлеушінің бұрын бюджеттен қайтарылған және салықтықтексеру жүргізу барысында қайтарылуы расталмаған қосылған құн салығының асып кеткен сомасын аударуы (қайтаруы), өсімпұл сомасын аударуы | F40: 3049.9072 | G40: Перечисление (возврат) налогоплательщиком суммы превышения налога на добавленную стоимость, ранее возвращенной из бюджета и не подтвержденной к возврату при проведении налоговой проверки, перечисление суммы пени
D41: 15 | E41: Еуразиялық экономикалық одаққа мүше мемлекеттер аумағынан импортталған тауарларға қосылған құн салығы | F41: 649992.43 | G41: Налог на добавленную стоимость на товары, импортированные стерритории государств-членов Евразийского экономического союза
D42: 16 | E42: Тауарлармен электрондық сауданы жүзеге асыру, жеке тұлғаларға электрондық нысанда қызметтер көрсету кезінде шетелдік компаниялардан түсетін қосылған құн салығы | F42: 41290.872 | G42: Налог на добавленную стоимость с иностранных интернет компаний при осуществлении электронной торговли товарами, оказании услуг в электронной форме физическим лицам
A43: L01 Категория дохода | B43: L01 Класс дохода | C43: 2 | D43: L01 Специфика дохода | E43: Акциздер | F43: 460822.23 | G43: Акцизы
...

Sheet табл 5
B2: Кесте 5 | D2: Таблица 5
B3: ШЫҒЫСТАРДЫҢ ВЕДОМСТВОЛЫҚ | D3: ИСПОЛНЕНИЕ ГОСУДАРСТВЕННОГО БЮДЖЕТА
B4: СЫНЫПТАМАСЫ БОЙЫНША | D4: ПО ВЕДОМСТВЕННОЙ
B5: МЕМЛЕКЕТТІК БЮДЖЕТТІҢ АТҚАРАЛУЫ | D5: КЛАССИФИКАЦИИ РАСХОДОВ
B6: (млн. теңге) | D6: (млн. тенге)
B8: Бағдарламалард_x000D_ ың_x000D_ əкімшісі/_x000D_ Администратор_x000D_ программ | C8: Атауы | D8: 2026 ж. қаңтар-мамыр есеп/_x000D_ январь-май 2026 г. | E8: Наименование
B9: 1 | C9: 2 | D9: 3 | E9: 4
C10: БАРЛЫҒЫ | D10: 14519417 | E10: ВСЕГО
B11: 101 | C11: Қазақстан Республикасы Президентінің Әкімшілігі | D11: 7885.9139 | E11: Администрация Президента Республики Казахстан
B12: 106 | C12: Адам құқықтары жөніндегі ұлттық орталық | D12: 619.28185 | E12: Национальный центр по правам человека
B13: 107 | C13: Қазақстан Республикасы Жоғары Сот Кеңесінің Аппараты | D13: 825.92672 | E13: Аппарат Высшего Судебного Совета Республики Казахстан
B14: 109 | C14: Қазақстан Республикасы Үкіметінің Аппараты | D14: 3235.3784 | E14: Аппарат Правительства Республики Казахстан
B15: 110 | C15: Облыс мәслихатының аппараты | D15: 1409.0058 | E15: Аппарат маслихата области
B16: 111 | C16: Республикалық маңызы бар қала, астана мәслихатының аппараты | D16: 327.79208 | E16: Аппарат маслихата города республиканского значения, столицы
B17: 112 | C17: Аудан (облыстық маңызы бар қала) мәслихатының аппараты | D17: 5938.5651 | E17: Аппарат маслихата района (города областного значения)
B18: 120 | C18: Облыс әкімінің аппараты | D18: 23132.588 | E18: Аппарат акима области
B19: 121 | C19: Республикалық маңызы бар қала, астана әкімінің аппараты | D19: 5108.0326 | E19: Аппарат акима города республиканского значения, столицы
B20: 122 | C20: Аудан (облыстық маңызы бар қала) әкімінің аппараты | D20: 44309.647 | E20: Аппарат акима района (города областного значения)
B21: 123 | C21: Қаладағы аудан әкімінің аппараты | D21: 142677.88 | E21: Аппарат акима района в городе
B22: 124 | C22: Аудандық маңызы бар қала, ауыл, кент, ауылдық округ әкімінің аппараты | D22: 127073.43 | E22: Аппарат акима города районного значения, села, поселка, сельского округа
... B220: 821 | C220: Ауданның (облыстық маңызы бар қаланың) қоғамдық даму бөлімі | D220: 569.21017 | E220: Отдел общественного развития района (города областного значения)

Sheet табл 6
A1: 6-кесте | D1: Таблица 6
A2: ШЫҒЫНДАРДЫҢ ЭКОНОМИКАЛЫҚ ЖІКТЕМЕСІ | D2: ИСПОЛНЕНИЕ ГОСУДАРСТВЕННОГО БЮДЖЕТА ПО
A3: БОЙЫНША МЕМЛЕКЕТТІК БЮДЖЕТТІК ОРЫНДАЛУЫ | D3: ЭКОНОМИЧЕСКОЙ КЛАССИФИКАЦИИ РАСХОДОВ
A4: (млн.теңге) | D4: (млн.тенге)
A5: Cанаты/_x000D_ Категория | B5: Iшкi сыныбы/_x000D_ Подкласс | C5: Атауы | D5: 2026 ж. қаңтар-мамыр/январь-май отчет 2026 г. | E5: Наименование
A7: 1 | B7: 2 | C7: 3 | D7: 4 | E7: 5
C8: БАРЛЫҒЫ | D8: 14519417 | E8: ВСЕГО
A9: 1 | C9: Ағымдағы шығындар | D9: 12576295 | E9: Текущие затраты
A10: 1 | B10: 110 | C10: Жалақы | D10: 1865904.3 | E10: Заработная плата
B11: 120 | C11: Жұмыс берушілердің жарналары | D11: 187209.15 | E11: Взносы работодателей
B12: 130 | C12: Қазақстан Республикасының заңнамалық актілеріне сәйкес азаматтардың жекелеген санаттарына жалақы төлеу және жарналар аудару | D12: 69623.872 | E12: Выплата заработной платы отдельным категориям граждан и отчисления взносов в соответствии с законодательными актами Республики Казахстан
B13: 140 | C13: Қорлар сатып алу | D13: 154447.44 | E13: Приобретение запасов
B14: 150 | C14: Қызметтер мен жұмыстарды сатып алу | D14: 1930819.3 | E14: Приобретение услуг и работ
B15: 160 | C15: Басқа да ағымдағы шығындар | D15: 1597402.8 | E15: Другие текущие затраты
B16: 210 | C16: Ішкі қарыздар бойынша сыйақы төлемдері | D16: 1804033.3 | E16: Выплаты вознаграждений по внутренним займам
B17: 220 | C17: Сыртқы заемдар бойынша сыйақылар төлеу | D17: 125687.43 | E17: Выплаты вознаграждений по внешним займам
B18: 310 | C18: Бюджеттік субсидиялар | D18: 983962.22 | E18: Бюджетные субсидии
B19: 320 | C19: Жеке тұлғаларға берілетін трансферттер | D19: 3157277.7 | E19: Трансферты физическим лицам
B20: 340 | C20: Шетелге берiлетiн ағымдағы трансферттер | D20: 17644.183 | E20: Текущие трансферты за границу
B21: 360 | C21: Нысаналы жарна | D21: 655858.97 | E21: Целевой взнос
B22: 370 | D22: 26424.348
A23: 2 | C23: Күрделі шығындар | D23: 1217269.1 | E23: Капитальные затраты
A24: 2 | B24: 410 | C24: Негiзгi құралдарды, материалдық емес және биологиялық активтерді сатып алу | D24: 288006.73 | E24: Приобретение основных средств, нематериальных и биологических активов
B25: 420 | C25: Негізгі қаражатты күрделі жөндеу | D25: 84713.349 | E25: Капитальный ремонт основных средств
B26: 430 | C26: Дамуға бағытталған күрделі шығындар | D26: 844548.98 | E26: Капитальные затраты, направленные на развитие
A27: 3 | C27: Бюджеттік кредиттер | D27: 218468.24 | E27: Бюджетные кредиты
A28: 3 | B28: 510 | C28: Ішкі бюджеттік кредиттер | D28: 218468.24 | E28: Внутренние бюджетные кредиты
A29: 4 | C29: Қаржы активтерін сатып алу | D29: 419712.47 | E29: Приобретение финансовых активов
A30: 4 | B30: 610 | C30: Қаржы активтерін сатып алу | D30: 419617.07 | E30: Приобретение финансовых активов
B31: 620 | C31: Елден тысқары жерлерден қаржы активтерін сатып алу | D31: 95.397215 | E31: Приобретение финансовых активов за пределами страны
A32: 6 | C32: Мемлекеттік-жекешелік әріптестік жобалар бойынша мемлекеттік міндеттемелерді орындау | D32: 87671.957 | E32: Выполнение государственных обязательств по проектам государственно-частного партнерства
A33: 6 | B33: 810 | C33: Мемлекеттік концессиялық міндеттемелерді орындау | D33: 87671.957 | E33: Выполнение государственных концессионных обязательств

Sheet табл 7
A1: 7-кесте | E1: Таблица 7
A2: РЕСПУБЛИКАЛЫҚ БЮДЖЕТТІҢ АТҚАРЫЛУЫ | E2: ИСПОЛНЕНИЕ РЕСПУБЛИКАНСКОГО БЮДЖЕТА
A3: (млн.теңге) | E3: (млн. тенге)
A5: Атауы | B5: 2023 ж. есеп/ 2023 г. отчет | C5: 2024 ж. есеп/ 2024 г. отчет | D5: 2025 ж. есеп/ 2025 г. отчет | F5: 2026 ж. қантар-мамыр есеп/январь-май отчет 2026 г. | G5: Наименование
D6: жылдық/ годовой | E6: қантар-мамыр/январь-май
A7: 1 | B7: 2 | C7: 3 | D7: 4 | E7: 5 | F7: 6 | G7: 7
A8: I. КІРІСТЕР | B8: 19037979 | C8: 19624012 | D8: 21090148 | E8: 8842213.2 | F8: 9274897.4 | G8: I. ДОХОДЫ
A9: Салықтық түсімдер_x000D_ оның iшiнде: | B9: 12912428 | C9: 12307810 | D9: 14463081 | E9: 5541693.5 | F9: 7235595.1 | G9: Налоговые поступления,_x000D_ в том числе:
A10: корпоративтік табыс салығы | B10: 3889594.5 | C10: 3653190.8 | D10: 4532987.5 | E10: 1715992.2 | F10: 1989979.1 | G10: корпоративный подоходный налог
A11: қосылған құн салығы | B11: 5674110.6 | C11: 5179378.1 | D11: 6111842.3 | E11: 2397413.6 | F11: 3478321.8 | G11: налог на добавленную стоимость
A12: акциздер | B12: 161890.43 | C12: 125189.66 | D12: 117407.4 | E12: 43476.411 | F12: 40188.696 | G12: акцизы
A13: Салықтық емес түсімдер | B13: 1617610.1 | C13: 1201438.2 | D13: 823130.62 | E13: 377164.44 | F13: 166208.9 | G13: Неналоговые поступления
A14: Негізгі капиталды сатудан түсетін түсімдер | B14: 735.69631 | C14: 6170.4309 | D14: 12039.586 | E14: 2062.1976 | F14: 336.64101 | G14: Поступления от продажи основного капитала
A15: Арнаулы түсімдер | B15: 0 | C15: 0 | D15: 0 | E15: 0 | F15: 2956.7177 | G15: Специальные поступления
A16: Трансферттердің түсімдері | B16: 4507205 | C16: 6108593.6 | D16: 5791896.9 | E16: 2921293.1 | F16: 1869800 | G16: Поступления трансфертов
A17: II. ШЫҒЫНДАР | B17: 21547819 | C17: 23106552 | D17: 24958709 | E17: 9815105.9 | F17: 10685592 | G17: II. ЗАТРАТЫ
A18: 1. Жалпы сипаттағы мемлекеттiк қызметтер | B18: 1137687.2 | C18: 1293447.3 | D18: 1334753.4 | E18: 468819.41 | F18: 571419.31 | G18: 1. Государственные услуги общего характера
A19: 2. Қорғаныс | B19: 1100070.9 | C19: 1038491.2 | D19: 1149535.1 | E19: 336751.03 | F19: 599415.83 | G19: 2. Оборона
... A40: VII. БЮДЖЕТТІҢ ТАПШЫЛЫҒЫН ҚАРЖЫЛАНДЫРУ (ПРОФИЦИТТІ ПАЙДАЛАНУ | B40: 3120850.3 | C40: 3648890.5 | D40: 4065222.9 | E40: 1032257.1 | F40: 1689245.1 | G40: VII. ФИНАНСИРОВАНИЕ ДЕФИЦИТА (ИСПОЛЬЗОВАНИЕ ПРОФИЦИТА) БЮДЖЕТА
A41: Ішкі | B41: 3529699.5 | C41: 3355950.9 | D41: 3542318.8 | E41: 1176694.1 | F41: =F42-F43 -> 1842706.7 | G41: Внутреннее
A42: Түсімдер | B42: 5318608.1 | C42: 5643320.3 | D42: 6027050.7 | E42: 2648599.9 | F42: 2758786.8 | G42: Поступление
A43: Өтеу | B43: 1788908.6 | C43: 2287369.4 | D43: 2484731.9 | E43: 1471905.8 | F43: 916080.02 | G43: Погашение
A44: Сыртқы | B44: -408849.23 | C44: 292939.56 | D44: 522904.09 | E44: -144436.99 | F44: =F45-F46 -> 79954.511 | G44: Внешнее
A45: Түсімдер | B45: 251872.16 | C45: 1447223.5 | D45: 2231117.1 | E45: 77013.789 | F45: 251761.07 | G45: Поступление
A46: Өтеу | B46: 660721.39 | C46: 1154283.9 | D46: 1708213 | E46: 221450.78 | F46: 171806.56 | G46: Погашение

Sheet табл 8 (дох)
B2: 8-кесте | H2: Таблица 8
F3: РЕСПУБЛИКАЛЫҚ БЮДЖЕТТІҢ АТҚАРЫЛУЫ/ ИСПОЛНЕНИЕ РЕСПУБЛИКАНСКОГО БЮДЖЕТА
B4: (млн.теңге) | H4: (млн.тенге)
B5: Санаты/ Категория | C5: Сыныбы/ Класс | D5: Сыныпшасы/ Подкласс | E5: Ерешелігі/ Специфика | F5: Атауы | G5: 2026 ж. қаңтар-мамыр есеп/_x000D_ январь-май отчет 2026 г. | H5: Наименование
B6: 1 | C6: 2 | D6: 3 | E6: 4 | F6: 5 | G6: 6 | H6: 7
F7: ТҮСІМДЕР | G7: 9407213.1 | H7: ПОСТУПЛЕНИЯ
F8: оның ішінде: | H8: в том числе:
F9: КІРІСТЕР | G9: 9274897.4 | H9: ДОХОДЫ
B10: 1 | F10: Салықтық түсімдер | G10: 7235595.1 | H10: Налоговые поступления
C11: 01 | F11: Табыс салығы | G11: 1989979.1 | H11: Подоходный налог
D12: 1 | F12: Корпоративтік табыс салығы | G12: 1989979.1 | H12: Корпоративный подоходный налог
B13: 1 | C13: 01 | D13: 1 | E13: 10 | F13: Мұнай секторы ұйымдарынан түсетін түсімдерді қоспағанда, ірі кәсіпкерлік субъектілерінен – заңды тұлғалардан алынатын корпоративтік табыс салығы | G13: 1989979.1 | H13: Корпоративный подоходный налог с юридических лиц – субъектов крупного предпринимательства, за исключением поступлений от организаций нефтяного сектора
C14: 05 | F14: Тауарларға, жұмыстарға және көрсетілетін қызметтерге салынатын iшкi салықтар | G14: 4359338.8 | H14: Внутренние налоги на товары, работы и услуги
D15: 1 | F15: Қосылған құн салығы | G15: 3478321.8 | H15: Налог на добавленную стоимость
C16: 05 | D16: 1 | E16: 01 | F16: Қазақстан Республикасының аумағында өндiрiлген тауарларға, орындалған жұмыстарға және көрсетілген қызметтерге салынатынқосылған құн салығы | G16: 1741399.1 | H16: Hалог на добавленную стоимость на произведенные товары, выполненные работы и оказанные услуги на территории Республики Казахстан
E17: 02 | F17: Ресей Федерациясы және Беларусь Республикасының аумағынан импортталатын тауарларға салынатын қосылған құн салығынан басқа, Қазақстан Республикасының аумағына импортталатын тауарларға салынатын қосылған құн салығы | G17: 902672.68 | H17: Hалог на добавленную стоимость на товары, импортируемые на территорию Республики Казахстан, кроме налога на добавленнуюстоимость на товары, импортируемые с территории Российской Федерации и Республики Беларусь
E18: 04 | F18: Резидент емес үшін қосылған құн салығы | G18: 139916.8 | H18: Налог на добавленную стоимость за нерезидента
E19: 14 | F19: Салық төлеушінің бұрын бюджеттен қайтарылған және салықтықтексеру жүргізу барысында қайтарылуы расталмаған қосылған құн салығының асып кеткен сомасын аударуы (қайтаруы), өсімпұл сомасын аударуы | G19: 3049.9072 | H19: Перечисление (возврат) налогоплательщиком суммы превышения налога на добавленную стоимость, ранее возвращенной из бюджета и не подтвержденной к возврату при проведении налоговой проверки, перечисление суммы пени
E20: 15 | F20: Еуразиялық экономикалық одаққа мүше мемлекеттер аумағынан импортталған тауарларға қосылған құн салығы | G20: 649992.43 | H20: Налог на добавленную стоимость на товары, импортированные стерритории государств-членов Евразийского экономического союза
E21: 16 | F21: Тауарлармен электрондық сауданы жүзеге асыру, жеке тұлғаларға электрондық нысанда қызметтер көрсету кезінде шетелдік компаниялардан түсетін қосылған құн салығы | G21: 41290.872 | H21: Налог на добавленную стоимость с иностранных интернет компаний при осуществлении электронной торговли товарами, оказании услуг в электронной форме физическим лицам
D22: 2 | F22: Акциздер | G22: 40188.696 | H22: Акцизы
D23: 2 | E23: 76 | F23: Қазақстан Республикасының аумағына Еуразиялық экономикалық одағына мүше мемлекеттердің аумағынан әкелінетін темекі өнімдері | G23: 2250.2641 | H23: Табачные изделия, ввозимые на территорию Республики Казахстан с территории государств-членов Евразийского экономического союза
E24: 77 | F24: Қазақстан Республикасының аумағына Еуразиялық экономикалық одағына мүше мемлекеттердің аумағынан әкелінетін спирттiң және (немесе) шарап материалының, алкоголь өнімдерінің барлық түрлерi | G24: 5996.5958 | H24: Все виды спирта и (или) виноматериала, алкогольной продукции, ввозимых на территорию Республики Казахстан с территории государств-членов Евразийского экономического союза
E25: 78 | F25: Қазақстан Республикасының аумағына Еуразиялық экономикалық одағына мүше мемлекеттердің аумағынан әкелінетін акцизделетін өнімнің өзге түрлері | G25: 171.54942 | H25: Прочие виды подакцизной продукции, ввозимой на территорию Республики Казахстан с территории государств-членов Евразийского экономического союза
E26: 79 | F26: Қазақстан Республикасы аумағына Еуразиялық экономикалық одағына мүше мемлекеттердің аумағынан әкелінетін бензин (авиациялықты қоспағанда) және дизель отыны | G26: 5167.7958 | H26: Бензин (за исключением авиационного) и дизельное топливо, ввозимых на территорию Республики Казахстан с территории государств-членов Евразийского экономического союза
E27: 80 | F27: Еуразиялық экономикалық одағына мүше болып табылмайтын мемлекеттердің аумағынан әкелінетін, Қазақстан Республикасының аумағына импортталатын спирттің және (немесе) шарап материалының, алкоголь өнімдерінің барлық түрлері | G27: 6646.6357 | H27: Все виды спирта и (или) виноматериала, алкогольной продукции, импортируемых на территорию Республики Казахстан с территории государств, не являющихся членами Евразийского экономического союза
E28: 81 | F28: Еуразиялық экономикалық одағына мүше болып табылмайтын мемлекеттердің аумағынан әкелінетін, Қазақстан Республикасының аумағына импортталатын темекі өнімдері | G28: 17666.962 | H28: Табачные изделия, импортируемые на территорию Республики Казахстан с территории государств, не являющихся членами Евразийского экономического союза
E29: 82 | F29: Еуразиялық экономикалық одағына мүше болып табылмайтын мемлекеттердің аумағынан әкелінетін, Қазақстан Республикасының аумағына импортталатын акцизделетін өнімдердің өзге түрлері | G29: 2240.9591 | H29: Прочие виды подакцизных продукций, импортируемые на территорию Республики Казахстан с территории государств, не являющихся членами Евразийского экономического союза
E30: 83 | F30: Еуразиялық экономикалық одағына мүше болып табылмайтын мемлекеттер аумағынан әкелінетін, Қазақстан Республикасының аумағына импортталатын бензин (авиациялықты қоспағанда) және дизель отыны | G30: 47.933857 | H30: Бензин (за исключением авиационного) и дизельное топливо, импортируемых на территорию Республики Казахстан с территориигосударств, не являющихся членами Евразийского экономического союза
D31: 3 | F31: Табиғи және басқа да ресурстарды пайдаланғаны үшiн түсетiн түсiмдер | G31: 840784.63 | H31: Поступления за использование природных и других ресурсов
D32: 3 | E32: 01 | F32: Қалааралық және (немесе) халықаралық телефон байланысын, сондай-ақ ұялы байланысты бергені үшін төлемақы | G32: 4212.7877 | H32: Плата за предоставление междугородной и (или) международнойтелефонной связи, а также сотовой связи
E33: 02 | F33: Мұнай секторы ұйымдарынан түсетін түсімдерді қоспағанда, үстеме пайдаға салынатын салық | G33: 165.032 | H33: Налог на сверхприбыль, за исключением поступлений от организаций нефтяного сектора
E34: 05 | F34: Мұнай секторы ұйымдарынан түсетін түсімдерді қоспағанда, бонустар | G34: 2377.9092 | H34: Бонусы, за исключением поступлений от организаций нефтяногосектора
E35: 06 | F35: Кең таралған пайдалы қазбаларды, жерасты суларын, емдік балшықтарды және мұнай секторы ұйымдарынан түсетін түсімдерді қоспағанда, пайдалы қазбаларды өндіру салығы | G35: 838117.86 | H35: Налог на добычу полезных ископаемых, за исключением общераспространенных полезных ископаемых, подземных вод, лечебных грязей и поступлений от организаций нефтяного сектора
E36: 07 | F36: Мұнай секторы ұйымдарынан түсетін түсімдерді қоспағанда, экспортқа рента салығы | G36: 775.41666 | H36: Рентный налог на экспорт, за исключением поступлений от организаций нефтяного сектора
E37: 08 | F37: Мұнай секторы ұйымдарынан түсетін түсімдерді қоспағанда, жасалған келісімшарттар бойынша өнімді бөлу жөніндегі Қазақстан Республикасының үлесі | G37: 0.001 | H37: Доля Республики Казахстан по разделу продукции по заключенным контрактам, за исключением поступлений от организаций нефтяного сектора
E38: 09 | F38: Радиожиілік спектрін пайдаланғаны үшін төлем | G38: -4864.3213 | H38: Плата за использование радиочастотного спектра
E39: 12 | F39: Мұнай секторы ұйымдарынан түсетін түсімдерді қоспағанда, өнімді бөлу туралы келісімшарт бойынша қызметті жүзеге асыратын жер қойнауын пайдаланушының қосымша төлемі және баламалы салық | G39: -0.051695 | H39: Дополнительный платеж недропользователя, осуществляющего деятельность по контракту о разделе продукции, и альтернативный налог, за исключением поступлений от организаций нефтяногосектора
D40: 4 | F40: Кәсiпкерлiк және кәсiби қызметтi жүргiзгенi үшiн алынатын алымдар | G40: 43.714365 | H40: Сборы за ведение предпринимательской и профессиональной деятельности
D41: 4 | E41: 28 | F41: Республикалық бюджетке төленетін тіркелгені үшін алым | G41: 38.367355 | H41: Регистрационный сбор, зачисляемый в республиканский бюджет
...

Sheet табл 8 (расх)
G2: (млн. тенге)
A3: (млн.теңге)
A5: Санаты/ Категория | B5: Сыныбы/ Класс | C5: Сыныпшасы/ Подкласс | D5: Ерешелігі/ Специфика | E5: Атауы | F5: 2026 қаңтар-мамыр есеп/_x000D_ январь-май отчет 2026г. | G5: Наименование
A6: 1 | B6: 2 | C6: 3 | D6: 4 | E6: 5 | F6: 6 | G6: 7
E7: ШЫҒЫСТАР | F7: 11096458 | G7: РАСХОДЫ
E8: оның ішінде: | G8: в том числе:
E9: II. ШЫҒЫНДАР | F9: 10685592 | G9: II. ЗАТРАТЫ
A10: 01 | E10: Жалпы сипаттағы мемлекеттiк қызметтер | F10: 571419.31 | G10: Государственные услуги общего характера
B11: 1 | E11: Мемлекеттiк басқарудың жалпы функцияларын орындайтын өкiлдi, атқарушы және басқа органдар | F11: 159286.25 | G11: Представительные, исполнительные и другие органы, выполняющие общие функции государственного управления
C12: 101 | E12: Қазақстан Республикасы Президентінің Әкімшілігі | F12: 7885.9139 | G12: Администрация Президента Республики Казахстан
A13: 01 | B13: 1 | C13: 101 | D13: 001 | E13: Мемлекет басшысының қызметін қамтамасыз ету | F13: 7885.9139 | G13: Обеспечение деятельности Главы государства
C14: 106 | E14: Адам құқықтары жөніндегі ұлттық орталық | F14: 618.90609 | G14: Национальный центр по правам человека
C15: 106 | D15: 001 | E15: Адамның және азаматтың құқықтары мен бостандықтарының сақталуын қадағалау жөніндегі көрсетілетін қызметтер | F15: 618.90609 | G15: Услуги по наблюдению за соблюдением прав и свобод человека и гражданина
C16: 107 | E16: Қазақстан Республикасы Жоғары Сот Кеңесінің Аппараты | F16: 508.04907 | G16: Аппарат Высшего Судебного Совета Республики Казахстан
C17: 107 | D17: 001 | E17: Қазақстан Республикасы Жоғары Сот Кеңесінің қызметін қамтамасыз ету жөніндегі көрсетілетін қызметтер | F17: 508.04907 | G17: Услуги по обеспечению деятельности Высшего Судебного СоветаРеспублики Казахстан
C18: 109 | E18: Қазақстан Республикасы Үкіметінің Аппараты | F18: 2083.6078 | G18: Аппарат Правительства Республики Казахстан
C19: 109 | D19: 001 | E19: Қазақстан Республикасы Премьер-Министрінің қызметін қамтамасыз ету жөніндегі көрсетілетін қызметтер | F19: 2083.6078 | G19: Услуги по обеспечению деятельности Премьер-Министра Республики Казахстан
C20: 626 | E20: Қазақстан Республикасының Стратегиялық жоспарлау және реформалар агенттігі | F20: 9217.68 | G20: Агентство по стратегическому планированию и реформам Республики Казахстан
C21: 626 | D21: 001 | E21: Реформаларды қалыптастыруға және тиімді іске асыруға жәрдемдесу жөніндегі көрсетілетін қызметтер, стратегиялық жоспарлау, мемлекеттік статистикалық қызмет салаларында мемлекеттік саясатты жүзеге асыру, мемлекеттік басқару жүйесі мен квазиме | F21: 9217.3297 | G21: Услуги по содействию в формировании и эффективной реализации реформ, осуществление государственной политики в сферах стратегического планирования, государственной статистической деятельности, участие в совершенствовании системы государствен
D22: 101 | E22: Өкілдiк шығындарға арналған қаражат есебiнен іс-шаралар өткізу | F22: 0.350325 | G22: Проведение мероприятий за счет средств на представительскиезатраты
C23: 637 | E23: Қазақстан Республикасы Конституциялық Сотының Аппараты | F23: 704.19643 | G23: Аппарат Конституционного Суда Республики Казахстан
C24: 637 | D24: 001 | E24: Республика аумағында Қазақстан Республикасы Конституциясының үстемдігін қамтамасыз ету | F24: 704.19643 | G24: Обеспечение верховенства Конституции Республики Казахстан на территории Республики
C25: 690 | E25: Қазақстан Республикасының Орталық сайлау комиссиясы | F25: 22565.905 | G25: Центральная избирательная комиссия Республики Казахстан
C26: 690 | D26: 001 | E26: Сайлау өткізуді ұйымдастыру | F26: 612.85896 | G26: Организация проведения выборов
D27: 002 | E27: Сайлау өткізу | F27: 2516.0606 | G27: Проведение выборов
D28: 101 | E28: Өкілдiк шығындарға арналған қаражат есебiнен іс-шаралар өткізу | F28: 17.137305 | G28: Проведение мероприятий за счет средств на представительскиезатраты
D29: 109 | E29: Қазақстан Республикасы Үкіметінің шұғыл шығындарға арналғанрезервінің есебінен ағымды іс-шаралар өткізу | F29: 19419.849 | G29: Проведение текущих мероприятий за счет резерва Правительства Республики Казахстан на неотложные затраты
C30: 693 | E30: Материалдық-техникалық қамтамасыз ету басқармасы | F30: 11434.932 | G30: Управление материально-технического обеспечения
C31: 693 | D31: 001 | E31: Қазақстан Республикасы Парламентінің қызметін қамтамасыз ету жөніндегі көрсетілетін қызметтер | F31: 11434.932 | G31: Услуги по обеспечению деятельности Парламента Республики Казахстан
C32: 694 | E32: Қазақстан Республикасы Президентiнiң Іс Басқармасы | F32: 104267.06 | G32: Управление Делами Президента Республики Казахстан
C33: 694 | D33: 001 | E33: Қазақстан Республикасы Президенті Іс Басқармасының мемлекеттік функциялары мен өкілеттіктерін жүзеге асыруды қамтамасызету жөніндегі көрсетілетін қызметтер | F33: 58631.743 | G33: Услуги по обеспечению осуществления государственных функцийи полномочий Управления Делами Президента Республики Казахстан
D34: 009 | E34: Қазақстан Республикасы Президенттік орталығының қызметін қамтамасыз ету жөніндегі көрсетілетін қызметтер | F34: 609.94137 | G34: Услуги по обеспечению деятельности Президентского центра Республики Казахстан
D35: 109 | E35: Қазақстан Республикасы Үкіметінің шұғыл шығындарға арналғанрезервінің есебінен ағымды іс-шаралар өткізу | F35: 1609.5 | G35: Проведение текущих мероприятий за счет резерва Правительства Республики Казахстан на неотложные затраты
D36: 167 | E36: Қазақстан Республикасы Президентінің бастамаларына арналғанрезервінің есебінен бюджеттік инвестициялық жобаларды іске асыру | F36: 43415.878 | G36: Реализация бюджетных инвестиционных проектов за счет резерва на инициативы Президента Республики Казахстан
B37: 2 | E37: Қаржылық қызмет | F37: 2072.9178 | G37: Финансовая деятельность
C38: 217 | E38: Қазақстан Республикасының Қаржы министрлігі | F38: 66.900873 | G38: Министерство финансов Республики Казахстан
B39: 2 | C39: 217 | D39: 002 | E39: Халықаралық қаржы ұйымдары қаржыландыратын инвестициялық жобалардың аудитiн жүзеге асыру | F39: 0 | G39: Осуществление аудита инвестиционных проектов, финансируемыхмеждународными финансовыми организациями
D40: 094 | E40: Мемлекеттік активтерді басқару | F40: 66.900873 | G40: Управление государственными активами
C41: 406 | E41: Қазақстан Республикасының Жоғары аудиторлық палатасы | F41: 2006.0169 | G41: Высшая аудиторская палата Республики Казахстан
C42: 406 | D42: 001 | E42: Қазақстан Республикасы Жоғары аудиторлық палатасының қызметін қамтамасыз ету жөніндегі көрсетілетін қызметтер | F42: 2006.0169 | G42: Услуги по обеспечению деятельности Высшей аудиторской палаты Республики Казахстан
...

Sheet табл 9
B2: Кесте 9 | D2: Таблица 9
B3: ШЫҒЫСТАРДЫҢ ВЕДОМСТВОЛЫҚ | D3: ИСПОЛНЕНИЕ РЕСПУБЛИКАНСКОГО БЮДЖЕТА
B4: СЫНЫПТАМАСЫ БОЙЫНША | D4: ПО ВЕДОМСТВЕННОЙ
B5: РЕСПУБЛИКАЛЫҚ БЮДЖЕТТІҢ АТҚАРАЛУЫ | D5: КЛАССИФИКАЦИИ РАСХОДОВ
B6: (млн. теңге) | D6: (млн. тенге)
B8: Бағдарламалард_x000D_ ың_x000D_ əкімшісі/_x000D_ Администратор_x000D_ программ | C8: Атауы | D8: 2026 ж. қаңтар-мамыр есеп/_x000D_ январь-май 2026 г. | E8: Наименование
B9: 1 | C9: 2 | D9: 3 | E9: 4
C10: БАРЛЫҒЫ | D10: 11096458 | E10: ВСЕГО
B11: 101 | C11: Қазақстан Республикасы Президентінің Әкімшілігі | D11: 7885.9139 | E11: Администрация Президента Республики Казахстан
B12: 106 | C12: Адам құқықтары жөніндегі ұлттық орталық | D12: 619.28185 | E12: Национальный центр по правам человека
B13: 107 | C13: Қазақстан Республикасы Жоғары Сот Кеңесінің Аппараты | D13: 825.92672 | E13: Аппарат Высшего Судебного Совета Республики Казахстан
B14: 109 | C14: Қазақстан Республикасы Үкіметінің Аппараты | D14: 3235.3784 | E14: Аппарат Правительства Республики Казахстан
B15: 201 | C15: Қазақстан Республикасының Ішкі істер министрлігі | D15: 295255.14 | E15: Министерство внутренних дел Республики Казахстан
B16: 202 | C16: Қазақстан Республикасының Төтенше жағдайлар министрлiгi | D16: 88259.986 | E16: Министерство по чрезвычайным ситуациям Республики Казахстан
B17: 204 | C17: Қазақстан Республикасының Сыртқы iстер министрлiгi | D17: 66005.304 | E17: Министерство иностранных дел Республики Казахстан
B18: 207 | C18: Қазақстан Республикасының Экология және табиғи ресурстар министрлігі | D18: 35756.336 | E18: Министерство экологии и природных ресурсов Республики Казахстан
B19: 208 | C19: Қазақстан Республикасының Қорғаныс министрлігі | D19: 518827.1 | E19: Министерство обороны Республики Казахстан
B20: 211 | C20: Қазақстан Республикасының Сауда және интеграция министрлігі | D20: 54737.795 | E20: Министерство торговли и интеграции Республики Казахстан
B21: 212 | C21: Қазақстан Республикасының Ауыл шаруашылығы министрлiгi | D21: 186012.42 | E21: Министерство сельского хозяйства Республики Казахстан
B22: 213 | C22: Қазақстан Республикасының Еңбек және халықты әлеуметтiк қорғау министрлiгi | D22: 2816276.7 | E22: Министерство труда и социальной защиты населения РеспубликиКазахстан
... B49: 694 | C49: Қазақстан Республикасы Президентiнiң Іс Басқармасы | D49: 156168.18 | E49: Управление Делами Президента Республики Казахстан

Sheet табл 10
A1: 10-кесте ШЫҒЫНДАРДЫҢ ЭКОНОМИКАЛЫҚ ЖІКТЕМЕСІ БОЙЫНША РЕСПУБЛИКАЛЫҚ БЮДЖЕТТІК ОРЫНДАЛУЫ (млн.теңге) | E1: Таблица 10 ИСПОЛНЕНИЕ РЕСПУБЛИКАНСКОГО БЮДЖЕТА ПО ЭКОНОМИЧЕСКОЙ КЛАССИФИКАЦИИ РАСХОДОВ (млн. тенге)
A3: Cанаты/_x000D_ Категория | B3: Iшкi сыныбы/_x000D_ Подкласс | C3: Ерекшелiгi/_x000D_ Специфика | D3: Атауы | F3: 2026 ж. қаңтар-мамыр/_x000D_ январь-май отчет 2026 г. | G3: Наименование
A4: 1 | B4: 2 | C4: 3 | D4: 4 | F4: 5 | G4: 6
D5: БАРЛЫҒЫ | F5: 11096458 | G5: ВСЕГО
A6: 1 | D6: Ағымдағы шығындар | F6: 10282759 | G6: Текущие затраты
A7: L01 Категория расходов | B7: 110 | D7: Жалақы | F7: 400318.18 | G7: Заработная плата
A8: 1 | B8: 110 | C8: 111 | D8: Еңбекке ақы төлеу | F8: 289052.29 | G8: Оплата труда
A9: 1 | C9: 112 | D9: Қосымша ақшалай төлемдер | F9: 63296.101 | G9: Дополнительные денежные выплаты
A10: 1 | C10: 113 | D10: Өтемақы төлемдері | F10: 43140.367 | G10: Компенсационные выплаты
A11: 1 | C11: 114 | D11: Міндетті кәсіптік зейнетақы жарналары | F11: 89.526614 | G11: Обязательные профессиональные пенсионные взносы
A12: 1 | C12: 116 | D12: Жұмыс берушілердің міндетті зейнетақы жарналары | F12: 4739.8924 | G12: Обязательные пенсионные взносы работодателей
A13: L01 Категория расходов | B13: 120 | D13: Жұмыс берушілердің жарналары | F13: 26582.192 | G13: Взносы работодателей
A14: 1 | B14: 120 | C14: 121 | D14: Әлеуметтік салық | F14: 9652.1482 | G14: Социальный налог
A15: 1 | C15: 122 | D15: Мемлекеттiк әлеуметтiк сақтандыру қорына әлеуметтiк аударымдар | F15: 11847.696 | G15: Социальные отчисления в Государственный фонд социального страхования
A16: 1 | C16: 123 | D16: Мiндеттi сақтандыру жарналары | F16: 324.94368 | G16: Взносы на обязательное страхование
A17: 1 | C17: 124 | D17: Міндетті әлеуметтік медициналық сақтандыруға аударымдар | F17: 4757.4041 | G17: Отчисления на обязательное социальное медицинское страхование
A18: L01 Категория расходов | B18: 130 | D18: Қазақстан Республикасының заңнамалық актілеріне сәйкес азаматтардың жекелеген санаттарына жалақы төлеу және жарналар аудару | F18: 23001.079 | G18: Выплата заработной платы отдельным категориям граждан и отчисления взносов в соответствии с законодательными актами Республики Казахстан
A19: 1 | B19: 130 | C19: 131 | D19: Техникалық персоналдың және келісімшарттық қызметшілердің еңбегіне ақы төлеу | F19: 20147.487 | G19: Оплата труда технического персонала и контрактных служащих
A20: 1 | C20: 134 | D20: Алқа билерге сыйақылар төлеу | F20: 135.03202 | G20: Выплата вознаграждений присяжным заседателям
A21: 1 | C21: 135 | D21: Техникалық персонал және келісімшарттық қызметшілер бойыншажұмыс берушілердің жарналары | F21: 2481.7688 | G21: Взносы работодателей по техническому персоналу и контрактным служащим
A22: 1 | C22: 136 | D22: Техникалық персоналдың және келісімшарттық қызметшілердің ел ішіндегі іссапарлары мен қызметтiк жол жүрулері | F22: 228.5563 | G22: Командировки и служебные разъезды внутри страны технического персонала и контрактных служащих
A23: 1 | C23: 137 | D23: Алқабилердің іссапарлық шығыстары | F23: 8.235341 | G23: Командировочные расходы присяжных заседателей
A24: L01 Категория расходов | B24: 140 | D24: Қорлар сатып алу | F24: 46697.178 | G24: Приобретение запасов
A25: 1 | B25: 140 | C25: 141 | D25: Азық-түлiк өнiмдерiн сатып алу | F25: 23577.106 | G25: Приобретение продуктов питания
A26: 1 | C26: 142 | D26: Дәрілік заттар және медициналық мақсаттағы өзге де бұйымдарды сатып алу | F26: 756.32933 | G26: Приобретение лекарственных средств и прочих изделий медицинского назначения
A27: 1 | C27: 143 | D27: Заттай мүлiктердi, басқа да киім нысанын және арнаулы киім-кешектер сатып алу, тiгу және жөндеу | F27: 7948.8904 | G27: Приобретение, пошив и ремонт предметов вещевого имущества идругого форменного и специального обмундирования
A28: 1 | C28: 144 | D28: Отын, жанар-жағар май материалдарын сатып алу | F28: 6329.2176 | G28: Приобретение топлива, горюче-смазочных материалов
A29: 1 | C29: 149 | D29: Өзге де қорларды сатып алу | F29: 8085.634 | G29: Приобретение прочих запасов
A30: L01 Категория расходов | B30: 150 | D30: Қызметтер мен жұмыстарды сатып алу | F30: 561172.97 | G30: Приобретение услуг и работ
A31: 1 | B31: 150 | C31: 151 | D31: Коммуналдық қызметтерге ақы төлеу | F31: 20539.405 | G31: Оплата коммунальных услуг
A32: 1 | C32: 152 | D32: Байланыс қызметтерiне ақы төлеу | F32: 9185.9432 | G32: Оплата услуг связи
A33: 1 | C33: 153 | D33: Көлiктiк қызмет көрсетулерге ақы төлеу | F33: 3657.7926 | G33: Оплата транспортных услуг
A34: 1 | C34: 154 | D34: Зерттеулер бойынша қызметтерге ақы төлеу | F34: 74089.25 | G34: Оплата услуг по исследованиям
A35: 1 | C35: 155 | D35: Мемлекеттiк әлеуметтiк тапсырыс шеңберiнде көрсетілетін қызметтерге ақы төлеу | F35: 185.57417 | G35: Оплата услуг в рамках государственного социального заказа
A36: 1 | C36: 156 | D36: Консалтингтік қызметтерге ақы төлеу | F36: 80.512 | G36: Оплата консалтинговых услуг
A37: 1 | C37: 157 | D37: Форумдар, семинарлар, конференциялар өткізуге және имидждік іс-шараларға арналған қызметтерге ақы төлеу | F37: 168.28589 | G37: Оплата услуг на проведение форумов, семинаров, конференций и на имиджевые мероприятия
A38: 1 | C38: 158 | D38: Ақпараттандыру саласындағы жұмыстар мен қызметтерге ақы төлеу | F38: 11779.684 | G38: Оплата работ и услуг в сфере информатизации
A39: 1 | C39: 159 | D39: Өзге де қызметтер мен жұмыстарға ақы төлеу | F39: 441486.53 | G39: Оплата прочих услуг и работ
A40: L01 Категория расходов | B40: 160 | D40: Басқа да ағымдағы шығындар | F40: 1163939.4 | G40: Другие текущие затраты
A41: 1 | B41: 160 | C41: 161 | D41: Ел iшiндегi iссапарлар мен қызметтiк сапарлар | F41: 8371.5462 | G41: Командировки и служебные разъезды внутри страны
...

Sheet таб 11
