Workbook
Name \E: #REF!
Name \E: #REF!
Name \E: #REF!
Name \E: #REF!
Name \E: #REF!
Name _____________________MS798: #REF!
Name _____________________MS798: #REF!
Name _____________________tab1: #REF!
Name _____________________tab2: #REF!
Name _____________________tab6798: #REF!
Name ____________________MS798: #REF!
Name ____________________tab1: #REF!
Name ____________________tab2: #REF!
Name ____________________tab6798: #REF!
Name ___________________MS798: #REF!
Name ___________________tab1: #REF!
Name ___________________tab2: #REF!
Name ___________________tab6798: #REF!
Name __________________MS798: #REF!
Name __________________tab1: #REF!
Name __________________tab2: #REF!
Name __________________tab6798: #REF!
Name _________________MS798: #REF!
Name _________________prt1: #N/A
Name _________________prt2: #N/A
Name _________________prt3: #N/A
Name _________________prt4: #N/A
Name _________________prt5: #N/A
Name _________________prt6: #N/A
Name _________________prt7: #N/A
Name _________________prt8: #N/A
Name _________________tab1: #REF!
Name _________________tab2: #REF!
Name _________________tab6798: #REF!
Name ________________MS798: #REF!
Name ________________prt1: #N/A
Name ________________prt2: #N/A
Name ________________prt3: #N/A
Name ________________prt4: #N/A
Name ________________prt5: #N/A
Name ________________prt6: #N/A
Name ________________prt7: #N/A
Name ________________prt8: #N/A
Name ________________tab1: #REF!
Name ________________tab2: #REF!
Name ________________tab6798: #REF!
Name _______________MS798: #REF!
Name _______________prt1: #N/A
Name _______________prt2: #N/A
Name _______________prt3: #N/A
Name _______________prt4: #N/A
Name _______________prt5: #N/A
Name _______________prt6: #N/A
Name _______________prt7: #N/A
Name _______________prt8: #N/A
Name _______________tab1: #REF!
Name _______________tab2: #REF!
Name _______________tab6798: #REF!
Name ______________MS798: #REF!
Name ______________prt1: #N/A

Sheet табл 1
A1: 1-кесте | I1: Таблица 1
A3: НЕГІЗГІ МАКРОЭКОНОМИКАЛЫҚ ИНДИКАТОРЛАР/
A4: ОСНОВНЫЕ МАКРОЭКОНОМИЧЕСКИЕ ИНДИКАТОРЫ
A6: Атауы | B6: 2019 жыл/ 2019 год | C6: 2020 жыл/ 2020 год | D6: 2021 жыл/ 2021 год | E6: 2022 жыл/ 2022 год | F6: 2023 жыл/ 2023 год | G6: 2024 жыл/ 2024 год | H6: 2025 ж. 1 тамыздағы есеп/ отчет на 1 августа 2025 г. | I6: Наименование
A7: 1 | B7: 2 | C7: 3 | D7: 4 | E7: 5 | F7: 6 | G7: 7 | H7: 8 | I7: 9
A8: Жалпы ішкi өнiм, млрд. теңге | B8: 69532.626 | C8: 70649 | D8: 83951.587 | E8: 65487.797 | F8: 120561.1 | G8: 84962.621 | H8: 61361.3 | I8: Валовой внутренний продукт, млрд.тенге январь-июнь 2025 года (предварит. данные)
A9: өткен жылдың тиiстi кезеңiндегi нақты есептеудегi %-бен | B9: 104.5 | C9: 97.5 | D9: 103.3 | E9: 103 | F9: 105.1 | G9: 104.1 | H9: 106.3 | I9: в % к соответствующему периоду предыдущего года
A10: Өнеркәсiп өнiмiнiң көлемi, млрд. теңге | B10: 29380.342 | C10: 26743.4 | D10: 37047.6 | E10: 4157.4 | F10: 46401.716 | G10: 50124.86 | H10: 34204.1 | I10: Объем промышленного производства, млрд.тенге (январь-июль 2025г.)
A11: өткен жылдың тиiстi кезеңiне %-бен | B11: 104.1 | C11: 99.3 | D11: 103.8 | E11: 97.2 | F11: 104.3 | G11: 102.8 | H11: 106.9 | I11: в % к соответствующему периоду предыдущего года
A12: Мембюджетке кірістер, млрд. теңге | B12: 12758.479 | C12: 14521.191 | D12: 15847.431 | E12: 20248.101 | F12: 24917.246 | G12: ='[46]табл 2 '!C8/1000 -> 27132.165 | H12: ='табл 2 '!C8/1000 -> 16361.108 | I12: Доходы в госбюджет, млрд.тенге
A13: ЖIӨ-ге %-бен | B13: 18.502241 | C13: 20.535071 | D13: =D12/D8*100 -> 18.876869 | E13: =E12/E8*100 -> 30.918891 | G13: =G12/G8*100 -> 31.934237 | H13: =H12/H8*100 -> 26.663561 | I13: в % к ВВП
A14: Мембюджеттен шығындар, млрд. теңге | B14: 13535.581 | C14: 16725.097 | D14: 17951.888 | E14: 21532.543 | F14: 26760 | G14: ='[46]табл 2 '!C18/1000 -> 30318.236 | H14: ='табл 2 '!C18/1000 -> 17461.82 | I14: Затраты из госбюджета, млрд. тенге
A15: ЖIӨ-ге %-бен | B15: 19.629188 | C15: 23.651714 | D15: =D14/D8*100 -> 21.38362 | E15: =E14/E8*100 -> 32.880238 | F15: 35.421743 | G15: =G14/G8*100 -> 35.684206 | H15: =H14/H8*100 -> 28.457382 | I15: в % к ВВП
A16: Таза бюджеттік кредит беру, млрд. теңге | B16: 262.88084 | C16: 261.98101 | D16: 267.33754 | E16: 592.68034 | F16: 466.44174 | G16: ='[46]табл 2 '!C34/1000 -> 198.40855 | H16: ='табл 3'!F34/1000 -> 139.28394 | I16: Чистое бюджетное кредитование, млрд. тенге
A17: ЖIӨ-ге %-бен | B17: 0.38122761 | C17: 0.37047917 | D17: =D16/D8*100 -> 0.31844251 | E17: =E16/E8*100 -> 0.9050241 | F17: 0.61742075 | G17: =G16/G8*100 -> 0.23352452 | H17: =H16/H8*100 -> 0.22698987 | I17: в % к ВВП
A18: Қаржылық активтермен болатын операциялар бойынша сальдо, млрд. теңге | B18: 245.32373 | C18: 340.26326 | D18: 163.01136 | E18: 292.00158 | F18: 501.9047 | G18: ='[46]табл 2 '!C37/1000 -> 201.56181 | H18: ='табл 2 '!C37/1000 -> 285.29756 | I18: Сальдо по операциям с финансовыми активами, млрд.тенге
A19: ЖIӨ-ге %-бен | B19: 0.35576643 | C19: 0.48118163 | D19: =D18/D8*100 -> 0.19417306 | E19: =E18/E8*100 -> 0.44588701 | F19: 0.66436244 | G19: =G18/G8*100 -> 0.23723586 | H19: =H18/H8*100 -> 0.46494707 | I19: в % к ВВП
A20: Мембюджеттiң тапшылығы (-) / профицитi (+), млрд. теңге | B20: -1285.3067 | C20: -2806.1502 | D20: -2534.8062 | E20: -2169.1247 | F20: -2811.1006 | G20: ='[46]табл 2 '!C40/1000 -> -3586.0419 | H20: ='табл 3'!F40/1000 -> -1525.2933 | I20: Дефицит (-) / профицит (+) госбюджета, млрд.тенге
A21: ЖIӨ-ге %-бен | B21: -1.8639412 | C21: -3.9683036 | D21: =D20/D8*100 -> -3.0193666 | E21: =E20/E8*100 -> -3.3122579 | F21: -3.7210045 | G21: =G20/G8*100 -> -4.2207288 | H21: =H20/H8*100 -> -2.4857578 | I21: в % к ВВП
A22: Тұтыну бағаларының индексі өткен жылдың айына, %-бен | B22: 105.4 | C22: 107.5 | D22: 108.4 | E22: 120.3 | F22: 109.5 | G22: 108.9 | H22: 112.2 | I22: Индекс потребительских цен к августу предыдущего года, в %
A23: орташа есеппен өткен жылдың тиiстi кезеңiндегi кезге арналған, %-бен | B23: 105.3 | C23: 106.8 | D23: 108 | E23: 115 | G23: 108.6 | H23: 105.7 | I23: в среднем за период к соответствующему периоду предыдущего года, в %
A24: Орташа айлық атаулы жалақы 1 қызметкердың, теңге | B24: 186815 | C24: 220848 | D24: 268051 | E24: 303055 | F24: 350542 | G24: 390328 | H24: 448620 | I24: Среднемесячная номинальная заработная плата 1 работника, тенге (2 квартал 2025г.)
A25: өткен жылдың тиiстi кезеңiне %-бен | B25: 114.8 | C25: 104.4 | D25: 115.3 | E25: 112.2 | F25: 116.9 | G25: 111.3 | H25: 111.3 | I25: в % к соответствующему периоду предыдущего года
A26: Экспорт, млн. АҚШ долл. | B26: 58065.6 | C26: 46 949,7 2 | D26: 54549.5 | E26: ____ | F26: 71274.7 | G26: 73884.5 | H26: 36819.5 | I26: Экспорт, млн. долл. США (январь-июнь 2025г.)
A27: өткен жылдың тиiстi кезеңiне %-бен | B27: 95 | C27: 80.9 | D27: 124.5 | I27: в % к соответствующему периоду предыдущего года
A28: Импорт, млн. АҚШ долл. | B28: 39709.3 | C28: 38 081,4 2 | D28: 36825.9 | E28: ____ | F28: 54643.5 | G28: 53590.3 | H28: 29138.5 | I28: Импорт, млн. долл. США (январь-июнь 2025г.)
A29: өткен жылдың тиiстi кезеңiне %-бен | B29: 118 | C29: 95.9 | D29: 104.2 | I29: в % к соответствующему периоду предыдущего года
A30: Сауда балансының сальдосы, млн. АҚШ долл. | B30: 18356.3 | C30: 8969 | D30: 17723.6 | E30: ____ | F30: 16631.2 | G30: =G26-G28 -> 20294.2 | H30: =H26-H28 -> 7681 | I30: Сальдо торгового баланса, млн. долл. США
A31: Теңгенiң АҚШ долларына қарағандағы ресми айырбас бағамы: | I31: Официальный обменный курс тенге к доллару США:
A32: кезеңнiң аяғындағы | B32: 381.18 | C32: 420.71 | D32: 433.83 | E32: 459.92 | F32: 448.17 | G32: 525.11 | H32: 546.36 | I32: на конец периода
A33: кезең бойынша орташа | B33: 382.75 | C33: 412.95 | D33: 433.66 | E33: 460.48 | F33: 451.28 | G33: 469.44 | H33: 528.81 | I33: в среднем за период январь-июль 2025 года
A35: Ақпарат көзi: / Источник:
A36: Қазақстан Республикасының Қаржы министрлiгi / Министерство финансов Республики Казахстан.
A37: Ұлттық статистика бюросы Қазақстан Республикасының Стратегиялық жоспарлау және реформалар агенттігі / Бюро национальной статистики Агентства по стратегическому планированию и реформам Республики Казахстан
A38: Қазақстан Республикасының Ұлттық Банкi / Национальный Банк Республики Казахстан.
A39: Ескерту: / Примечание:
A40: 1 - Ұлттық статистика бюросы Қазақстан Республикасының Стратегиялық жоспарлау және реформалар агенттігінің деректері бойынша /Объем ВВП по отчетным данным Бюро национальной статистики Агентства по стратегическому планированию и реформам Республики Казахстан
A41: 2 - Ұлттық статистика бюросы Қазақстан Республикасының Стратегиялық жоспарлау және реформалар агенттігінің деректері бойынша /По данным Бюро национальной статистики Агентства по стратегическому планированию и реформам Республики Казахстан
A42: 3 - Ұлттық статистика бюросы Қазақстан Республикасының Стратегиялық жоспарлау және реформалар агенттігінің деректері бойынша /По данным Бюро национальной статистики Агентства по стратегическому планированию и реформам Республики Казахстан

Sheet табл 2 
A1: 2-кесте | F1: Таблица - 2
A2: МЕМЛЕКЕТТІК ЖӘНЕ РЕСПУБЛИКАЛЫҚ | F2: СРАВНИТЕЛЬНЫЙ АНАЛИЗ ИСПОЛНЕНИЯ
A3: БЮДЖЕТТЕР АТҚАРЫЛУЫНЫҢ САЛЫСТЫРМА ТАЛДАУЫ | F3: ГОСУДАРСТВЕННОГО И РЕСПУБЛИКАНСКОГО БЮДЖЕТОВ
A5: Атауы | B5: Мемлекеттік бюджет / Государственный бюджет | F5: Республикалық бюджет / Республиканский бюджет | J5: Наименование
B6: 2025 жылға түзету енгізілген бюджет (млн. теңге)/ скорректированный бюджет на 2025 год (млн.тенге) | C6: 2025 жылғы қаңтар-шілде атқарылуы (млн. теңге)/ исполнение за январь-июль 2025 года (млн.тенге) | D6: бір жылға түзету енгізілген бюджеттің атқарылу %-ы/% исполнения к скорректированному бюджету на год | E6: 2024 ж. қаңтар-шілде %-бен 2025 ж. қаңтар-шілдеге/ 2025 г. январь-июль в % к январю-июлю 2024 г. | F6: 2025 жылға түзету енгізілген бюджет (млн. теңге)/ скорректированный бюджет на 2025 год (млн.тенге) | G6: 2025 жылғы қаңтар-шілде атқарылуы (млн. теңге)/ исполнение за январь-июль 2025 года (млн.тенге) | H6: бір жылға түзету енгізілген бюджеттің атқарылу %-ы/% исполнения к скорректированному бюджету на год | I6: 2024 ж. қаңтар-шілде %-бен 2025 ж. қаңтар-шілдеге/ 2025 г. январь-июль в % к январю-июлю 2024 г.
A7: 1 | B7: 2 | C7: 3 | D7: 4 | E7: 5 | F7: 6 | G7: 7 | H7: 8 | I7: 9 | J7: 10
A8: I. КІРІСТЕР | B8: 29363162 | C8: 16361108 | D8: 55.719843 | E8: 112.60792 | F8: 21392055 | G8: 11543427 | H8: 53.961281 | I8: 112.43755 | J8: I. ДОХОДЫ
A9: Салықтық түсімдер оның iшiнде: | B9: 23065569 | C9: 12073505 | D9: 52.344276 | E9: 117.53547 | F9: 15193344 | G9: 7239542.7 | H9: 47.649436 | I9: 119.29379 | J9: Налоговые поступления, в том числе:
A10: корпорациялық табыс салығы | B10: 6690090.8 | C10: 3277371.7 | D10: 48.988449 | E10: 119.46468 | F10: 5087546.7 | G10: 2237617.7 | H10: 43.982255 | I10: 125.43367 | J10: корпоративный подоходный налог
A11: жеке табыс салығы | B11: 2604126.1 | C11: 1591651.2 | D11: 61.120357 | E11: 113.3821 | F11: 0 | G11: 0 | H11: 0 | I11: 0 | J11: индивидуальный подоходный налог
A12: әлеуметтік салық | B12: 1727455.1 | C12: 1042470.7 | D12: 60.347196 | E12: 117.46983 | F12: 0 | G12: 0 | H12: 0 | I12: 0 | J12: социальный налог
A13: қосылған құн салығы | B13: 6510033 | C13: 3067591.1 | D13: 47.120977 | E13: 122.27757 | F13: 6510033 | G13: 3067591.1 | H13: 47.120977 | I13: 122.27757 | J13: налог на добавленную стоимость
A14: акциздер | B14: 954584.86 | C14: 547340.06 | D14: 57.33802 | E14: 122.28168 | F14: 149702.35 | G14: 68224.961 | H14: 45.573741 | I14: 98.24186 | J14: акцизы
A15: Салықтық емес түсімдер | B15: 736338.75 | C15: 709043.91 | D15: 96.293169 | E15: 61.7369 | F15: 435325.85 | G15: 459781.24 | H15: 105.61772 | I15: 52.432752 | J15: Неналоговые поступления
A16: Негізгі капиталды сатудан түсетін түсімдер | B16: 311254.07 | C16: 103558.82 | D16: 33.271475 | E16: 94.52776 | F16: 5200 | G16: 2062.5326 | H16: 39.664089 | I16: 44.029785 | J16: Поступления от продажи основного капитала
A17: Трансферттердің түсімдері | B17: 5250000 | C17: 3475000 | D17: 66.190476 | E17: 115.87196 | F17: 5758184.9 | G17: 3842040.4 | H17: 66.723116 | I17: 115.8541 | J17: Поступления трансфертов
A18: II. ШЫҒЫНДАР | B18: 33857057 | C18: 17461820 | D18: 51.575125 | E18: 108.96696 | F18: 25193778 | G18: 13382506 | H18: 53.118299 | I18: 103.30965 | J18: II. ЗАТРАТЫ
A19: 1. Жалпы сипаттағы мемлекеттiк қызметтер | B19: 1921415.6 | C19: 893361.5 | D19: 46.494966 | E19: 98.01588 | F19: 1431272.2 | G19: 597063.17 | H19: 41.715558 | I19: 93.05389 | J19: 1. Государственные услуги общего характера
... A32: 14. Борышқа қызмет көрсету | B32: 2550090.2 | C32: 2035215.4 | D32: 79.809547 | E32: 119.06396 | F32: 2497932.3 | G32: 2017823 | H32: 80.77973 | I32: 119.30154 | J32: 14. Обслуживание долга
F33: 5578500.9 | G33: 3358383.8 | H33: 60.202264 | I33: 106.47882 | J33: 15. Трансферты
A34: III. ТАЗА БЮДЖЕТТІК КРЕДИТ БЕРУ | B34: 363161.74 | C34: 139283.94 | D34: 38.353141 | E34: 130.74924 | F34: 252140.98 | G34: 55411.289 | H34: 21.976312 | I34: 78.0273 | J34: III. ЧИСТОЕ БЮДЖЕТНОЕ КРЕДИТОВАНИЕ
A35: Бюджеттік кредиттер | B35: 636968.88 | C35: 281411.46 | D35: 44.179782 | E35: 124.0133 | F35: 510480 | G35: 204000 | H35: 39.962388 | I35: 106.16709 | J35: Бюджетные кредиты
A36: Бюджеттік кредиттерді өтеу | B36: 273807.14 | C36: 142127.53 | D36: 51.907898 | E36: 118.05313 | F36: 258339.02 | G36: 148588.71 | H36: 57.516944 | I36: 122.66406 | J36: Погашение бюджетных кредитов
A37: IV. ҚАРЖЫ АКТИВТЕРІМЕН ОПЕРАЦИЯЛАР БОЙЫНША САЛЬДО - ҚАРЖЫ АК | B37: 525287.43 | C37: 285297.56 | D37: 54.312658 | E37: 207.66876 | F37: 46891.3 | G37: 19155.048 | H37: 40.849897 | I37: 45.14115 | J37: IV. САЛЬДО ПО ОПЕРАЦИЯМ С ФИНАНСОВЫМИ АКТИВАМИ
A38: Қаржылық активтерді сатып алу | B38: 528067.62 | C38: 288193.58 | D38: 54.575129 | E38: 208.87861 | F38: 46891.3 | G38: 19155.048 | H38: 40.849897 | I38: 45.14115 | J38: Приобретение финансовых активов
A39: Мемлекеттің қаржы активтерін сатудан түсетін түсімдер | B39: 2780.189 | C39: 2896.0196 | D39: 104.16628 | E39: 490.24066 | J39: Поступления от продажи финансовых активов государства
A40: V. БЮДЖЕТ ТАПШЫЛЫҒЫ (ПРОФИЦИТІ) | B40: -5382344.4 | C40: -1525293.3 | D40: 28.338827 | E40: -87.68501 | F40: -4100755.3 | G40: -1913645.8 | H40: 46.665691 | I40: -68.32725 | J40: V. ДЕФИЦИТ (ПРОФИЦИТ) БЮДЖЕТА
A41: VI. БЮДЖЕТТІҢ МҰНАЙҒА ҚАТЫСТЫ ЕМЕС ТАПШЫЛЫҒЫ (ПРОФИЦИТІ) | B41: -12282044 | C41: -5881059.7 | D41: 47.883394 | E41: -105.83906 | F41: -11000455 | G41: -6269412.2 | H41: 56.992298 | I41: -94.73562 | J41: VI. НЕНЕФТЯНОЙ ДЕФИЦИТ (ПРОФИЦИТ) БЮДЖЕТА

Sheet табл 3
A1: 3-кесте | E1: Таблица 3
A2: МЕМЛЕКЕТТІК БЮДЖЕТТІҢ АТҚАРЫЛУЫ | E2: ИСПОЛНЕНИЕ ГОСУДАРСТВЕННОГО БЮДЖЕТА
A3: (млн.теңге) | E3: (млн. тенге)
A5: Атауы | B5: 2022 ж. есеп/ 2022 г. отчет | C5: 2023 ж. есеп/ 2023 г. отчет | D5: 2024 ж. есеп/ 2024 г. отчет | F5: 2025 ж. қантар-шілде есеп/январь-июль отчет 2025 г. | G5: Наименование
D6: жылдық/ годовой | E6: қантар-шілде/январь-июль
A7: 1 | B7: 2 | C7: 3 | D7: 4 | E7: 5 | F7: 6 | G7: 7
A8: I. КІРІСТЕР | B8: 20248101 | C8: 24917246 | D8: 27132165 | E8: 14529270 | F8: 16361108 | G8: I. ДОХОДЫ
A9: Салықтық түсімдер_x000D_ оның iшiнде: | B9: 14843311 | C9: 18912204 | D9: 19700517 | E9: 10272223 | F9: 12073505 | G9: Налоговые поступления,_x000D_ в том числе:
A10: корпорациялық табыс салығы | B10: 3962495.8 | C10: 5045696.1 | D10: 5213291.4 | E10: 2743381.2 | F10: 3277371.7 | G10: корпоративный подоходный налог
A11: жеке табыс салығы | B11: 1499712.4 | C11: 1992384.9 | D11: 2451640 | E11: 1403794.1 | F11: 1591651.2 | G11: индивидуальный подоходный налог
A12: әлеуметтік салық | B12: 1035129 | C12: 1321272.8 | D12: 1579329.4 | E12: 887436.98 | F12: 1042470.7 | G12: социальный налог
A13: қосылған құн салығы | B13: 4226358.8 | C13: 5674110.6 | D13: 5179378.1 | E13: 2508711.3 | F13: 3067591.1 | G13: налог на добавленную стоимость
A14: акциздер | B14: 757266.87 | C14: 840215.7 | D14: 844909.98 | E14: 447605.92 | F14: 547340.06 | G14: акцизы
A15: Салықтық емес түсімдер | B15: 584848.01 | C15: 1822932.9 | D15: 1629968 | E15: 1148493 | F15: 709043.91 | G15: Неналоговые поступления
A16: Негізгі капиталды сатудан түсетін түсімдер | B16: 239941.5 | C16: 182108.73 | D16: 201680.05 | E16: 109553.88 | F16: 103558.82 | G16: Поступления от продажи основного капитала
A17: Трансферттердің түсімдері | B17: 4580000 | C17: 4000000 | D17: 5600000 | E17: 2999000 | F17: 3475000 | G17: Поступления трансфертов
A18: II. ШЫҒЫНДАР | B18: 21532543 | C18: 26760000 | D18: 30318236 | E18: 16024875 | F18: 17461820 | G18: II. ЗАТРАТЫ
A19: 1. Жалпы сипаттағы мемлекеттiк қызметтер | B19: 1211805.7 | C19: 1489124.1 | D19: 1766404.2 | E19: 911445.68 | F19: 893361.5 | G19: 1. Государственные услуги общего характера
... A32: 14. Борышқа қызмет көрсету | B32: 1357551.8 | C32: 1865649 | D32: 2232329.2 | E32: 1709346.4 | F32: 2035215.4 | G32: 14. Обслуживание долга
A33: 15. Трансферттер | B33: 140421.01 | C33: - | D33: - | E33: - | F33: - | G33: 15. Трансферты
A34: III. ТАЗА БЮДЖЕТТІК КРЕДИТ БЕРУ | B34: 592680.34 | C34: 466441.74 | D34: 198408.55 | E34: 106527.53 | F34: 139283.94 | G34: III. ЧИСТОЕ БЮДЖЕТНОЕ КРЕДИТОВАНИЕ
A35: Бюджеттік кредиттер | B35: 742434.13 | C35: 712385.4 | D35: 519749.13 | E35: 226920.38 | F35: 281411.46 | G35: Бюджетные кредиты
A36: Бюджеттік кредиттерді өтеу | B36: 149753.78 | C36: 245943.66 | D36: 321340.58 | E36: 120392.85 | F36: 142127.53 | G36: Погашение бюджетных кредитов
A37: IV. ҚАРЖЫ АКТИВТЕРІМЕН ОПЕРАЦИЯЛАР БОЙЫНША САЛЬДО - ҚАРЖЫ АК | B37: 292001.58 | C37: 501904.7 | D37: 201561.81 | E37: 137381.07 | F37: 285297.56 | G37: IV. САЛЬДО ПО ОПЕРАЦИЯМ С ФИНАНСОВЫМИ АКТИВАМИ
A38: Қаржылық активтерді сатып алу | B38: 293189.28 | C38: 503365.1 | D38: 202951.32 | E38: 137971.81 | F38: 288193.58 | G38: Приобретение финансовых активов
A39: Мемлекеттің қаржы активтерін сатудан түсетін түсімдер | B39: 1187.6999 | C39: 1460.4064 | D39: 1389.5083 | E39: 590.73428 | F39: 2896.0196 | G39: Поступления от продажи финансовых активов государства
A40: V. БЮДЖЕТ ТАПШЫЛЫҒЫ (ПРОФИЦИТІ) | B40: -2169124.7 | C40: -2811100.6 | D40: -3586041.9 | E40: -1739514.3 | F40: -1525293.3 | G40: V. ДЕФИЦИТ (ПРОФИЦИТ) БЮДЖЕТА
A41: VI. БЮДЖЕТТІҢ МҰНАЙҒА ҚАТЫСТЫ ЕМЕС ТАПШЫЛЫҒЫ (ПРОФИЦИТІ) | B41: -8370502.3 | C41: -8454245.5 | D41: -10784416 | E41: -5556606.1 | F41: -5881059.7 | G41: VI. НЕНЕФТЯНОЙ ДЕФИЦИТ (ПРОФИЦИТ) БЮДЖЕТА
A42: VII. БЮДЖЕТТІҢ ТАПШЫЛЫҒЫН ҚАРЖЫЛАНДЫРУ (ПРОФИЦИТТІ ПАЙДАЛАНУ | B42: 2169124.7 | C42: 2811100.6 | D42: 3586041.9 | E42: 1739514.3 | F42: 1525293.3 | G42: VII. ФИНАНСИРОВАНИЕ ДЕФИЦИТА (ИСПОЛЬЗОВАНИЕ ПРОФИЦИТА) БЮДЖЕТА
A43: Ішкі | B43: 2312930.2 | C43: 3221830.7 | D43: 3293971.1 | E43: 1882679.8 | F43: 1673301.6 | G43: Внутреннее
A44: Түсімдер | B44: 3925848 | C44: 5179541.7 | D44: 5785457.6 | E44: 3692099.2 | F44: 3477623.5 | G44: Поступление
A45: Өтеу | B45: 1612917.7 | C45: 1957711 | D45: 2491486.6 | E45: 1809419.4 | F45: 1804322 | G45: Погашение
... A48: Өтеу | B48: 209770.89 | C48: 662602.27 | D48: 1155152.7 | E48: 198689.08 | F48: 1527454 | G48: Погашение

Sheet табл 4
A1: 4-кесте | G1: Таблица 4
A3: МЕМЛЕКЕТТІК БЮДЖЕТКЕ ТҮСІМДЕР/_x000D_ ПОСТУПЛЕНИЯ В ГОСУДАРСТВЕННЫЙ БЮДЖЕТ
A5: (млн.теңге) | G5: (млн.тенге)
A7: Санаты/ Категория | B7: Сыныбы/ Класс | C7: Сыныпшасы/ Подкласс | D7: Ерешелігі/ Специфика | E7: Атауы | F7: 2025 ж. қаңтар-шілде есеп/_x000D_ январь-июль отчет 2025 г. | G7: Наименование
A8: 1 | B8: 2 | C8: 3 | D8: 4 | E8: 5 | F8: 6 | G8: 7
E9: ТҮСІМДЕР | F9: 16506131 | G9: ПОСТУПЛЕНИЯ
E10: оның ішінде: | G10: в том числе:
E11: КІРІСТЕР | F11: 16361108 | G11: ДОХОДЫ
A12: 1 | B12: L01 Класс дохода | C12: L01 Подкласс дохода | D12: L01 Специфика дохода | E12: Салықтық түсімдер | F12: 12073505 | G12: Налоговые поступления
A13: L01 Категория дохода | B13: 01 | C13: L01 Подкласс дохода | D13: L01 Специфика дохода | E13: Табыс салығы | F13: 4869022.9 | G13: Подоходный налог
A14: L01 Категория дохода | B14: L01 Класс дохода | C14: 1 | D14: L01 Специфика дохода | E14: Корпорациялық табыс салығы | F14: 3277371.7 | G14: Корпоративный подоходный налог
A15: 1 | B15: 01 | C15: 1 | D15: 10 | E15: Мұнай секторы ұйымдарынан түсетін түсімдерді қоспағанда, ірі кәсіпкерлік субъектілерінен – заңды тұлғалардан алынатын корпоративтік табыс салығы | F15: 2237617.7 | G15: Корпоративный подоходный налог с юридических лиц – субъектов крупного предпринимательства, за исключением поступлений от организаций нефтяного сектора
D16: 11 | E16: Ірі кәсіпкерлік субъектілерінен және мұнай секторы ұйымдарынан түсетін түсімдерді қоспағанда, заңды тұлғалардан алынатын корпоративтік табыс салығы | F16: 1039754 | G16: Корпоративный подоходный налог с юридических лиц, за исключением поступлений от субъектов крупного предпринимательства и организаций нефтяного сектора
A17: L01 Категория дохода | B17: L01 Класс дохода | C17: 2 | D17: L01 Специфика дохода | E17: Жеке табыс салығы | F17: 1591651.2 | G17: Индивидуальный подоходный налог
C18: 2 | D18: 01 | E18: Төлем көзінен салық салынатын табыстардан ұсталатын жеке табыс салығы | F18: 1245048.6 | G18: Индивидуальный подоходный налог с доходов, облагаемых у источника выплаты
D19: 02 | E19: Төлем көзінен салық салынбайтын табыстардан ұсталатын жеке табыс салығы | F19: 334477.07 | G19: Индивидуальный подоходный налог с доходов, не облагаемых у источника выплаты
D20: 05 | E20: Төлем көзінен салық салынбайтын шетелдік азаматтар табыстарынан ұсталатын жеке табыс салығы | F20: 12125.509 | G20: Индивидуальный подоходный налог с доходов иностранных граждан, не облагаемых у источника выплаты
A21: L01 Категория дохода | B21: 03 | C21: L01 Подкласс дохода | D21: L01 Специфика дохода | E21: Әлеуметтiк салық | F21: 1042470.7 | G21: Социальный налог
A22: L01 Категория дохода | B22: L01 Класс дохода | C22: 1 | D22: L01 Специфика дохода | E22: Әлеуметтік салық | F22: 1042470.7 | G22: Социальный налог
B23: 03 | C23: 1 | D23: 01 | E23: Әлеуметтік салық | F23: 1042470.7 | G23: Социальный налог
A24: L01 Категория дохода | B24: 04 | C24: L01 Подкласс дохода | D24: L01 Специфика дохода | E24: Меншiкке салынатын салықтар | F24: 437977.17 | G24: Hалоги на собственность
A25: L01 Категория дохода | B25: L01 Класс дохода | C25: 1 | D25: L01 Специфика дохода | E25: Мүлiкке салынатын салықтар | F25: 305262.29 | G25: Hалоги на имущество
B26: 04 | C26: 1 | D26: 01 | E26: Заңды тұлғалардың және жеке кәсіпкерлердің мүлкіне салынатын салық | F26: 291401.58 | G26: Налог на имущество юридических лиц и индивидуальных предпринимателей
D27: 02 | E27: Жеке тұлғалардың мүлкiне салынатын салық | F27: 13860.717 | G27: Hалог на имущество физических лиц
A28: L01 Категория дохода | B28: L01 Класс дохода | C28: 3 | D28: L01 Специфика дохода | E28: Жер салығы | F28: 10114.546 | G28: Земельный налог
C29: 3 | D29: 02 | E29: Жер салығы | F29: 10114.546 | G29: Земельный налог
A30: L01 Категория дохода | B30: L01 Класс дохода | C30: 4 | D30: L01 Специфика дохода | E30: Көлiк құралдарына салынатын салық | F30: 119327.14 | G30: Hалог на транспортные средства
C31: 4 | D31: 01 | E31: Заңды тұлғалардан көлiк құралдарына салынатын салық | F31: 14703.929 | G31: Hалог на транспортные средства с юридических лиц
D32: 02 | E32: Жеке тұлғалардан көлiк құралдарына салынатын салық | F32: 104623.21 | G32: Hалог на транспортные средства с физических лиц
A33: L01 Категория дохода | B33: L01 Класс дохода | C33: 5 | D33: L01 Специфика дохода | E33: Бірыңғай жер салығы | F33: 3273.1892 | G33: Единый земельный налог
C34: 5 | D34: 01 | E34: Бірыңғай жер салығы | F34: 3273.1892 | G34: Единый земельный налог
A35: L01 Категория дохода | B35: 05 | C35: L01 Подкласс дохода | D35: L01 Специфика дохода | E35: Тауарларға, жұмыстарға және қызметтерге салынатын iшкi салықтар | F35: 4393387.2 | G35: Внутренние налоги на товары, работы и услуги
A36: L01 Категория дохода | B36: L01 Класс дохода | C36: 1 | D36: L01 Специфика дохода | E36: Қосылған құн салығы | F36: 3067591.1 | G36: Налог на добавленную стоимость
B37: 05 | C37: 1 | D37: 01 | E37: Қазақстан Республикасының аумағында өндiрiлген тауарларға, орындалған жұмыстарға және көрсетілген қызметтерге салынатын қосылған құн салығы | F37: 1104662.5 | G37: Hалог на добавленную стоимость на произведенные товары, выполненные работы и оказанные услуги на территории Республики Казахстан
D38: 02 | E38: Ресей Федерациясы және Беларусь Республикасының аумағынан импортталатын тауарларға салынатын қосылған құн салығынан басқа, Қазақстан Республикасының аумағына импортталатын тауарларға салынатын қосылған құн салығы | F38: 1107698.1 | G38: Hалог на добавленную стоимость на товары, импортируемые на территорию Республики Казахстан, кроме налога на добавленнуюстоимость на товары, импортируемые с территории Российской Федерации и Республики Беларусь
D39: 04 | E39: Резидент емес үшін қосылған құн салығы | F39: 122175.14 | G39: Налог на добавленную стоимость за нерезидента
D40: 14 | E40: Салық төлеушінің бұрын бюджеттен қайтарылған және салықтық тексеру жүргізу барысында қайтарылуы расталмаған қосылған құн салығының асып кеткен сомасын аударуы (қайтаруы), өсімпұл сомасын аударуы | F40: 4503.0997 | G40: Перечисление (возврат) налогоплательщиком суммы превышения налога на добавленную стоимость, ранее возвращенной из бюджета и не подтвержденной к возврату при проведении налоговой проверки, перечисление суммы пени
D41: 15 | E41: Еуразиялық экономикалық одаққа мүше мемлекеттер аумағынан импортталған тауарларға қосылған құн салығы | F41: 697884.35 | G41: Налог на добавленную стоимость на товары, импортированные стерритории государств-членов Евразийского экономического союза
D42: 16 | E42: Тауарлармен электрондық сауданы жүзеге асыру, жеке тұлғаларға электрондық нысанда қызметтер көрсету кезінде шетелдік компаниялардан түсетін қосылған құн салығы | F42: 30667.93 | G42: Налог на добавленную стоимость с иностранных интернет компаний при осуществлении электронной торговли товарами, оказании услуг в электронной форме физическим лицам
A43: L01 Категория дохода | B43: L01 Класс дохода | C43: 2 | D43: L01 Специфика дохода | E43: Акциздер | F43: 547340.06 | G43: Акцизы
...

Sheet табл 5
B2: Кесте 5 | D2: Таблица 5
B3: ШЫҒЫСТАРДЫҢ ВЕДОМСТВОЛЫҚ | D3: ИСПОЛНЕНИЕ ГОСУДАРСТВЕННОГО БЮДЖЕТА
B4: СЫНЫПТАМАСЫ БОЙЫНША | D4: ПО ВЕДОМСТВЕННОЙ
B5: МЕМЛЕКЕТТІК БЮДЖЕТТІҢ АТҚАРАЛУЫ | D5: КЛАССИФИКАЦИИ РАСХОДОВ
B6: (млн. теңге) | D6: (млн. тенге)
B8: Бағдарламалард_x000D_ ың_x000D_ əкімшісі/_x000D_ Администратор_x000D_ программ | C8: Атауы | D8: 2025 ж. қаңтар-шілде есеп/_x000D_ январь-июль 2025 г. | E8: Наименование
B9: 1 | C9: 2 | D9: 3 | E9: 4
C10: БАРЛЫҒЫ | D10: 18031425 | E10: ВСЕГО
B11: 101 | C11: Қазақстан Республикасы Президентінің Әкімшілігі | D11: 10302.321 | E11: Администрация Президента Республики Казахстан
B12: 106 | C12: Адам құқықтары жөніндегі ұлттық орталық | D12: 804.47123 | E12: Национальный центр по правам человека
B13: 107 | C13: Қазақстан Республикасы Жоғары Сот Кеңесінің Аппараты | D13: 1067.4368 | E13: Аппарат Высшего Судебного Совета Республики Казахстан
B14: 109 | C14: Қазақстан Республикасы үкіметінің Аппараты_x000D_ | D14: 3844.9471 | E14: Аппарат Правительства Республики Казахстан
B15: 110 | C15: Облыс мәслихатының аппараты | D15: 1736.6674 | E15: Аппарат маслихата области
B16: 111 | C16: Республикалық маңызы бар қала, астана мәслихатының аппараты | D16: 459.5372 | E16: Аппарат маслихата города республиканского значения, столицы
B17: 112 | C17: Аудан (облыстық маңызы бар қала) мәслихатының аппараты | D17: 8066.6056 | E17: Аппарат маслихата района (города областного значения)
B18: 120 | C18: Облыс әкімінің аппараты | D18: 34273.549 | E18: Аппарат акима области
B19: 121 | C19: Республикалық маңызы бар қала, астана әкімінің аппараты | D19: 5724.7868 | E19: Аппарат акима города республиканского значения, столицы
B20: 122 | C20: Аудан (облыстық маңызы бар қала) әкімінің аппараты | D20: 62260.456 | E20: Аппарат акима района (города областного значения)
B21: 123 | C21: Қаладағы аудан, аудандық маңызы бар қала, кент, ауыл, ауылдық округ әкімінің аппараты | D21: 265552.38 | E21: Аппарат акима района в городе, города районного значения, поселка, села, сельского округа
B22: 124 | C22: Аудандық маңызы бар қала, ауыл, кент, ауылдық округ әкімінің аппараты | D22: 202072.2 | E22: Аппарат акима города районного значения, села, поселка, сельского округа
... B224: 821 | C224: Ауданның (облыстық маңызы бар қаланың) қоғамдық даму бөлімі | D224: 762.1748 | E224: Отдел общественного развития района (города областного значения)

Sheet табл 6
A1: 6-кесте | D1: Таблица 6
A2: ШЫҒЫНДАРДЫҢ ЭКОНОМИКАЛЫҚ ЖІКТЕМЕСІ | D2: ИСПОЛНЕНИЕ ГОСУДАРСТВЕННОГО БЮДЖЕТА ПО
A3: БОЙЫНША МЕМЛЕКЕТТІК БЮДЖЕТТІК ОРЫНДАЛУЫ | D3: ЭКОНОМИЧЕСКОЙ КЛАССИФИКАЦИИ РАСХОДОВ
A4: (млн.теңге) | D4: (млн.тенге)
A5: Cанаты/_x000D_ Категория | B5: Iшкi сыныбы/_x000D_ Подкласс | C5: Атауы | D5: 2025 ж. қаңтар-шілде/январь-июль отчет 2025 г. | E5: Наименование
A7: 1 | B7: 2 | C7: 3 | D7: 4 | E7: 5
C8: БАРЛЫҒЫ | D8: 18031425 | E8: ВСЕГО
A9: 1 | C9: Ағымдағы шығындар | D9: 15371617 | E9: Текущие затраты
A10: 1 | B10: 110 | C10: Жалақы | D10: 2755362.3 | E10: Заработная плата
B11: 120 | C11: Жұмыс берушілердің жарналары | D11: 261271.42 | E11: Взносы работодателей
B12: 130 | C12: Қазақстан Республикасының заңнамалық актілеріне сәйкес азаматтардың жекелеген санаттарына жалақы төлеу және жарналар аудару | D12: 108909.95 | E12: Выплата заработной платы отдельным категориям граждан и отчисления взносов в соответствии с законодательными актами Республики Казахстан
B13: 140 | C13: Қорлар сатып алу | D13: 236901.77 | E13: Приобретение запасов
B14: 150 | C14: Қызметтер мен жұмыстарды сатып алу | D14: 2815634.4 | E14: Приобретение услуг и работ
B15: 160 | C15: Басқа да ағымдағы шығындар | D15: 1260790.4 | E15: Другие текущие затраты
B16: 170 | C16: Мемлекеттік емес қарыздар бойынша шығыстарды өтеу | D16: 25693.549 | E16: Возмещение расходов по негосударственным займам
B17: 210 | C17: Ішкі қарыздар бойынша сыйақы төлемдері | D17: 1797503.7 | E17: Выплаты вознаграждений по внутренним займам
B18: 220 | C18: Сыртқы заемдар бойынша сыйақылар төлеу | D18: 237711.73 | E18: Выплаты вознаграждений по внешним займам
B19: 310 | C19: Бюджеттік субсидиялар | D19: 1023959.7 | E19: Бюджетные субсидии
B20: 320 | C20: Жеке тұлғаларға берілетін трансферттер | D20: 3957426.2 | E20: Трансферты физическим лицам
B21: 340 | C21: Шетелге берiлетiн ағымдағы трансферттер | D21: 16651.768 | E21: Текущие трансферты за границу
B22: 360 | C22: Нысаналы жарна | D22: 873800 | E22: Целевой взнос
A23: 2 | C23: Күрделі шығындар | D23: 1985666.2 | E23: Капитальные затраты
A24: 2 | B24: 410 | C24: Негiзгi құралдарды, материалдық емес және биологиялық активтерді сатып алу | D24: 346961.39 | E24: Приобретение основных средств, нематериальных и биологических активов
B25: 420 | C25: Негізгі қаражатты күрделі жөндеу | D25: 236643.2 | E25: Капитальный ремонт основных средств
B26: 430 | C26: Дамуға бағытталған күрделі шығындар | D26: 1402061.6 | E26: Капитальные затраты, направленные на развитие
A27: 3 | C27: Бюджеттік кредиттер | D27: 281409.96 | E27: Бюджетные кредиты
A28: 3 | B28: 510 | C28: Ішкі бюджеттік кредиттер | D28: 281409.96 | E28: Внутренние бюджетные кредиты
A29: 4 | C29: Қаржы активтерін сатып алу | D29: 298697.01 | E29: Приобретение финансовых активов
A30: 4 | B30: 610 | C30: Қаржы активтерін сатып алу | D30: 298559.68 | E30: Приобретение финансовых активов
B31: 620 | C31: Елден тысқары жерлерден қаржы активтерін сатып алу | D31: 137.32896 | E31: Приобретение финансовых активов за пределами страны
A32: 6 | C32: Мемлекеттік-жекешелік әріптестік жобалар бойынша мемлекеттік міндеттемелерді орындау | D32: 94034.599 | E32: Выполнение государственных обязательств по проектам государственно-частного партнерства
A33: 6 | B33: 810 | C33: Мемлекеттік концессиялық міндеттемелерді орындау | D33: 94034.599 | E33: Выполнение государственных концессионных обязательств

Sheet табл 7
A1: 7-кесте | E1: Таблица 7
A2: РЕСПУБЛИКАЛЫҚ БЮДЖЕТТІҢ АТҚАРЫЛУЫ | E2: ИСПОЛНЕНИЕ РЕСПУБЛИКАНСКОГО БЮДЖЕТА
A3: (млн.теңге) | E3: (млн. тенге)
A5: Атауы | B5: 2022 ж. есеп/ 2022 г. отчет | C5: 2023 ж. есеп/ 2023 г. отчет | D5: 2024 ж. есеп/ 2024 г. отчет | F5: 2025 ж. қантар-шілде есеп/январь-июль отчет 2025 г. | G5: Наименование
D6: жылдық/ годовой | E6: қантар-шілде/январь-июль
A7: 1 | B7: 2 | C7: 3 | D7: 4 | E7: 5 | F7: 6 | G7: 7
A8: I. КІРІСТЕР | B8: 15963398 | C8: 19037979 | D8: 19624012 | E8: 10266523 | F8: 11543427 | G8: I. ДОХОДЫ
A9: Салықтық түсімдер_x000D_ оның iшiнде: | B9: 10026825 | C9: 12912428 | D9: 12307810 | E9: 6068667 | F9: 7239542.7 | G9: Налоговые поступления,_x000D_ в том числе:
A10: корпорациялық табыс салығы | B10: 2920802.8 | C10: 3889594.5 | D10: 3653190.8 | E10: 1783905.2 | F10: 2237617.7 | G10: корпоративный подоходный налог
A11: қосылған құн салығы | B11: 4226358.8 | C11: 5674110.6 | D11: 5179378.1 | E11: 2508711.3 | F11: 3067591.1 | G11: налог на добавленную стоимость
A12: акциздер | B12: 153619.22 | C12: 161890.43 | D12: 125189.66 | E12: 69445.916 | F12: 68224.961 | G12: акцизы
A13: Салықтық емес түсімдер | B13: 438204.42 | C13: 1617610.1 | D13: 1201438.2 | E13: 876897.02 | F13: 459781.24 | G13: Неналоговые поступления
A14: Негізгі капиталды сатудан түсетін түсімдер | B14: 6954.9546 | C14: 735.69631 | D14: 6170.4309 | E14: 4684.4031 | F14: 2062.5326 | G14: Поступления от продажи основного капитала
A15: Трансферттердің түсімдері | B15: 5491414.1 | C15: 4507205 | D15: 6108593.6 | E15: 3316274.8 | F15: 3842040.4 | G15: Поступления трансфертов
A16: II. ШЫҒЫНДАР | B16: 17791797 | C16: 21547819 | D16: 23106552 | E16: 12953781 | F16: 13382506 | G16: II. ЗАТРАТЫ
A17: 1. Жалпы сипаттағы мемлекеттiк қызметтер | B17: 1047844 | C17: 1137687.2 | D17: 1293447.3 | E17: 641631.58 | F17: 597063.17 | G17: 1. Государственные услуги общего характера
A18: 2. Қорғаныс | B18: 1073075.9 | C18: 1100070.9 | D18: 1038491.2 | E18: 520472.5 | F18: 484052.08 | G18: 2. Оборона
A19: 3. Қоғамдық тәртіп, қауіпсіздік, құқықтық, сот, қылмыстық-атқару қызметі | B19: 1074316.3 | C19: 1275903.8 | D19: 1287986.9 | E19: 643346.68 | F19: 682846.03 | G19: 3. Общественный порядок, безопасность, правовая, судебная, уголовно-исполнительная деятельность
... A45: Өтеу | B45: 208253.95 | C45: 660721.39 | D45: 1154283.9 | E45: 197820.32 | F45: 1527454 | G45: Погашение

Sheet табл 8 (дох)
B2: 8-кесте | H2: Таблица 8
F3: РЕСПУБЛИКАЛЫҚ БЮДЖЕТТІҢ АТҚАРЫЛУЫ/ ИСПОЛНЕНИЕ РЕСПУБЛИКАНСКОГО БЮДЖЕТА
B4: (млн.теңге) | H4: (млн.тенге)
B5: Санаты/ Категория | C5: Сыныбы/ Класс | D5: Сыныпшасы/ Подкласс | E5: Ерешелігі/ Специфика | F5: Атауы | G5: 2025 ж. қаңтар-шілде есеп/_x000D_ январь-июль отчет 2025 г. | H5: Наименование
B6: 1 | C6: 2 | D6: 3 | E6: 4 | F6: 5 | G6: 6 | H6: 7
F7: ТҮСІМДЕР | G7: 11692016 | H7: ПОСТУПЛЕНИЯ
F8: оның ішінде: | H8: в том числе:
F9: КІРІСТЕР | G9: 11543427 | H9: ДОХОДЫ
B10: 1 | F10: Салықтық түсімдер | G10: 7239542.7 | H10: Налоговые поступления
C11: 01 | F11: Табыс салығы | G11: 2237617.7 | H11: Подоходный налог
D12: 1 | F12: Корпорациялық табыс салығы | G12: 2237617.7 | H12: Корпоративный подоходный налог
B13: 1 | C13: 01 | D13: 1 | E13: 10 | F13: Мұнай секторы ұйымдарынан түсетін түсімдерді қоспағанда, ірі кәсіпкерлік субъектілерінен – заңды тұлғалардан алынатын корпоративтік табыс салығы | G13: 2237617.7 | H13: Корпоративный подоходный налог с юридических лиц – субъектов крупного предпринимательства, за исключением поступлений от организаций нефтяного сектора
C14: 05 | F14: Тауарларға, жұмыстарға және қызметтерге салынатын iшкi салықтар | G14: 3751789.7 | H14: Внутренние налоги на товары, работы и услуги
D15: 1 | F15: Қосылған құн салығы | G15: 3067591.1 | H15: Налог на добавленную стоимость
C16: 05 | D16: 1 | E16: 01 | F16: Қазақстан Республикасының аумағында өндiрiлген тауарларға, орындалған жұмыстарға және көрсетілген қызметтерге салынатын қосылған құн салығы | G16: 1104662.5 | H16: Hалог на добавленную стоимость на произведенные товары, выполненные работы и оказанные услуги на территории Республики Казахстан
E17: 02 | F17: Ресей Федерациясы және Беларусь Республикасының аумағынан импортталатын тауарларға салынатын қосылған құн салығынан басқа, Қазақстан Республикасының аумағына импортталатын тауарларға салынатын қосылған құн салығы | G17: 1107698.1 | H17: Hалог на добавленную стоимость на товары, импортируемые на территорию Республики Казахстан, кроме налога на добавленнуюстоимость на товары, импортируемые с территории Российской Федерации и Республики Беларусь
E18: 04 | F18: Резидент емес үшін қосылған құн салығы | G18: 122175.14 | H18: Налог на добавленную стоимость за нерезидента
E19: 14 | F19: Салық төлеушінің бұрын бюджеттен қайтарылған және салықтық тексеру жүргізу барысында қайтарылуы расталмаған қосылған құн салығының асып кеткен сомасын аударуы (қайтаруы), өсімпұл сомасын аударуы | G19: 4503.0997 | H19: Перечисление (возврат) налогоплательщиком суммы превышения налога на добавленную стоимость, ранее возвращенной из бюджета и не подтвержденной к возврату при проведении налоговой проверки, перечисление суммы пени
E20: 15 | F20: Еуразиялық экономикалық одаққа мүше мемлекеттер аумағынан импортталған тауарларға қосылған құн салығы | G20: 697884.35 | H20: Налог на добавленную стоимость на товары, импортированные стерритории государств-членов Евразийского экономического союза
E21: 16 | F21: Тауарлармен электрондық сауданы жүзеге асыру, жеке тұлғаларға электрондық нысанда қызметтер көрсету кезінде шетелдік компаниялардан түсетін қосылған құн салығы | G21: 30667.93 | H21: Налог на добавленную стоимость с иностранных интернет компаний при осуществлении электронной торговли товарами, оказании услуг в электронной форме физическим лицам
D22: 2 | F22: Акциздер | G22: 68224.961 | H22: Акцизы
D23: 2 | E23: 76 | F23: Қазақстан Республикасының аумағына Еуразиялық экономикалық одаққа мүше мемлекеттердің аумағынан әкелінетін темекі өнімдері | G23: 7013.0455 | H23: Табачные изделия, ввозимые на территорию Республики Казахстан с территории государств-членов Евразийского экономического союза
E24: 77 | F24: Қазақстан Республикасының аумағына Еуразиялық экономикалық одаққа мүше мемлекеттердің аумағынан әкелінетін спирттiң және (немесе) шарап материалының, алкоголь өнімдерінің барлық түрлерi | G24: 9691.7062 | H24: Все виды спирта и (или) виноматериала, алкогольной продукции, ввозимых на территорию Республики Казахстан с территории государств-членов Евразийского экономического союза
E25: 78 | F25: Қазақстан Республикасының аумағына Еуразиялық экономикалық одаққа мүше мемлекеттердің аумағынан әкелінетін акцизделетінөнімнің өзге түрлері | G25: 10.8828 | H25: Прочие виды подакцизной продукции, ввозимой на территорию Республики Казахстан с территории государств-членов Евразийского экономического союза
E26: 79 | F26: Қазақстан Республикасы аумағына Еуразиялық экономикалық одаққа мүше мемлекеттердің аумағынан әкелінетін бензин (авиациялықты қоспағанда) және дизель отыны | G26: 10633.958 | H26: Бензин (за исключением авиационного) и дизельное топливо, ввозимых на территорию Республики Казахстан с территории государств-членов Евразийского экономического союза
E27: 80 | F27: Еуразиялық экономикалық одаққа мүше болып табылмайтын мемлекеттердің аумағынан әкелінетін, Қазақстан Республикасының аумағына импортталатын спирттің және (немесе) шарап материалының, алкоголь өнімдерінің барлық түрлері | G27: 9132.9916 | H27: Все виды спирта и (или) виноматериала, алкогольной продукции, импортируемых на территорию Республики Казахстан с территории государств, не являющихся членами Евразийского экономического союза
E28: 81 | F28: Еуразиялық экономикалық одаққа мүше болып табылмайтын мемлекеттердің аумағынан әкелінетін, Қазақстан Республикасының аумағына импортталатын темекі өнімдері | G28: 29093.108 | H28: Табачные изделия, импортируемые на территорию Республики Казахстан с территории государств, не являющихся членами Евразийского экономического союза
E29: 82 | F29: Еуразиялық экономикалық одаққа мүше болып табылмайтын мемлекеттердің аумағынан әкелінетін, Қазақстан Республикасының аумағына импортталатын акцизделетін өнімдердің өзге түрлері | G29: 2577.8349 | H29: Прочие виды подакцизных продукций, импортируемые на территорию Республики Казахстан с территории государств, не являющихся членами Евразийского экономического союза
E30: 83 | F30: Еуразиялық экономикалық одаққа мүше болып табылмайтын мемлекеттер аумағынан әкелінетін, Қазақстан Республикасының аумағына импортталатын бензин (авиациялықты қоспағанда) және дизель отыны | G30: 71.434439 | H30: Бензин (за исключением авиационного) и дизельное топливо, импортируемых на территорию Республики Казахстан с территориигосударств, не являющихся членами Евразийского экономического союза
D31: 3 | F31: Табиғи және басқа да ресурстарды пайдаланғаны үшiн түсетiн түсiмдер | G31: 596259.49 | H31: Поступления за использование природных и других ресурсов
D32: 3 | E32: 01 | F32: Қалааралық және (немесе) халықаралық телефон байланысын, сондай-ақ ұялы байланысты бергені үшін төлемақы | G32: 7793.3647 | H32: Плата за предоставление междугородной и (или) международнойтелефонной связи, а также сотовой связи
E33: 02 | F33: Үстеме пайда салығы, мұнай секторы ұйымдарынан түсетін түсімдерден басқа | G33: 155.32398 | H33: Налог на сверхприбыль, за исключением поступлений от организаций нефтяного сектора
E34: 05 | F34: Бонустар, мұнай секторы ұйымдарынан түсетін түсімдерден басқа | G34: 19546.681 | H34: Бонусы, за исключением поступлений от организаций нефтяногосектора
E35: 06 | F35: Пайдалы қазбаларды өндіруге салынатын салық, мұнай секторы ұйымдарынан түсетін түсімдерден басқа | G35: 536314.47 | H35: Налог на добычу полезных ископаемых, за исключением поступлений от организаций нефтяного сектора
E36: 07 | F36: Мұнай секторы ұйымдарынан түсетін түсімдерді қоспағанда, экспортқа салынатын рента салығы | G36: 1792.9649 | H36: Рентный налог на экспорт, за исключением поступлений от организаций нефтяного сектора
E37: 09 | F37: Радиожиілік спектрін пайдаланғаны үшін төлем | G37: 27556.743 | H37: Плата за использование радиочастотного спектра
E38: 12 | F38: Мұнай секторы ұйымдарынан түсетін түсімдерді қоспағанда, өнімді бөлу туралы келісімшарт бойынша қызметін жүзеге асыратын жер қойнауын пайдаланушының қосымша төлемі | G38: 0.01176 | H38: Дополнительный платеж недропользователя, осуществляющего деятельность по контракту о разделе продукции, за исключением поступлений от организаций нефтяного сектора
E39: 13 | F39: Республикалық маңызы бар ерекше қорғалатын табиғи аумақтарды пайдаланғаны үшін төлем | G39: 6.7306857 | H39: Плата за использование особо охраняемых природных территорий республиканского значения
E40: 17 | F40: Цифрлық майнинг үшін төлемақы | G40: 3093.2012 | H40: Плата за цифровой майнинг
D41: 4 | F41: Кәсiпкерлiк және кәсiби қызметтi жүргiзгенi үшiн алынатын алымдар | G41: 10799.642 | H41: Сборы за ведение предпринимательской и профессиональной деятельности
...

Sheet табл 8 (расх)
G3: (млн. тенге)
A4: (млн.теңге)
A6: Санаты/ Категория | B6: Сыныбы/ Класс | C6: Сыныпшасы/ Подкласс | D6: Ерешелігі/ Специфика | E6: Атауы | F6: 2025 қаңтар-шілде есеп/_x000D_ январь-июль отчет 2025г. | G6: Наименование
A7: 1 | B7: 2 | C7: 3 | D7: 4 | E7: 5 | F7: 6 | G7: 7
E8: ШЫҒЫСТАР | F8: 13605661 | G8: РАСХОДЫ
E9: оның ішінде: | G9: в том числе:
E10: II. ШЫҒЫНДАР | F10: 13382506 | G10: II. ЗАТРАТЫ
A11: 01 | E11: Жалпы сипаттағы мемлекеттiк қызметтер | F11: 597063.17 | G11: Государственные услуги общего характера
B12: 1 | E12: Мемлекеттiк басқарудың жалпы функцияларын орындайтын өкiлдi, атқарушы және басқа органдар | F12: 120958.91 | G12: Представительные, исполнительные и другие органы, выполняющие общие функции государственного управления
C13: 101 | E13: Қазақстан Республикасы Президентінің Әкімшілігі | F13: 10302.321 | G13: Администрация Президента Республики Казахстан
A14: 01 | B14: 1 | C14: 101 | D14: 001 | E14: Мемлекет басшысының қызметін қамтамасыз ету | F14: 10302.321 | G14: Обеспечение деятельности Главы государства
C15: 106 | E15: Адам құқықтары жөніндегі ұлттық орталық | F15: 804.47123 | G15: Национальный центр по правам человека
C16: 106 | D16: 001 | E16: Адамның және азаматтың құқықтары мен бостандықтарының сақталуын қадағалау жөніндегі қызметтер | F16: 744.29123 | G16: Услуги по наблюдению за соблюдением прав и свобод человека и гражданина
D17: 005 | E17: Қазақстандағы ұлттық құқық қорғау тетіктерінің тиімділігін күшейту | F17: 60.18 | G17: Усиление эффективности национальных правозащитных механизмов в Казахстане
C18: 107 | E18: Қазақстан Республикасы Жоғары Сот Кеңесінің Аппараты | F18: 638.54975 | G18: Аппарат Высшего Судебного Совета Республики Казахстан
C19: 107 | D19: 001 | E19: Қазақстан Республикасы Жоғары Сот Кеңесінің қызметін қамтамасыз ету жөнінде көрсетілетін қызметтер | F19: 638.54975 | G19: Услуги по обеспечению деятельности Высшего Судебного СоветаРеспублики Казахстан
C20: 109 | E20: Қазақстан Республикасы үкіметінің Аппараты_x000D_ | F20: 2600.2279 | G20: Аппарат Правительства Республики Казахстан
C21: 109 | D21: 001 | E21: Қазақстан Республикасы Премьер-Министрінің қызметін қамтамасыз ету жөніндегі көрсетілетін қызметтер | F21: 2600.2279 | G21: Услуги по обеспечению деятельности Премьер-Министра Республики Казахстан
C22: 626 | E22: Қазақстан Республикасының Стратегиялық жоспарлау және реформалар агенттігі | F22: 10955.141 | G22: Агентство по стратегическому планированию и реформам Республики Казахстан
C23: 626 | D23: 001 | E23: Реформаларды қалыптастыруға және тиімді іске асыруға жәрдемдесу жөніндегі көрсетілетін қызметтер, стратегиялық жоспарлау, мемлекеттік статистикалық қызмет салаларында мемлекеттік саясатты жүзеге асыру, мемлекеттік басқару жүйесі мен квазиме | F23: 10955.141 | G23: Услуги по содействию в формировании и эффективной реализации реформ, осуществление государственной политики в сферах стратегического планирования, государственной статистической деятельности, участие в совершенствовании системы государствен
D24: 101 | E24: Өкілдiк шығындарға арналған қаражат есебiнен іс-шаралар өткізу | F24: 0 | G24: Проведение мероприятий за счет средств на представительскиезатраты
C25: 637 | E25: Қазақстан Республикасы Конституциялық Сотының Аппараты | F25: 939.80843 | G25: Аппарат Конституционного Суда Республики Казахстан
C26: 637 | D26: 001 | E26: Республика аумағында Қазақстан Республикасы Конституциясының үстемдігін қамтамасыз ету | F26: 939.80843 | G26: Обеспечение верховенства Конституции Республики Казахстан на территории Республики
C27: 690 | E27: Қазақстан Республикасының Орталық сайлау комиссиясы | F27: 4729.3762 | G27: Центральная избирательная комиссия Республики Казахстан
C28: 690 | D28: 001 | E28: Сайлау өткізуді ұйымдастыру | F28: 550.27862 | G28: Организация проведения выборов
D29: 002 | E29: Сайлау өткізу | F29: 3841.0036 | G29: Проведение выборов
D30: 004 | E30: Облыстық бюджеттерге аудандардың (облыстық маңызы бар қалалардың) әкімдерін сайлауды қамтамасыз етуге және өткізуге берілетін ағымдағы нысаналы трансферттер | F30: 320.1767 | G30: Целевые текущие трансферты областным бюджетам на обеспечение и проведение выборов акимов районов (городов областного значения)
D31: 101 | E31: Өкілдiк шығындарға арналған қаражат есебiнен іс-шаралар өткізу | F31: 17.917296 | G31: Проведение мероприятий за счет средств на представительскиезатраты
C32: 693 | E32: Материалдық-техникалық қамтамасыз ету басқармасы | F32: 13944.705 | G32: Управление материально-технического обеспечения
C33: 693 | D33: 001 | E33: Қазақстан Республикасы Парламентінің қызметін қамтамасыз ету жөніндегі көрсетілетін қызметтер | F33: 13944.705 | G33: Услуги по обеспечению деятельности Парламента Республики Казахстан
C34: 694 | E34: Қазақстан Республикасы Президентiнiң Іс басқармасы | F34: 76044.307 | G34: Управление Делами Президента Республики Казахстан
C35: 694 | D35: 001 | E35: Қазақстан Республикасы Президенті Іс Басқармасының мемлекеттік функциялары мен өкілеттіктерін жүзеге асыруды қамтамасыз ету жөніндегі қызметтер | F35: 41308.958 | G35: Услуги по обеспечению осуществления государственных функцийи полномочий Управления делами Президента Республики Казахстан
D36: 009 | E36: Қазақстан Республикасы Президенттік орталығының қызметін қамтамасыз ету жөніндегі көрсетілетін қызметтер | F36: 740.71496 | G36: Услуги по обеспечению деятельности Президентского центра Республики Казахстан
D37: 109 | E37: Қазақстан Республикасы Үкіметінің шұғыл шығындарға арналғанрезервінің есебінен ағымды іс-шаралар өткізу_x000D_ | F37: 6768.0732 | G37: Проведение текущих мероприятий за счет резерва Правительства Республики Казахстан на неотложные затраты_x000D_
D38: 139 | E38: Қазақстан Республикасы Үкіметінің шұғыл шығындарға арналғанрезервінің есебінен дамуға бағытталған іс-шаралар өткізу | F38: 27226.56 | G38: Проведение мероприятий, направленных на развитие за счет резерва Правительства Республики Казахстан на неотложные затраты
B39: 2 | E39: Қаржылық қызмет | F39: 10521.148 | G39: Финансовая деятельность
C40: 217 | E40: Қазақстан Республикасының Қаржы министрлiгi | F40: 8031.5709 | G40: Министерство финансов Республики Казахстан
B41: 2 | C41: 217 | D41: 002 | E41: Халықаралық қаржы ұйымдары қаржыландыратын инвестициялық жобалардың аудитiн жүзеге асыру | F41: 0 | G41: Осуществление аудита инвестиционных проектов, финансируемыхмеждународными финансовыми организациями
D42: 094 | E42: Мемлекеттік активтерді басқару | F42: 99.205037 | G42: Управление государственными активами
D43: 205 | E43: Шекарадағы өткізу пункттерін жаңғырту және техникалық толықжарақтандыру | F43: 7932.3659 | G43: Модернизация и техническое дооснащение пунктов пропуска на границе
...

Sheet табл 9
B2: Кесте 9 | D2: Таблица 9
B3: ШЫҒЫСТАРДЫҢ ВЕДОМСТВОЛЫҚ | D3: ИСПОЛНЕНИЕ РЕСПУБЛИКАНСКОГО БЮДЖЕТА
B4: СЫНЫПТАМАСЫ БОЙЫНША | D4: ПО ВЕДОМСТВЕННОЙ
B5: РЕСПУБЛИКАЛЫҚ БЮДЖЕТТІҢ АТҚАРАЛУЫ | D5: КЛАССИФИКАЦИИ РАСХОДОВ
B6: (млн. теңге) | D6: (млн. тенге)
B8: Бағдарламалард_x000D_ ың_x000D_ əкімшісі/_x000D_ Администратор_x000D_ программ | C8: Атауы | D8: 2025 ж. қаңтар-шілде есеп/_x000D_ январь-июль 2025 г. | E8: Наименование
B9: 1 | C9: 2 | D9: 3 | E9: 4
C10: БАРЛЫҒЫ | D10: 13605661 | E10: ВСЕГО
B11: 101 | C11: Қазақстан Республикасы Президентінің Әкімшілігі | D11: 10302.321 | E11: Администрация Президента Республики Казахстан
B12: 106 | C12: Адам құқықтары жөніндегі ұлттық орталық | D12: 804.47123 | E12: Национальный центр по правам человека
B13: 107 | C13: Қазақстан Республикасы Жоғары Сот Кеңесінің Аппараты | D13: 1067.4368 | E13: Аппарат Высшего Судебного Совета Республики Казахстан
B14: 109 | C14: Қазақстан Республикасы үкіметінің Аппараты_x000D_ | D14: 3844.9471 | E14: Аппарат Правительства Республики Казахстан
B15: 201 | C15: Қазақстан Республикасының Iшкi iстер министрлiгi | D15: 331278.37 | E15: Министерство внутренних дел Республики Казахстан
B16: 202 | C16: Қазақстан Республикасының Төтенше жағдайлар министрлiгi | D16: 78700.162 | E16: Министерство по чрезвычайным ситуациям Республики Казахстан
B17: 204 | C17: Қазақстан Республикасының Сыртқы iстер министрлiгi | D17: 73518.479 | E17: Министерство иностранных дел Республики Казахстан
B18: 207 | C18: Қазақстан Республикасының Экология және табиғи ресурстар министрлігі | D18: 45451.131 | E18: Министерство экологии и природных ресурсов Республики Казахстан
B19: 208 | C19: Қазақстан Республикасының Қорғаныс министрлiгi | D19: 361690.96 | E19: Министерство обороны Республики Казахстан
B20: 211 | C20: Қазақстан Республикасының Сауда және интеграция министрлігі | D20: 8918.6847 | E20: Министерство торговли и интеграции Республики Казахстан
B21: 212 | C21: Қазақстан Республикасының Ауыл шаруашылығы министрлiгi | D21: 333839.83 | E21: Министерство сельского хозяйства Республики Казахстан
B22: 213 | C22: Қазақстан Республикасының Еңбек және халықты әлеуметтiк қорғау министрлiгi | D22: 3480572 | E22: Министерство труда и социальной защиты населения РеспубликиКазахстан
... B50: 694 | C50: Қазақстан Республикасы Президентiнiң Іс басқармасы | D50: 123192.3 | E50: Управление Делами Президента Республики Казахстан

Sheet табл 10
A1: 10-кесте ШЫҒЫНДАРДЫҢ ЭКОНОМИКАЛЫҚ ЖІКТЕМЕСІ БОЙЫНША РЕСПУБЛИКАЛЫҚ БЮДЖЕТТІК ОРЫНДАЛУЫ (млн.теңге) | E1: Таблица 10 ИСПОЛНЕНИЕ РЕСПУБЛИКАНСКОГО БЮДЖЕТА ПО ЭКОНОМИЧЕСКОЙ КЛАССИФИКАЦИИ РАСХОДОВ (млн. тенге)
A3: Cанаты/_x000D_ Категория | B3: Iшкi сыныбы/_x000D_ Подкласс | C3: Ерекшелiгi/_x000D_ Специфика | D3: Атауы | F3: 2025 ж. қаңтар-шілде/_x000D_ январь-июль отчет 2025 г. | G3: Наименование
A4: 1 | B4: 2 | C4: 3 | D4: 4 | F4: 5 | G4: 6
D5: БАРЛЫҒЫ | F5: 13605661 | G5: ВСЕГО
A6: 1 | D6: Ағымдағы шығындар | F6: 12763971 | G6: Текущие затраты
A7: L01 Категория расходов | B7: 110 | D7: Жалақы | F7: 666220.08 | G7: Заработная плата
A8: 1 | B8: 110 | C8: 111 | D8: Еңбекке ақы төлеу | F8: 491268.8 | G8: Оплата труда
A9: 1 | C9: 112 | D9: Қосымша ақшалай төлемдер | F9: 83894.576 | G9: Дополнительные денежные выплаты
A10: 1 | C10: 113 | D10: Өтемақы төлемдері | F10: 86307.043 | G10: Компенсационные выплаты
A11: 1 | C11: 114 | D11: Міндетті кәсіптік зейнетақы жарналары | F11: 130.52484 | G11: Обязательные профессиональные пенсионные взносы
A12: 1 | C12: 116 | D12: Жұмыс берушілердің міндетті зейнетақы жарналары | F12: 4619.1388 | G12: Обязательные пенсионные взносы работодателей
A13: L01 Категория расходов | B13: 120 | D13: Жұмыс берушілердің жарналары | F13: 41126.634 | G13: Взносы работодателей
A14: 1 | B14: 120 | C14: 121 | D14: Әлеуметтік салық | F14: 14971.537 | G14: Социальный налог
A15: 1 | C15: 122 | D15: Мемлекеттiк әлеуметтiк сақтандыру қорына әлеуметтiк аударымдар | F15: 20133.096 | G15: Социальные отчисления в Государственный фонд социального страхования
A16: 1 | C16: 123 | D16: Мiндеттi сақтандыру жарналары | F16: 315.69274 | G16: Взносы на обязательное страхование
A17: 1 | C17: 124 | D17: Міндетті әлеуметтік медициналық сақтандыруға аударымдар | F17: 5706.3085 | G17: Отчисления на обязательное социальное медицинское страхование
A18: L01 Категория расходов | B18: 130 | D18: Қазақстан Республикасының заңнамалық актілеріне сәйкес азаматтардың жекелеген санаттарына жалақы төлеу және жарналар аудару | F18: 47276.701 | G18: Выплата заработной платы отдельным категориям граждан и отчисления взносов в соответствии с законодательными актами Республики Казахстан
A19: 1 | B19: 130 | C19: 131 | D19: Техникалық персоналдың еңбегіне ақы төлеу | F19: 41144.366 | G19: Оплата труда технического персонала
A20: 1 | C20: 134 | D20: Алқа билерге сыйақылар төлеу | F20: 294.48479 | G20: Выплата вознаграждений присяжным заседателям
A21: 1 | C21: 135 | D21: Техникалық персонал бойынша жұмыс берушілердің жарналары | F21: 5168.996 | G21: Взносы работодателей по техническому персоналу
A22: 1 | C22: 136 | D22: Техникалық персоналдың ел iшiндегi iссапарлары мен қызметтiк сапарлары | F22: 655.64717 | G22: Командировки и служебные разъезды внутри страны технического персонала
A23: 1 | C23: 137 | D23: Қорғаушы мәжілістердің қызметтiк сапарлар | F23: 13.206975 | G23: Командировочные расходы присяжных заседателей
A24: L01 Категория расходов | B24: 140 | D24: Қорлар сатып алу | F24: 82369.683 | G24: Приобретение запасов
A25: 1 | B25: 140 | C25: 141 | D25: Азық-түлiк өнiмдерiн сатып алу | F25: 37704.465 | G25: Приобретение продуктов питания
A26: 1 | C26: 142 | D26: Дәрілік заттар және медициналық мақсаттағы өзге де бұйымдарды сатып алу | F26: 4804.5507 | G26: Приобретение лекарственных средств и прочих изделий медицинского назначения
A27: 1 | C27: 143 | D27: Заттай мүлiктердi, басқа да киім нысанын және арнаулы киім-кешектер сатып алу, тiгу және жөндеу | F27: 9648.4513 | G27: Приобретение, пошив и ремонт предметов вещевого имущества идругого форменного и специального обмундирования
A28: 1 | C28: 144 | D28: Отын, жанар-жағар май материалдарын сатып алу | F28: 17261.563 | G28: Приобретение топлива, горюче-смазочных материалов
A29: 1 | C29: 149 | D29: Өзге де қорларды сатып алу | F29: 12950.653 | G29: Приобретение прочих запасов
A30: L01 Категория расходов | B30: 150 | D30: Қызметтер мен жұмыстарды сатып алу | F30: 654879.36 | G30: Приобретение услуг и работ
A31: 1 | B31: 150 | C31: 151 | D31: Коммуналдық қызметтерге ақы төлеу | F31: 26965.145 | G31: Оплата коммунальных услуг
A32: 1 | C32: 152 | D32: Байланыс қызметтерiне ақы төлеу | F32: 11475.507 | G32: Оплата услуг связи
A33: 1 | C33: 153 | D33: Көлiктiк қызмет көрсетулерге ақы төлеу | F33: 6518.5967 | G33: Оплата транспортных услуг
A34: 1 | C34: 154 | D34: Зерттеулер бойынша қызметтерге ақы төлеу | F34: 83318.261 | G34: Оплата услуг по исследованиям
A35: 1 | C35: 155 | D35: Мемлекеттiк әлеуметтiк тапсырыс шеңберiнде көрсетілетін қызметтерге ақы төлеу | F35: 24.553732 | G35: Оплата услуг в рамках государственного социального заказа
A36: 1 | C36: 156 | D36: Консалтингтік қызметтерге ақы төлеу | F36: 468.07018 | G36: Оплата консалтинговых услуг
A37: 1 | C37: 157 | D37: Форумдар, семинарлар, конференциялар өткізуге және имидждік іс-шараларға арналған қызметтерге ақы төлеу | F37: 85.285255 | G37: Оплата услуг на проведение форумов, семинаров, конференций и на имиджевые мероприятия
A38: 1 | C38: 158 | D38: Ақпараттандыру саласындағы жұмыстар мен қызметтерге ақы төлеу | F38: 15388.719 | G38: Оплата работ и услуг в сфере информатизации
A39: 1 | C39: 159 | D39: Өзге де қызметтер мен жұмыстарға ақы төлеу | F39: 510635.22 | G39: Оплата прочих услуг и работ
A40: L01 Категория расходов | B40: 160 | D40: Басқа да ағымдағы шығындар | F40: 811568.19 | G40: Другие текущие затраты
A41: 1 | B41: 160 | C41: 161 | D41: Ел iшiндегi iссапарлар мен қызметтiк сапарлар | F41: 13636.275 | G41: Командировки и служебные разъезды внутри страны
...

Sheet таб 11
A1: 11-кесте ШЫҒЫНДАРДЫҢ ЭКОНОМИКАЛЫҚ ЖІКТЕМЕСІ БОЙЫНША ЖЕРГІЛІКТІ БЮДЖЕТТІК ОРЫНДАЛУЫ (млн.теңге) | E1: Таблица 11 ИСПОЛНЕНИЕ МЕСТНОГО БЮДЖЕТА ПО ЭКОНОМИЧЕСКОЙ КЛАССИФИКАЦИИ РАСХОДОВ (млн. тенге)
A3: Cанаты/_x000D_ Категория | B3: Iшкi сыныбы/_x000D_ Подкласс | C3: Ерекшелiгi/_x000D_ Специфика | D3: Атауы | F3: 2025 ж. қаңтар-шілде/_x000D_ январь-июль отчет 2025 г. | G3: Наименование
A4: 1 | B4: 2 | C4: 3 | D4: 4 | F4: 5 | G4: 6
D5: БАРЛЫҒЫ | F5: 8922479.3 | G5: ВСЕГО
A6: 1 | D6: Ағымдағы шығындар | F6: 6640100.4 | G6: Текущие затраты
A7: L01 Категория расходов | B7: 110 | D7: Жалақы | F7: 2089142.2 | G7: Заработная плата
A8: 1 | B8: 110 | C8: 111 | D8: Еңбекке ақы төлеу | F8: 1835834.1 | G8: Оплата труда
A9: 1 | C9: 112 | D9: Қосымша ақшалай төлемдер | F9: 63570.066 | G9: Дополнительные денежные выплаты
A10: 1 | C10: 113 | D10: Өтемақы төлемдері | F10: 160352.72 | G10: Компенсационные выплаты
A11: 1 | C11: 114 | D11: Міндетті кәсіптік зейнетақы жарналары | F11: 7.0122609 | G11: Обязательные профессиональные пенсионные взносы
A12: 1 | C12: 116 | D12: Жұмыс берушілердің міндетті зейнетақы жарналары | F12: 29378.324 | G12: Обязательные пенсионные взносы работодателей
A13: L01 Категория расходов | B13: 120 | D13: Жұмыс берушілердің жарналары | F13: 220144.78 | G13: Взносы работодателей
A14: 1 | B14: 120 | C14: 121 | D14: Әлеуметтік салық | F14: 100132.36 | G14: Социальный налог
A15: 1 | C15: 122 | D15: Мемлекеттiк әлеуметтiк сақтандыру қорына әлеуметтiк аударымдар | F15: 73570.265 | G15: Социальные отчисления в Государственный фонд социального страхования
A16: 1 | C16: 123 | D16: Мiндеттi сақтандыру жарналары | F16: 681.11039 | G16: Взносы на обязательное страхование
A17: 1 | C17: 124 | D17: Міндетті әлеуметтік медициналық сақтандыруға аударымдар | F17: 45761.051 | G17: Отчисления на обязательное социальное медицинское страхование
A18: L01 Категория расходов | B18: 130 | D18: Қазақстан Республикасының заңнамалық актілеріне сәйкес азаматтардың жекелеген санаттарына жалақы төлеу және жарналар аудару | F18: 61633.245 | G18: Выплата заработной платы отдельным категориям граждан и отчисления взносов в соответствии с законодательными актами Республики Казахстан
A19: 1 | B19: 130 | C19: 131 | D19: Техникалық персоналдың еңбегіне ақы төлеу | F19: 53249.682 | G19: Оплата труда технического персонала
A20: 1 | C20: 133 | D20: Негізгі жұмыс орны бойынша мәслихат депутаттарына орташа жалақыны өтеу | F20: 0.534632 | G20: Возмещение средней заработной платы депутатам маслихата по их основному месту работы
