Workbook
Name \E: #REF!
Name \E: #REF!
Name _____________________MS798: #REF!
Name _____________________MS798: #REF!
Name _____________________tab1: #REF!
Name _____________________tab2: #REF!
Name _____________________tab6798: #REF!
Name ____________________MS798: #REF!
Name ____________________tab1: #REF!
Name ____________________tab2: #REF!
Name ____________________tab6798: #REF!
Name ___________________MS798: #REF!
Name ___________________tab1: #REF!
Name ___________________tab2: #REF!
Name ___________________tab6798: #REF!
Name __________________MS798: #REF!
Name __________________tab1: #REF!
Name __________________tab2: #REF!
Name __________________tab6798: #REF!
Name _________________MS798: #REF!
Name _________________prt1: #N/A
Name _________________prt2: #N/A
Name _________________prt3: #N/A
Name _________________prt4: #N/A
Name _________________prt5: #N/A
Name _________________prt6: #N/A
Name _________________prt7: #N/A
Name _________________prt8: #N/A
Name _________________tab1: #REF!
Name _________________tab2: #REF!
Name _________________tab6798: #REF!
Name ________________MS798: #REF!
Name ________________prt1: #N/A
Name ________________prt2: #N/A
Name ________________prt3: #N/A
Name ________________prt4: #N/A
Name ________________prt5: #N/A
Name ________________prt6: #N/A
Name ________________prt7: #N/A
Name ________________prt8: #N/A
Name ________________tab1: #REF!
Name ________________tab2: #REF!
Name ________________tab6798: #REF!
Name _______________MS798: #REF!
Name _______________prt1: #N/A
Name _______________prt2: #N/A
Name _______________prt3: #N/A
Name _______________prt4: #N/A
Name _______________prt5: #N/A
Name _______________prt6: #N/A
Name _______________prt7: #N/A
Name _______________prt8: #N/A
Name _______________tab1: #REF!
Name _______________tab2: #REF!
Name _______________tab6798: #REF!
Name ______________MS798: #REF!
Name ______________prt1: #N/A
Name ______________prt2: #N/A
Name ______________prt3: #N/A
Name ______________prt4: #N/A

Sheet табл 1
A1: 1-кесте | I1: Таблица 1
A3: НЕГІЗГІ МАКРОЭКОНОМИКАЛЫҚ ИНДИКАТОРЛАР/
A4: ОСНОВНЫЕ МАКРОЭКОНОМИЧЕСКИЕ ИНДИКАТОРЫ
A6: Атауы | B6: 2019 жыл/ 2019 год | C6: 2020 жыл/ 2020 год | D6: 2021 жыл/ 2021 год | E6: 2022 жыл/ 2022 год | F6: 2023 жыл/ 2023 год | G6: 2024 жыл/ 2024 год | H6: 2025 ж. 1 наурыздағы есеп/ отчет на 1 марта 2025 г. | I6: Наименование
A7: 1 | B7: 2 | C7: 3 | D7: 4 | E7: 5 | F7: 6 | G7: 7 | H7: 8 | I7: 9
A8: Жалпы ішкi өнiм, млрд. теңге | B8: 69532.626 | C8: 70649 | D8: 83951.587 | E8: 65487.797 | F8: 120561.1 | G8: 84962.621 | H8: 135251.66 | I8: Валовой внутренний продукт, млрд.тенге январь-декабрь 2024 год (опер. данные)
A9: өткен жылдың тиiстi кезеңiндегi нақты есептеудегi %-бен | B9: 104.5 | C9: 97.5 | D9: 103.3 | E9: 103 | F9: 105.1 | G9: 104.1 | H9: 104.8 | I9: в % к соответствующему периоду предыдущего года
A10: Өнеркәсiп өнiмiнiң көлемi, млрд. теңге | B10: 29380.342 | C10: 26743.4 | D10: 37047.6 | E10: 4157.4 | F10: 46401.716 | G10: 50124.86 | H10: 9112 | I10: Объем промышленного производства, млрд.тенге (январь-февраль 2025г.)
A11: өткен жылдың тиiстi кезеңiне %-бен | B11: 104.1 | C11: 99.3 | D11: 103.8 | E11: 97.2 | F11: 104.3 | G11: 102.8 | H11: 105.9 | I11: в % к соответствующему периоду предыдущего года
A12: Мембюджетке кірістер, млрд. теңге | B12: 12758.479 | C12: 14521.191 | D12: 15847.431 | E12: 20248.101 | F12: 24917.246 | G12: ='[46]табл 2 '!C8/1000 -> 27132.165 | H12: ='табл 2 '!C8/1000 -> 5021.3126 | I12: Доходы в госбюджет, млрд.тенге
A13: ЖIӨ-ге %-бен | B13: 18.502241 | C13: 20.535071 | D13: =D12/D8*100 -> 18.876869 | E13: =E12/E8*100 -> 30.918891 | G13: =G12/G8*100 -> 31.934237 | H13: =H12/H8*100 -> 3.71257 | I13: в % к ВВП
A14: Мембюджеттен шығындар, млрд. теңге | B14: 13535.581 | C14: 16725.097 | D14: 17951.888 | E14: 21532.543 | F14: 26760 | G14: ='[46]табл 2 '!C18/1000 -> 30318.236 | H14: ='табл 2 '!C18/1000 -> 4380.2348 | I14: Затраты из госбюджета, млрд. тенге
A15: ЖIӨ-ге %-бен | B15: 19.629188 | C15: 23.651714 | D15: =D14/D8*100 -> 21.38362 | E15: =E14/E8*100 -> 32.880238 | F15: 35.421743 | G15: =G14/G8*100 -> 35.684206 | H15: =H14/H8*100 -> 3.2385811 | I15: в % к ВВП
A16: Таза бюджеттік кредит беру, млрд. теңге | B16: 262.88084 | C16: 261.98101 | D16: 267.33754 | E16: 592.68034 | F16: 466.44174 | G16: ='[46]табл 2 '!C34/1000 -> 198.40855 | H16: ='табл 3'!F34/1000 -> 12.537673 | I16: Чистое бюджетное кредитование, млрд. тенге
A17: ЖIӨ-ге %-бен | B17: 0.38122761 | C17: 0.37047917 | D17: =D16/D8*100 -> 0.31844251 | E17: =E16/E8*100 -> 0.9050241 | F17: 0.61742075 | G17: =G16/G8*100 -> 0.23352452 | H17: =H16/H8*100 -> 0.0092698848 | I17: в % к ВВП
A18: Қаржылық активтермен болатын операциялар бойынша сальдо, млрд. теңге | B18: 245.32373 | C18: 340.26326 | D18: 163.01136 | E18: 292.00158 | F18: 501.9047 | G18: ='[46]табл 2 '!C37/1000 -> 201.56181 | H18: ='табл 2 '!C37/1000 -> 68.054292 | I18: Сальдо по операциям с финансовыми активами, млрд.тенге
A19: ЖIӨ-ге %-бен | B19: 0.35576643 | C19: 0.48118163 | D19: =D18/D8*100 -> 0.19417306 | E19: =E18/E8*100 -> 0.44588701 | F19: 0.66436244 | G19: =G18/G8*100 -> 0.23723586 | H19: =H18/H8*100 -> 0.050316787 | I19: в % к ВВП
A20: Мембюджеттiң тапшылығы (-) / профицитi (+), млрд. теңге | B20: -1285.3067 | C20: -2806.1502 | D20: -2534.8062 | E20: -2169.1247 | F20: -2811.1006 | G20: ='[46]табл 2 '!C40/1000 -> -3586.0419 | H20: ='табл 3'!F40/1000 -> 560.48587 | I20: Дефицит (-) / профицит (+) госбюджета, млрд.тенге
A21: ЖIӨ-ге %-бен | B21: -1.8639412 | C21: -3.9683036 | D21: =D20/D8*100 -> -3.0193666 | E21: =E20/E8*100 -> -3.3122579 | F21: -3.7210045 | G21: =G20/G8*100 -> -4.2207288 | H21: =H20/H8*100 -> 0.4144022 | I21: в % к ВВП
A22: Тұтыну бағаларының индексі өткен жылдың айына, %-бен | B22: 105.4 | C22: 107.5 | D22: 108.4 | E22: 120.3 | F22: 109.5 | G22: 108.9 | H22: 109.4 | I22: Индекс потребительских цен к февралю предыдущего года, в %
A23: орташа есеппен өткен жылдың тиiстi кезеңiндегi кезге арналған, %-бен | B23: 105.3 | C23: 106.8 | D23: 108 | E23: 115 | G23: 108.6 | H23: 108.8 | I23: в среднем за период к соответствующему периоду предыдущего года, в %
A24: Орташа айлық атаулы жалақы 1 қызметкердың, теңге | B24: 186815 | C24: 220848 | D24: 268051 | E24: 303055 | F24: 350542 | G24: 390328 | H24: 434982 | I24: Среднемесячная номинальная заработная плата 1 работника, тенге (4 квартал 2024г.)
A25: өткен жылдың тиiстi кезеңiне %-бен | B25: 114.8 | C25: 104.4 | D25: 115.3 | E25: 112.2 | F25: 116.9 | G25: 111.3 | H25: 110.5 | I25: в % к соответствующему периоду предыдущего года
A26: Экспорт, млн. АҚШ долл. | B26: 58065.6 | C26: 46 949,7 2 | D26: 54549.5 | E26: ____ | F26: 71274.7 | G26: 73884.5 | H26: 5107.9 | I26: Экспорт, млн. долл. США (январь 2025г.)
A27: өткен жылдың тиiстi кезеңiне %-бен | B27: 95 | C27: 80.9 | D27: 124.5 | I27: в % к соответствующему периоду предыдущего года
A28: Импорт, млн. АҚШ долл. | B28: 39709.3 | C28: 38 081,4 2 | D28: 36825.9 | E28: ____ | F28: 54643.5 | G28: 53590.3 | H28: 4035.9 | I28: Импорт, млн. долл. США (январь 2025г.)
A29: өткен жылдың тиiстi кезеңiне %-бен | B29: 118 | C29: 95.9 | D29: 104.2 | I29: в % к соответствующему периоду предыдущего года
A30: Сауда балансының сальдосы, млн. АҚШ долл. | B30: 18356.3 | C30: 8969 | D30: 17723.6 | E30: ____ | F30: 16631.2 | G30: =G26-G28 -> 20294.2 | H30: =H26-H28 -> 1072 | I30: Сальдо торгового баланса, млн. долл. США
A31: Теңгенiң АҚШ долларына қарағандағы ресми айырбас бағамы: | I31: Официальный обменный курс тенге к доллару США:
A32: кезеңнiң аяғындағы | B32: 381.18 | C32: 420.71 | D32: 433.83 | E32: 459.92 | F32: 448.17 | G32: 525.11 | H32: 501.49 | I32: на конец периода
A33: кезең бойынша орташа | B33: 382.75 | C33: 412.95 | D33: 433.66 | E33: 460.48 | F33: 451.28 | G33: 469.44 | H33: 506.03 | I33: в среднем за период февраль 2025 года
A35: Ақпарат көзi: / Источник:
A36: Қазақстан Республикасының Қаржы министрлiгi / Министерство финансов Республики Казахстан.
A37: Ұлттық статистика бюросы Қазақстан Республикасының Стратегиялық жоспарлау және реформалар агенттігі / Бюро национальной статистики Агентства по стратегическому планированию и реформам Республики Казахстан
A38: Қазақстан Республикасының Ұлттық Банкi / Национальный Банк Республики Казахстан.
A39: Ескерту: / Примечание:
A40: 1 - Ұлттық статистика бюросы Қазақстан Республикасының Стратегиялық жоспарлау және реформалар агенттігінің деректері бойынша /Объем ВВП по отчетным данным Бюро национальной статистики Агентства по стратегическому планированию и реформам Республики Казахстан
A41: 2 - Ұлттық статистика бюросы Қазақстан Республикасының Стратегиялық жоспарлау және реформалар агенттігінің деректері бойынша /По данным Бюро национальной статистики Агентства по стратегическому планированию и реформам Республики Казахстан
A42: 3 - Ұлттық статистика бюросы Қазақстан Республикасының Стратегиялық жоспарлау және реформалар агенттігінің деректері бойынша /По данным Бюро национальной статистики Агентства по стратегическому планированию и реформам Республики Казахстан

Sheet табл 2 
A1: 2-кесте | F1: Таблица - 2
A2: МЕМЛЕКЕТТІК ЖӘНЕ РЕСПУБЛИКАЛЫҚ | F2: СРАВНИТЕЛЬНЫЙ АНАЛИЗ ИСПОЛНЕНИЯ
A3: БЮДЖЕТТЕР АТҚАРЫЛУЫНЫҢ САЛЫСТЫРМА ТАЛДАУЫ | F3: ГОСУДАРСТВЕННОГО И РЕСПУБЛИКАНСКОГО БЮДЖЕТОВ
A5: Атауы | B5: Мемлекеттік бюджет / Государственный бюджет | F5: Республикалық бюджет / Республиканский бюджет | J5: Наименование
B6: 2025 жылға түзету енгізілген бюджет (млн. теңге)/ скорректированный бюджет на 2025 год (млн.тенге) | C6: 2025 жылғы қаңтар-ақпан атқарылуы (млн. теңге)/ исполнение за январь-февраль 2025 года (млн.тенге) | D6: бір жылға түзету енгізілген бюджеттің атқарылу %-ы/% исполнения к скорректированному бюджету на год | E6: 2024 ж. қаңтар-ақпан %-бен 2025 ж. қаңтар-ақпанына/ 2025 г. январь-февраль в % к январю-февралю 2024 г. | F6: 2025 жылға түзету енгізілген бюджет (млн. теңге)/ скорректированный бюджет на 2025 год (млн.тенге) | G6: 2025 жылғы қаңтар-ақпан атқарылуы (млн. теңге)/ исполнение за январь-февраль 2025 года (млн.тенге) | H6: бір жылға түзету енгізілген бюджеттің атқарылу %-ы/% исполнения к скорректированному бюджету на год | I6: 2024 ж. қаңтар-ақпан %-бен 2025 ж. қаңтар-ақпанына/ 2025 г. январь-февраль в % к январю-февралю 2024 г.
A7: 1 | B7: 2 | C7: 3 | D7: 4 | E7: 5 | F7: 6 | G7: 7 | H7: 8 | I7: 9 | J7: 10
A8: I. КІРІСТЕР | B8: 28637489 | C8: 5021312.6 | D8: 17.534054 | E8: 118.86761 | F8: 21392055 | G8: 3634592.6 | H8: 16.990386 | I8: 121.60965 | J8: I. ДОХОДЫ
A9: Салықтық түсімдер оның iшiнде: | B9: 22588651 | C9: 3726749.7 | D9: 16.498328 | E9: 120.50161 | F9: 15193344 | G9: 2301508.5 | H9: 15.148137 | I9: 124.43169 | J9: Налоговые поступления, в том числе:
A10: корпорациялық табыс салығы | B10: 6573801.5 | C10: 928750.33 | D10: 14.128056 | E10: 129.83955 | F10: 5087546.7 | G10: 696571.35 | H10: 13.691695 | I10: 135.17772 | J10: корпоративный подоходный налог
A11: жеке табыс салығы | B11: 2449704.2 | C11: 500641.49 | D11: 20.436814 | E11: 112.94908 | F11: 0 | G11: 0 | H11: 0 | I11: 0 | J11: индивидуальный подоходный налог
A12: әлеуметтік салық | B12: 1613288.1 | C12: 341000.69 | D12: 21.136999 | E12: 112.68821 | F12: 0 | G12: 0 | H12: 0 | I12: 0 | J12: социальный налог
A13: қосылған құн салығы | B13: 6510033 | C13: 1105855.5 | D13: 16.986942 | E13: 121.86388 | F13: 6510033 | G13: 1105855.5 | H13: 16.986942 | I13: 121.86388 | J13: налог на добавленную стоимость
A14: акциздер | B14: 923315.43 | C14: 138324.24 | D14: 14.981255 | E14: 108.97919 | F14: 149702.35 | G14: 18199.007 | H14: 12.156794 | I14: 86.66342 | J14: акцизы
A15: Салықтық емес түсімдер | B15: 533506.6 | C15: 265249.93 | D15: 49.718209 | E15: 298.12003 | F15: 435325.85 | G15: 182604.09 | H15: 41.94653 | I15: 380.70455 | J15: Неналоговые поступления
A16: Негізгі капиталды сатудан түсетін түсімдер | B16: 265331.23 | C16: 29312.957 | D16: 11.047685 | E16: 68.77941 | F16: 5200 | G16: 558.11164 | H16: 10.732916 | I16: 11.955534 | J16: Поступления от продажи основного капитала
A17: Трансферттердің түсімдері | B17: 5250000 | C17: 1000000 | D17: 19.047619 | E17: 100 | F17: 5758184.9 | G17: 1149921.9 | H17: 19.970215 | I17: 105.83844 | J17: Поступления трансфертов
A18: II. ШЫҒЫНДАР | B18: 32167783 | C18: 4380234.8 | D18: 13.616838 | E18: 105.64626 | F18: 25193022 | G18: 3638727.6 | H18: 14.443394 | I18: 99.40659 | J18: II. ЗАТРАТЫ
A19: 1. Жалпы сипаттағы мемлекеттiк қызметтер | B19: 1564077.7 | C19: 285493.39 | D19: 18.253147 | E19: 104.83023 | F19: 1110934 | G19: 209111.92 | H19: 18.823073 | I19: 102.74469 | J19: 1. Государственные услуги общего характера
... A32: 14. Борышқа қызмет көрсету | B32: 2554145.6 | C32: 532224.77 | D32: 20.837684 | E32: 120.85358 | F32: 2502000 | G32: 529604.87 | H32: 21.167261 | I32: 120.55036 | J32: 14. Обслуживание долга
F33: 5774300.9 | G33: 776551.01 | H33: 13.448399 | I33: 103.52425 | J33: 15. Трансферты
A34: III. ТАЗА БЮДЖЕТТІК КРЕДИТ БЕРУ | B34: 324882.8 | C34: 12537.673 | D34: 3.8591373 | E34: 30.20462 | F34: 252140.98 | G34: 9424.1552 | H34: 3.7376531 | I34: 21.28575 | J34: III. ЧИСТОЕ БЮДЖЕТНОЕ КРЕДИТОВАНИЕ
A35: Бюджеттік кредиттер | B35: 594996.13 | C35: 25137.485 | D35: 4.2248149 | E35: 49.08786 | F35: 510480 | G35: 20000 | H35: 3.9178812 | I35: 40 | J35: Бюджетные кредиты
A36: Бюджеттік кредиттерді өтеу | B36: 270113.33 | C36: 12599.811 | D36: 4.6646389 | E36: 129.89428 | F36: 258339.02 | G36: 10575.845 | H36: 4.0937853 | I36: 184.71405 | J36: Погашение бюджетных кредитов
A37: IV. ҚАРЖЫ АКТИВТЕРІМЕН ОПЕРАЦИЯЛАР БОЙЫНША САЛЬДО - ҚАРЖЫ АК | B37: 472725.23 | C37: 68054.292 | D37: 14.396162 | E37: 322.46093 | F37: 46891.3 | G37: 76.74548 | H37: 0.16366678 | I37: 0.76544 | J37: IV. САЛЬДО ПО ОПЕРАЦИЯМ С ФИНАНСОВЫМИ АКТИВАМИ
A38: Қаржылық активтерді сатып алу | B38: 472923.34 | C38: 68246.713 | D38: 14.43082 | E38: 320.68461 | F38: 46891.3 | G38: 76.74548 | H38: 0.16366678 | I38: 0.76544 | J38: Приобретение финансовых активов
A39: Мемлекеттің қаржы активтерін сатудан түсетін түсімдер | B39: 198.1 | C39: 192.42119 | D39: 97.133364 | E39: 108.77085 | J39: Поступления от продажи финансовых активов государства
A40: V. БЮДЖЕТ ТАПШЫЛЫҒЫ (ПРОФИЦИТІ) | B40: -4327902 | C40: 560485.87 | D40: -12.950521 | E40: 3606.0883 | F40: -4100000 | G40: -13635.906 | H40: 0.33258307 | I40: -1.87819 | J40: V. ДЕФИЦИТ (ПРОФИЦИТ) БЮДЖЕТА
A41: VI. БЮДЖЕТТІҢ МҰНАЙҒА ҚАТЫСТЫ ЕМЕС ТАПШЫЛЫҒЫ (ПРОФИЦИТІ) | B41: -11227602 | C41: -558145.66 | D41: 4.9711921 | E41: -51.16406 | F41: -10999700 | G41: -1132267.4 | H41: 10.293621 | I41: -61.78982 | J41: VI. НЕНЕФТЯНОЙ ДЕФИЦИТ (ПРОФИЦИТ) БЮДЖЕТА

Sheet табл 3
A1: 3-кесте | E1: Таблица 3
A2: МЕМЛЕКЕТТІК БЮДЖЕТТІҢ АТҚАРЫЛУЫ | E2: ИСПОЛНЕНИЕ ГОСУДАРСТВЕННОГО БЮДЖЕТА
A3: (млн.теңге) | E3: (млн. тенге)
A5: Атауы | B5: 2022 ж. есеп/ 2022 г. отчет | C5: 2023 ж. есеп/ 2023 г. отчет | D5: 2024 ж. есеп/ 2024 г. отчет | F5: 2025 ж. қантар-ақпан есеп/январь-феврал отчет 2025 г. | G5: Наименование
D6: жылдық/ годовой | E6: қантар-ақпан/январь-феврал
A7: 1 | B7: 2 | C7: 3 | D7: 4 | E7: 5 | F7: 6 | G7: 7
A8: I. КІРІСТЕР | B8: 20248101 | C8: 24917246 | D8: 27132165 | E8: 4224290.1 | F8: 5021312.6 | G8: I. ДОХОДЫ#
A9: Салықтық түсімдер_x000D_ оның iшiнде: | B9: 14843311 | C9: 18912204 | D9: 19700517 | E9: 3092697.1 | F9: 3726749.7 | G9: Налоговые поступления,_x000D_ в том числе:
A10: корпорациялық табыс салығы | B10: 3962495.8 | C10: 5045696.1 | D10: 5213291.4 | E10: 715306.19 | F10: 928750.33 | G10: корпоративный подоходный налог
A11: жеке табыс салығы | B11: 1499712.4 | C11: 1992384.9 | D11: 2451640 | E11: 443245.31 | F11: 500641.49 | G11: индивидуальный подоходный налог
A12: әлеуметтік салық | B12: 1035129 | C12: 1321272.8 | D12: 1579329.4 | E12: 302605.48 | F12: 341000.69 | G12: социальный налог
A13: қосылған құн салығы | B13: 4226358.8 | C13: 5674110.6 | D13: 5179378.1 | E13: 907451.41 | F13: 1105855.5 | G13: налог на добавленную стоимость
A14: акциздер | B14: 757266.87 | C14: 840215.7 | D14: 844909.98 | E14: 126927.2 | F14: 138324.24 | G14: акцизы
A15: Салықтық емес түсімдер | B15: 584848.01 | C15: 1822932.9 | D15: 1629968 | E15: 88974.203 | F15: 265249.93 | G15: Неналоговые поступления
A16: Негізгі капиталды сатудан түсетін түсімдер | B16: 239941.5 | C16: 182108.73 | D16: 201680.05 | E16: 42618.795 | F16: 29312.957 | G16: Поступления от продажи основного капитала
A17: Трансферттердің түсімдері | B17: 4580000 | C17: 4000000 | D17: 5600000 | E17: 1000000 | F17: 1000000 | G17: Поступления трансфертов
A18: II. ШЫҒЫНДАР | B18: 21532543 | C18: 26760000 | D18: 30318236 | E18: 4146133.5 | F18: 4380234.8 | G18: II. ЗАТРАТЫ#
A19: 1. Жалпы сипаттағы мемлекеттiк қызметтер | B19: 1211805.7 | C19: 1489124.1 | D19: 1766404.2 | E19: 272338.8 | F19: 285493.39 | G19: 1. Государственные услуги общего характера
... A32: 14. Борышқа қызмет көрсету | B32: 1357551.8 | C32: 1865649 | D32: 2232329.2 | E32: 440388.08 | F32: 532224.77 | G32: 14. Обслуживание долга
A33: 15. Трансферттер | B33: 140421.01 | C33: - | D33: - | E33: - | F33: - | G33: 15. Трансферты
A34: III. ТАЗА БЮДЖЕТТІК КРЕДИТ БЕРУ | B34: 592680.34 | C34: 466441.74 | D34: 198408.55 | E34: 41509.119 | F34: 12537.673 | G34: III. ЧИСТОЕ БЮДЖЕТНОЕ КРЕДИТОВАНИЕ#
A35: Бюджеттік кредиттер | B35: 742434.13 | C35: 712385.4 | D35: 519749.13 | E35: 51209.17 | F35: 25137.485 | G35: Бюджетные кредиты
A36: Бюджеттік кредиттерді өтеу | B36: 149753.78 | C36: 245943.66 | D36: 321340.58 | E36: 9700.0511 | F36: 12599.811 | G36: Погашение бюджетных кредитов
A37: IV. ҚАРЖЫ АКТИВТЕРІМЕН ОПЕРАЦИЯЛАР БОЙЫНША САЛЬДО - ҚАРЖЫ АК | B37: 292001.58 | C37: 501904.7 | D37: 201561.81 | E37: 21104.663 | F37: 68054.292 | G37: IV. САЛЬДО ПО ОПЕРАЦИЯМ С ФИНАНСОВЫМИ АКТИВАМИ#
A38: Қаржылық активтерді сатып алу | B38: 293189.28 | C38: 503365.1 | D38: 202951.32 | E38: 21281.568 | F38: 68246.713 | G38: Приобретение финансовых активов
A39: Мемлекеттің қаржы активтерін сатудан түсетін түсімдер | B39: 1187.6999 | C39: 1460.4064 | D39: 1389.5083 | E39: 176.90512 | F39: 192.42119 | G39: Поступления от продажи финансовых активов государства
A40: V. БЮДЖЕТ ТАПШЫЛЫҒЫ (ПРОФИЦИТІ) | B40: -2169124.7 | C40: -2811100.6 | D40: -3586041.9 | E40: 15542.766 | F40: 560485.87 | G40: V. ДЕФИЦИТ (ПРОФИЦИТ) БЮДЖЕТА#
A41: VI. БЮДЖЕТТІҢ МҰНАЙҒА ҚАТЫСТЫ ЕМЕС ТАПШЫЛЫҒЫ (ПРОФИЦИТІ) | B41: -8370502.3 | C41: -8454245.5 | D41: -10784416 | E41: -1090893.9 | F41: -558145.66 | G41: VI. НЕНЕФТЯНОЙ ДЕФИЦИТ (ПРОФИЦИТ) БЮДЖЕТА#
A42: VII. БЮДЖЕТТІҢ ТАПШЫЛЫҒЫН ҚАРЖЫЛАНДЫРУ (ПРОФИЦИТТІ ПАЙДАЛАНУ | B42: 2169124.7 | C42: 2811100.6 | D42: 3586041.9 | E42: -15542.766 | F42: -560485.87 | G42: VII. ФИНАНСИРОВАНИЕ ДЕФИЦИТА (ИСПОЛЬЗОВАНИЕ ПРОФИЦИТА) БЮДЖЕТА
A43: Ішкі | B43: 2312930.2 | C43: 3221830.7 | D43: 3293971.1 | E43: 67576.348 | F43: -519102.66 | G43: Внутреннее
A44: Түсімдер | B44: 3925848 | C44: 5179541.7 | D44: 5785457.6 | E44: 737219.58 | F44: 221927.57 | G44: Поступление
A45: Өтеу | B45: 1612917.7 | C45: 1957711 | D45: 2491486.6 | E45: 669643.23 | F45: 741030.23 | G45: Погашение
... A48: Өтеу | B48: 209770.89 | C48: 662602.27 | D48: 1155152.7 | E48: 94548.874 | F48: 106694.99 | G48: Погашение

Sheet табл 4
A1: 4-кесте | G1: Таблица 4
A3: МЕМЛЕКЕТТІК БЮДЖЕТКЕ ТҮСІМДЕР/_x000D_ ПОСТУПЛЕНИЯ В ГОСУДАРСТВЕННЫЙ БЮДЖЕТ
A5: (млн.теңге) | G5: (млн.тенге)
A7: Санаты/ Категория | B7: Сыныбы/ Класс | C7: Сыныпшасы/ Подкласс | D7: Ерешелігі/ Специфика | E7: Атауы | F7: 2025 ж. қаңтар-ақпан есеп/_x000D_ январь-февраль отчет 2025 г. | G7: Наименование
A8: 1 | B8: 2 | C8: 3 | D8: 4 | E8: 5 | F8: 6 | G8: 7
E9: ТҮСІМДЕР | F9: 5034104.9 | G9: ПОСТУПЛЕНИЯ
E10: оның ішінде: | G10: в том числе:
E11: КІРІСТЕР | F11: 5021312.6 | G11: ДОХОДЫ
A12: 1 | B12: L01 Класс дохода | C12: L01 Подкласс дохода | D12: L01 Специфика дохода | E12: Салықтық түсімдер | F12: 3726749.7 | G12: Налоговые поступления
A13: L01 Категория дохода | B13: 01 | C13: L01 Подкласс дохода | D13: L01 Специфика дохода | E13: Табыс салығы | F13: 1429391.8 | G13: Подоходный налог
A14: L01 Категория дохода | B14: L01 Класс дохода | C14: 1 | D14: L01 Специфика дохода | E14: Корпорациялық табыс салығы | F14: 928750.33 | G14: Корпоративный подоходный налог
A15: 1 | B15: 01 | C15: 1 | D15: 10 | E15: Мұнай секторы ұйымдарынан түсетін түсімдерді қоспағанда, ірі кәсіпкерлік субъектілерінен – заңды тұлғалардан алынатын корпоративтік табыс салығы | F15: 696571.35 | G15: Корпоративный подоходный налог с юридических лиц – субъектов крупного предпринимательства, за исключением поступлений от организаций нефтяного сектора
D16: 11 | E16: Ірі кәсіпкерлік субъектілерінен және мұнай секторы ұйымдарынан түсетін түсімдерді қоспағанда, заңды тұлғалардан алынатын корпоративтік табыс салығы | F16: 232178.98 | G16: Корпоративный подоходный налог с юридических лиц, за исключением поступлений от субъектов крупного предпринимательства и организаций нефтяного сектора
A17: L01 Категория дохода | B17: L01 Класс дохода | C17: 2 | D17: L01 Специфика дохода | E17: Жеке табыс салығы | F17: 500641.49 | G17: Индивидуальный подоходный налог
C18: 2 | D18: 01 | E18: Төлем көзінен салық салынатын табыстардан ұсталатын жеке табыс салығы | F18: 344188.03 | G18: Индивидуальный подоходный налог с доходов, облагаемых у источника выплаты
D19: 02 | E19: Төлем көзінен салық салынбайтын табыстардан ұсталатын жеке табыс салығы | F19: 154249.29 | G19: Индивидуальный подоходный налог с доходов, не облагаемых у источника выплаты
D20: 05 | E20: Төлем көзінен салық салынбайтын шетелдік азаматтар табыстарынан ұсталатын жеке табыс салығы | F20: 2204.1678 | G20: Индивидуальный подоходный налог с доходов иностранных граждан, не облагаемых у источника выплаты
A21: L01 Категория дохода | B21: 03 | C21: L01 Подкласс дохода | D21: L01 Специфика дохода | E21: Әлеуметтiк салық | F21: 341000.69 | G21: Социальный налог
A22: L01 Категория дохода | B22: L01 Класс дохода | C22: 1 | D22: L01 Специфика дохода | E22: Әлеуметтік салық | F22: 341000.69 | G22: Социальный налог
B23: 03 | C23: 1 | D23: 01 | E23: Әлеуметтік салық | F23: 341000.69 | G23: Социальный налог
A24: L01 Категория дохода | B24: 04 | C24: L01 Подкласс дохода | D24: L01 Специфика дохода | E24: Меншiкке салынатын салықтар | F24: 160435.5 | G24: Hалоги на собственность
A25: L01 Категория дохода | B25: L01 Класс дохода | C25: 1 | D25: L01 Специфика дохода | E25: Мүлiкке салынатын салықтар | F25: 152083.55 | G25: Hалоги на имущество
B26: 04 | C26: 1 | D26: 01 | E26: Заңды тұлғалардың және жеке кәсіпкерлердің мүлкіне салынатын салық | F26: 151464.05 | G26: Налог на имущество юридических лиц и индивидуальных предпринимателей
D27: 02 | E27: Жеке тұлғалардың мүлкiне салынатын салық | F27: 619.49564 | G27: Hалог на имущество физических лиц
A28: L01 Категория дохода | B28: L01 Класс дохода | C28: 3 | D28: L01 Специфика дохода | E28: Жер салығы | F28: 3867.9594 | G28: Земельный налог
C29: 3 | D29: 02 | E29: Жер салығы | F29: 3867.9594 | G29: Земельный налог
A30: L01 Категория дохода | B30: L01 Класс дохода | C30: 4 | D30: L01 Специфика дохода | E30: Көлiк құралдарына салынатын салық | F30: 3713.7595 | G30: Hалог на транспортные средства
C31: 4 | D31: 01 | E31: Заңды тұлғалардан көлiк құралдарына салынатын салық | F31: 385.22226 | G31: Hалог на транспортные средства с юридических лиц
D32: 02 | E32: Жеке тұлғалардан көлiк құралдарына салынатын салық | F32: 3328.5372 | G32: Hалог на транспортные средства с физических лиц
A33: L01 Категория дохода | B33: L01 Класс дохода | C33: 5 | D33: L01 Специфика дохода | E33: Бірыңғай жер салығы | F33: 770.23487 | G33: Единый земельный налог
C34: 5 | D34: 01 | E34: Бірыңғай жер салығы | F34: 770.23487 | G34: Единый земельный налог
A35: L01 Категория дохода | B35: 05 | C35: L01 Подкласс дохода | D35: L01 Специфика дохода | E35: Тауарларға, жұмыстарға және қызметтерге салынатын iшкi салықтар | F35: 1550880.5 | G35: Внутренние налоги на товары, работы и услуги
A36: L01 Категория дохода | B36: L01 Класс дохода | C36: 1 | D36: L01 Специфика дохода | E36: Қосылған құн салығы | F36: 1105855.5 | G36: Налог на добавленную стоимость
B37: 05 | C37: 1 | D37: 01 | E37: Қазақстан Республикасының аумағында өндiрiлген тауарларға, орындалған жұмыстарға және көрсетілген қызметтерге салынатын қосылған құн салығы | F37: 588316.43 | G37: Hалог на добавленную стоимость на произведенные товары, выполненные работы и оказанные услуги на территории Республики Казахстан
D38: 02 | E38: Ресей Федерациясы және Беларусь Республикасының аумағынан импортталатын тауарларға салынатын қосылған құн салығынан басқа, Қазақстан Республикасының аумағына импортталатын тауарларға салынатын қосылған құн салығы | F38: 269675.7 | G38: Hалог на добавленную стоимость на товары, импортируемые на территорию Республики Казахстан, кроме налога на добавленнуюстоимость на товары, импортируемые с территории Российской Федерации и Республики Беларусь
D39: 04 | E39: Резидент емес үшін қосылған құн салығы | F39: 52040.043 | G39: Налог на добавленную стоимость за нерезидента
D40: 14 | E40: Салық төлеушінің бұрын бюджеттен қайтарылған және салықтық тексеру жүргізу барысында қайтарылуы расталмаған қосылған құн салығының асып кеткен сомасын аударуы (қайтаруы), өсімпұл сомасын аударуы | F40: 533.09975 | G40: Перечисление (возврат) налогоплательщиком суммы превышения налога на добавленную стоимость, ранее возвращенной из бюджета и не подтвержденной к возврату при проведении налоговой проверки, перечисление суммы пени
D41: 15 | E41: ЕАЭО мүше мемлекеттер аумағынан импортталған тауарларға қосылған құн салығы | F41: 181953.04 | G41: Налог на добавленную стоимость на товары, импортированные с территории государств-членов ЕАЭС
D42: 16 | E42: Тауарлармен электрондық сауданы жүзеге асыру, жеке тұлғаларға электрондық нысанда қызметтер көрсету кезінде шетелдік компаниялардан түсетін қосылған құн салығы | F42: 13337.202 | G42: Налог на добавленную стоимость с иностранных интернет компаний при осуществлении электронной торговли товарами, оказании услуг в электронной форме физическим лицам
A43: L01 Категория дохода | B43: L01 Класс дохода | C43: 2 | D43: L01 Специфика дохода | E43: Акциздер | F43: 138324.24 | G43: Акцизы
...

Sheet табл 5
B2: Кесте 5 | D2: Таблица 5
B3: ШЫҒЫСТАРДЫҢ ВЕДОМСТВОЛЫҚ | D3: ИСПОЛНЕНИЕ ГОСУДАРСТВЕННОГО БЮДЖЕТА
B4: СЫНЫПТАМАСЫ БОЙЫНША | D4: ПО ВЕДОМСТВЕННОЙ
B5: МЕМЛЕКЕТТІК БЮДЖЕТТІҢ АТҚАРАЛУЫ | D5: КЛАССИФИКАЦИИ РАСХОДОВ
B6: (млн. теңге) | D6: (млн. тенге)
B8: Бағдарламалард_x000D_ ың_x000D_ əкімшісі/_x000D_ Администратор_x000D_ программ | C8: Атауы | D8: 2025 ж. қаңтар-ақпан есеп/_x000D_ январь-февраль 2025 г. | E8: Наименование
B9: 1 | C9: 2 | D9: 3 | E9: 4
C10: БАРЛЫҒЫ | D10: 4473619 | E10: ВСЕГО
B11: 101 | C11: Қазақстан Республикасы Президентінің Әкімшілігі | D11: 2447.5945 | E11: Администрация Президента Республики Казахстан
B12: 106 | C12: Адам құқықтары жөніндегі ұлттық орталық | D12: 292.40694 | E12: Национальный центр по правам человека
B13: 107 | C13: Қазақстан Республикасы Жоғары Сот Кеңесінің Аппараты | D13: 298.27046 | E13: Аппарат Высшего Судебного Совета Республики Казахстан
B14: 109 | C14: Қазақстан Республикасы үкіметінің Аппараты_x000D_ | D14: 1113.2111 | E14: Аппарат Правительства Республики Казахстан
B15: 110 | C15: Облыс мәслихатының аппараты | D15: 450.50985 | E15: Аппарат маслихата области
B16: 111 | C16: Республикалық маңызы бар қала, астана мәслихатының аппараты | D16: 90.997243 | E16: Аппарат маслихата города республиканского значения, столицы
B17: 112 | C17: Аудан (облыстық маңызы бар қала) мәслихатының аппараты | D17: 2351.5673 | E17: Аппарат маслихата района (города областного значения)
B18: 120 | C18: Облыс әкімінің аппараты | D18: 6390.5994 | E18: Аппарат акима области
B19: 121 | C19: Республикалық маңызы бар қала, астана әкімінің аппараты | D19: 1278.3601 | E19: Аппарат акима города республиканского значения, столицы
B20: 122 | C20: Аудан (облыстық маңызы бар қала) әкімінің аппараты | D20: 14810.773 | E20: Аппарат акима района (города областного значения)
B21: 123 | C21: Қаладағы аудан, аудандық маңызы бар қала, кент, ауыл, ауылдық округ әкімінің аппараты | D21: 49040.969 | E21: Аппарат акима района в городе, города районного значения, поселка, села, сельского округа
B22: 124 | C22: Аудандық маңызы бар қала, ауыл, кент, ауылдық округ әкімінің аппараты | D22: 35672.104 | E22: Аппарат акима города районного значения, села, поселка, сельского округа
... B222: 821 | C222: Ауданның (облыстық маңызы бар қаланың) қоғамдық даму бөлімі | D222: 153.83387 | E222: Отдел общественного развития района (города областного значения)

Sheet табл 6
A1: 6-кесте | D1: Таблица 6
A2: ШЫҒЫНДАРДЫҢ ЭКОНОМИКАЛЫҚ ЖІКТЕМЕСІ | D2: ИСПОЛНЕНИЕ ГОСУДАРСТВЕННОГО БЮДЖЕТА ПО
A3: БОЙЫНША МЕМЛЕКЕТТІК БЮДЖЕТТІК ОРЫНДАЛУЫ | D3: ЭКОНОМИЧЕСКОЙ КЛАССИФИКАЦИИ РАСХОДОВ
A4: (млн.теңге) | D4: (млн.тенге)
A5: Cанаты/_x000D_ Категория | B5: Iшкi сыныбы/_x000D_ Подкласс | C5: Атауы | D5: 2025 ж. қаңтар-ақпан/январь-февраль отчет 2025 г. | E5: Наименование
A7: 1 | B7: 2 | C7: 3 | D7: 4 | E7: 5
C8: БАРЛЫҒЫ | D8: 4473619 | E8: ВСЕГО
A9: 1 | C9: Ағымдағы шығындар | D9: 4092577.8 | E9: Текущие затраты
A10: 1 | B10: 110 | C10: Жалақы | D10: 691990.29 | E10: Заработная плата
B11: 120 | C11: Жұмыс берушілердің жарналары | D11: 68687.421 | E11: Взносы работодателей
B12: 130 | C12: Қазақстан Республикасының заңнамалық актілеріне сәйкес азаматтардың жекелеген санаттарына жалақы төлеу және жарналар аудару | D12: 25289.276 | E12: Выплата заработной платы отдельным категориям граждан и отчисления взносов в соответствии с законодательными актами Республики Казахстан
B13: 140 | C13: Қорлар сатып алу | D13: 44785.107 | E13: Приобретение запасов
B14: 150 | C14: Қызметтер мен жұмыстарды сатып алу | D14: 621259.64 | E14: Приобретение услуг и работ
B15: 160 | C15: Басқа да ағымдағы шығындар | D15: 361199.94 | E15: Другие текущие затраты
B16: 210 | C16: Ішкі қарыздар бойынша сыйақы төлемдері | D16: 455632.53 | E16: Выплаты вознаграждений по внутренним займам
B17: 220 | C17: Сыртқы заемдар бойынша сыйақылар төлеу | D17: 76592.236 | E17: Выплаты вознаграждений по внешним займам
B18: 310 | C18: Бюджеттік субсидиялар | D18: 292235.77 | E18: Бюджетные субсидии
B19: 320 | C19: Жеке тұлғаларға берілетін трансферттер | D19: 1115853 | E19: Трансферты физическим лицам
B20: 340 | C20: Шетелге берiлетiн ағымдағы трансферттер | D20: 52.531823 | E20: Текущие трансферты за границу
B21: 360 | C21: Нысаналы жарна | D21: 339000 | E21: Целевой взнос
A22: 2 | C22: Күрделі шығындар | D22: 253696.28 | E22: Капитальные затраты
A23: 2 | B23: 410 | C23: Негiзгi құралдарды, материалдық емес және биологиялық активтерді сатып алу | D23: 41324.858 | E23: Приобретение основных средств, нематериальных и биологических активов
B24: 420 | C24: Негізгі қаражатты күрделі жөндеу | D24: 25849.442 | E24: Капитальный ремонт основных средств
B25: 430 | C25: Дамуға бағытталған күрделі шығындар | D25: 186521.98 | E25: Капитальные затраты, направленные на развитие
A26: 3 | C26: Бюджеттік кредиттер | D26: 25137.485 | E26: Бюджетные кредиты
A27: 3 | B27: 510 | C27: Ішкі бюджеттік кредиттер | D27: 25137.485 | E27: Внутренние бюджетные кредиты
A28: 4 | C28: Қаржы активтерін сатып алу | D28: 68606.713 | E28: Приобретение финансовых активов
A29: 4 | B29: 610 | C29: Қаржы активтерін сатып алу | D29: 68529.968 | E29: Приобретение финансовых активов
B30: 620 | C30: Елден тысқары жерлерден қаржы активтерін сатып алу | D30: 76.74548 | E30: Приобретение финансовых активов за пределами страны
A31: 6 | C31: Мемлекеттік-жекешелік әріптестік жобалар бойынша мемлекеттік міндеттемелерді орындау | D31: 33600.763 | E31: Выполнение государственных обязательств по проектам государственно-частного партнерства
A32: 6 | B32: 810 | C32: Мемлекеттік концессиялық міндеттемелерді орындау | D32: 33600.763 | E32: Выполнение государственных концессионных обязательств

Sheet табл 7
A1: 7-кесте | E1: Таблица 7
A2: РЕСПУБЛИКАЛЫҚ БЮДЖЕТТІҢ АТҚАРЫЛУЫ | E2: ИСПОЛНЕНИЕ РЕСПУБЛИКАНСКОГО БЮДЖЕТА
A3: (млн.теңге) | E3: (млн. тенге)
A5: Атауы | B5: 2022 ж. есеп/ 2022 г. отчет | C5: 2023 ж. есеп/ 2023 г. отчет | D5: 2024 ж. есеп/ 2024 г. отчет | F5: 2025 ж. қантар-ақпан есеп/январь-феврал отчет 2025 г. | G5: Наименование
D6: жылдық/ годовой | E6: қантар-ақпан/январь-феврал
A7: 1 | B7: 2 | C7: 3 | D7: 4 | E7: 5 | F7: 6 | G7: 7
A8: I. КІРІСТЕР | B8: 15963398 | C8: 19037979 | D8: 19624012 | E8: 2988736.9 | F8: 3634592.6 | G8: I. ДОХОДЫ#
A9: Салықтық түсімдер_x000D_ оның iшiнде: | B9: 10026825 | C9: 12912428 | D9: 12307810 | E9: 1849616 | F9: 2301508.5 | G9: Налоговые поступления,_x000D_ в том числе:
A10: корпорациялық табыс салығы | B10: 2920802.8 | C10: 3889594.5 | D10: 3653190.8 | E10: 515300.42 | F10: 696571.35 | G10: корпоративный подоходный налог
A11: қосылған құн салығы | B11: 4226358.8 | C11: 5674110.6 | D11: 5179378.1 | E11: 907451.41 | F11: 1105855.5 | G11: налог на добавленную стоимость
A12: акциздер | B12: 153619.22 | C12: 161890.43 | D12: 125189.66 | E12: 20999.642 | F12: 18199.007 | G12: акцизы
A13: Салықтық емес түсімдер | B13: 438204.42 | C13: 1617610.1 | D13: 1201438.2 | E13: 47964.777 | F13: 182604.09 | G13: Неналоговые поступления
A14: Негізгі капиталды сатудан түсетін түсімдер | B14: 6954.9546 | C14: 735.69631 | D14: 6170.4309 | E14: 4668.2284 | F14: 558.11164 | G14: Поступления от продажи основного капитала
A15: Трансферттердің түсімдері | B15: 5491414.1 | C15: 4507205 | D15: 6108593.6 | E15: 1086487.9 | F15: 1149921.9 | G15: Поступления трансфертов
A16: II. ШЫҒЫНДАР | B16: 17791797 | C16: 21547819 | D16: 23106552 | E16: 3660449.2 | F16: 3638727.6 | G16: II. ЗАТРАТЫ#
A17: 1. Жалпы сипаттағы мемлекеттiк қызметтер | B17: 1047844 | C17: 1137687.2 | D17: 1293447.3 | E17: 203525.77 | F17: 209111.92 | G17: 1. Государственные услуги общего характера
A18: 2. Қорғаныс | B18: 1073075.9 | C18: 1100070.9 | D18: 1038491.2 | E18: 127423.11 | F18: 80846.186 | G18: 2. Оборона
A19: 3. Қоғамдық тәртіп, қауіпсіздік, құқықтық, сот, қылмыстық-атқару қызметі | B19: 1074316.3 | C19: 1275903.8 | D19: 1287986.9 | E19: 149503.98 | F19: 158301.8 | G19: 3. Общественный порядок, безопасность, правовая, судебная, уголовно-исполнительная деятельность
... A45: Өтеу | B45: 208253.95 | C45: 660721.39 | D45: 1154283.9 | E45: 93680.118 | F45: 106694.99 | G45: Погашение

Sheet табл 8 (дох)
B2: 8-кесте | H2: Таблица 8
F3: РЕСПУБЛИКАЛЫҚ БЮДЖЕТТІҢ АТҚАРЫЛУЫ/ ИСПОЛНЕНИЕ РЕСПУБЛИКАНСКОГО БЮДЖЕТА
B4: (млн.теңге) | H4: (млн.тенге)
B5: Санаты/ Категория | C5: Сыныбы/ Класс | D5: Сыныпшасы/ Подкласс | E5: Ерешелігі/ Специфика | F5: Атауы | G5: 2025 ж. қаңтар-ақпан есеп/_x000D_ январь-февраль отчет 2025 г. | H5: Наименование
B6: 1 | C6: 2 | D6: 3 | E6: 4 | F6: 5 | G6: 6 | H6: 7
F7: ТҮСІМДЕР | G7: 3645168.4 | H7: ПОСТУПЛЕНИЯ
F8: оның ішінде: | H8: в том числе:
F9: КІРІСТЕР | G9: 3634592.6 | H9: ДОХОДЫ
B10: 1 | F10: Салықтық түсімдер | G10: 2301508.5 | H10: Налоговые поступления
C11: 01 | F11: Табыс салығы | G11: 696571.35 | H11: Подоходный налог
D12: 1 | F12: Корпорациялық табыс салығы | G12: 696571.35 | H12: Корпоративный подоходный налог
B13: 1 | C13: 01 | D13: 1 | E13: 10 | F13: Мұнай секторы ұйымдарынан түсетін түсімдерді қоспағанда, ірі кәсіпкерлік субъектілерінен – заңды тұлғалардан алынатын корпоративтік табыс салығы | G13: 696571.35 | H13: Корпоративный подоходный налог с юридических лиц – субъектов крупного предпринимательства, за исключением поступлений от организаций нефтяного сектора
C14: 05 | F14: Тауарларға, жұмыстарға және қызметтерге салынатын iшкi салықтар | G14: 1379961.5 | H14: Внутренние налоги на товары, работы и услуги
D15: 1 | F15: Қосылған құн салығы | G15: 1105855.5 | H15: Налог на добавленную стоимость
C16: 05 | D16: 1 | E16: 01 | F16: Қазақстан Республикасының аумағында өндiрiлген тауарларға, орындалған жұмыстарға және көрсетілген қызметтерге салынатын қосылған құн салығы | G16: 588316.43 | H16: Hалог на добавленную стоимость на произведенные товары, выполненные работы и оказанные услуги на территории Республики Казахстан
E17: 02 | F17: Ресей Федерациясы және Беларусь Республикасының аумағынан импортталатын тауарларға салынатын қосылған құн салығынан басқа, Қазақстан Республикасының аумағына импортталатын тауарларға салынатын қосылған құн салығы | G17: 269675.7 | H17: Hалог на добавленную стоимость на товары, импортируемые на территорию Республики Казахстан, кроме налога на добавленнуюстоимость на товары, импортируемые с территории Российской Федерации и Республики Беларусь
E18: 04 | F18: Резидент емес үшін қосылған құн салығы | G18: 52040.043 | H18: Налог на добавленную стоимость за нерезидента
E19: 14 | F19: Салық төлеушінің бұрын бюджеттен қайтарылған және салықтық тексеру жүргізу барысында қайтарылуы расталмаған қосылған құн салығының асып кеткен сомасын аударуы (қайтаруы), өсімпұл сомасын аударуы | G19: 533.09975 | H19: Перечисление (возврат) налогоплательщиком суммы превышения налога на добавленную стоимость, ранее возвращенной из бюджета и не подтвержденной к возврату при проведении налоговой проверки, перечисление суммы пени
E20: 15 | F20: ЕАЭО мүше мемлекеттер аумағынан импортталған тауарларға қосылған құн салығы | G20: 181953.04 | H20: Налог на добавленную стоимость на товары, импортированные с территории государств-членов ЕАЭС
E21: 16 | F21: Тауарлармен электрондық сауданы жүзеге асыру, жеке тұлғаларға электрондық нысанда қызметтер көрсету кезінде шетелдік компаниялардан түсетін қосылған құн салығы | G21: 13337.202 | H21: Налог на добавленную стоимость с иностранных интернет компаний при осуществлении электронной торговли товарами, оказании услуг в электронной форме физическим лицам
D22: 2 | F22: Акциздер | G22: 18199.007 | H22: Акцизы
D23: 2 | E23: 76 | F23: Қазақстан Республикасының аумағына Кеден одағына мүше мемлекеттердің аумағынан әкелінетін темекі өнімдері | G23: 4106.5058 | H23: Табачные изделия, ввозимые на территорию Республики Казахстан с территории государств-членов Таможенного союза
E24: 77 | F24: Қазақстан Республикасының аумағына Кеден одағына мүше мемлекеттердің аумағынан әкелінетін спирттiң және (немесе) шарап материалының, алкоголь өнімдерінің барлық түрлерi | G24: 2782.2992 | H24: Все виды спирта и (или) виноматериала, алкогольной продукции, ввозимых на территорию Республики Казахстан с территории государств-членов Таможенного союза
E25: 78 | F25: Қазақстан Республикасының аумағына Кеден одағына мүше мемлекеттердің аумағынан әкелінетін акцизделетін өнімнің өзге түрлері | G25: 4.3997715 | H25: Прочие виды подакцизных продукций, ввозимых на территорию Республики Казахстан с территории государств-членов Таможенного союза
E26: 79 | F26: Қазақстан Республикасы аумағына Кеден одағына мүше мемлекеттердің аумағынан әкелінетін бензин (авиациялықты қоспағанда) және дизель отыны | G26: 1008.8749 | H26: Бензин (за исключением авиационного) и дизельное топливо, ввозимых на территорию Республики Казахстан с территории государств-членов Таможенного союза
E27: 80 | F27: Кеден одағына мүше болып табылмайтын мемлекеттердің аумағынан әкелінетін, Қазақстан Республикасының аумағына импортталатын спирттің және (немесе) шарап материалының, алкоголь өнімдерінің барлық түрлері | G27: 2379.0343 | H27: Все виды спирта и (или) виноматериала, алкогольной продукции, импортируемых на территорию Республики Казахстан с территории государств, не являющихся членами Таможенного союза
E28: 81 | F28: Кеден одағына мүше болып табылмайтын мемлекеттердің аумағынан әкелінетін, Қазақстан Республикасының аумағына импортталатын темекі өнімдері | G28: 7298.2036 | H28: Табачные изделия, импортируемые на территорию Республики Казахстан с территории государств, не являющихся членами Таможенного союза
E29: 82 | F29: Кеден одағына мүше болып табылмайтын мемлекеттердің аумағынан әкелінетін, Қазақстан Республикасының аумағына импортталатын акцизделетін өнімдердің өзге түрлері | G29: 604.0667 | H29: Прочие виды подакцизных продукций, импортируемые на территорию Республики Казахстан с территории государств, не являющихся членами Таможенного союза
E30: 83 | F30: Кеден одағына мүше болып табылмайтын мемлекеттер аумағынан әкелінетін, Қазақстан Республикасының аумағына импортталатын бензин (авиациялықты қоспағанда) және дизель отыны | G30: 15.622548 | H30: Бензин (за исключением авиационного) и дизельное топливо, импортируемых на территорию Республики Казахстан с территории государств, не являющихся членами Таможенного союза
D31: 3 | F31: Табиғи және басқа да ресурстарды пайдаланғаны үшiн түсетiн түсiмдер | G31: 249280.03 | H31: Поступления за использование природных и других ресурсов
D32: 3 | E32: 01 | F32: Қалааралық және (немесе) халықаралық телефон байланысын көрсеткені үшін төлем,тағыда ұялы байланыс | G32: 2.3104093 | H32: Плата за предоставление междугородной и (или) международнойтелефонной связи, а также сотовой связи
E33: 05 | F33: Бонустар, мұнай секторы ұйымдарынан түсетін түсімдерден басқа | G33: 10154.905 | H33: Бонусы, за исключением поступлений от организаций нефтяногосектора
E34: 06 | F34: Пайдалы қазбаларды өндіруге салынатын салық, мұнай секторы ұйымдарынан түсетін түсімдерден басқа | G34: 237002.82 | H34: Налог на добычу полезных ископаемых, за исключением поступлений от организаций нефтяного сектора
E35: 07 | F35: Мұнай секторы ұйымдарынан түсетін түсімдерді қоспағанда, экспортқа салынатын рента салығы | G35: 827.62482 | H35: Рентный налог на экспорт, за исключением поступлений от организаций нефтяного сектора
E36: 09 | F36: Радиожиілік спектрін пайдаланғаны үшін төлем | G36: 224.07792 | H36: Плата за использование радиочастотного спектра
E37: 13 | F37: Республикалық маңызы бар ерекше қорғалатын табиғи аумақтарды пайдаланғаны үшін төлем | G37: -4.2021501 | H37: Плата за использование особо охраняемых природных территорий республиканского значения
E38: 17 | F38: Цифрлық майнинг үшін төлемақы | G38: 1072.4956 | H38: Плата за цифровой майнинг
D39: 4 | F39: Кәсiпкерлiк және кәсiби қызметтi жүргiзгенi үшiн алынатын алымдар | G39: 2586.494 | H39: Сборы за ведение предпринимательской и профессиональной деятельности
D40: 4 | E40: 06 | F40: Автокөлік құралдарының Қазақстан Республикасының аумағы арқылы өткені үшін алынатын алым | G40: 2561.7629 | H40: Сбор за проезд автотранспортных средств по территории Республики Казахстан
E41: 13 | F41: Телевизиялық және радио хабарын тарататын ұйымдарға радиожиілік өрісін пайдалануға рұқсат бергені үшін алынатын алым | G41: 0 | H41: Сбор за выдачу разрешения на использование радиочастотного спектра телевизионным и радиовещательным организациям
...

Sheet табл 8 (расх)
A3: (млн.теңге) | G3: (млн. тенге)
A6: Санаты/ Категория | B6: Сыныбы/ Класс | C6: Сыныпшасы/ Подкласс | D6: Ерешелігі/ Специфика | E6: Атауы | F6: 2025 қаңтар-ақпан есеп/_x000D_ январь-февраль отчет 2025г. | G6: Наименование
A7: 1 | B7: 2 | C7: 3 | D7: 4 | E7: 5 | F7: 6 | G7: 7
E8: ШЫҒЫСТАР | F8: 3658804.3 | G8: РАСХОДЫ
E9: оның ішінде: | G9: в том числе:
E10: II. ШЫҒЫНДАР | F10: 3638727.6 | G10: II. ЗАТРАТЫ
A11: 01 | E11: Жалпы сипаттағы мемлекеттiк қызметтер | F11: 209111.92 | G11: Государственные услуги общего характера
B12: 1 | E12: Мемлекеттiк басқарудың жалпы функцияларын орындайтын өкiлдi, атқарушы және басқа органдар | F12: 36932.294 | G12: Представительные, исполнительные и другие органы, выполняющие общие функции государственного управления
C13: 101 | E13: Қазақстан Республикасы Президентінің Әкімшілігі | F13: 2447.5945 | G13: Администрация Президента Республики Казахстан
A14: 01 | B14: 1 | C14: 101 | D14: 001 | E14: Мемлекет басшысының қызметін қамтамасыз ету | F14: 2447.5945 | G14: Обеспечение деятельности Главы государства
C15: 106 | E15: Адам құқықтары жөніндегі ұлттық орталық | F15: 292.40694 | G15: Национальный центр по правам человека
C16: 106 | D16: 001 | E16: Адамның және азаматтың құқықтары мен бостандықтарының сақталуын қадағалау жөніндегі қызметтер | F16: 232.22694 | G16: Услуги по наблюдению за соблюдением прав и свобод человека и гражданина
D17: 005 | E17: Қазақстандағы ұлттық құқық қорғау тетіктерінің тиімділігін күшейту | F17: 60.18 | G17: Усиление эффективности национальных правозащитных механизмов в Казахстане
C18: 107 | E18: Қазақстан Республикасы Жоғары Сот Кеңесінің Аппараты | F18: 189.53042 | G18: Аппарат Высшего Судебного Совета Республики Казахстан
C19: 107 | D19: 001 | E19: Қазақстан Республикасы Жоғары Сот Кеңесінің қызметін қамтамасыз ету жөнінде көрсетілетін қызметтер | F19: 189.53042 | G19: Услуги по обеспечению деятельности Высшего Судебного СоветаРеспублики Казахстан
C20: 109 | E20: Қазақстан Республикасы үкіметінің Аппараты_x000D_ | F20: 821.05498 | G20: Аппарат Правительства Республики Казахстан
C21: 109 | D21: 001 | E21: Қазақстан Республикасы Премьер-Министрінің қызметін қамтамасыз ету жөніндегі көрсетілетін қызметтер | F21: 821.05498 | G21: Услуги по обеспечению деятельности Премьер-Министра Республики Казахстан
C22: 626 | E22: Қазақстан Республикасының Стратегиялық жоспарлау және реформалар агенттігі | F22: 3834.6082 | G22: Агентство по стратегическому планированию и реформам Республики Казахстан
C23: 626 | D23: 001 | E23: Реформаларды қалыптастыруға және тиімді іске асыруға жәрдемдесу жөніндегі көрсетілетін қызметтер, стратегиялық жоспарлау, мемлекеттік статистикалық қызмет салаларында мемлекеттік саясатты жүзеге асыру, мемлекеттік басқару жүйесі мен квазиме | F23: 3834.6082 | G23: Услуги по содействию в формировании и эффективной реализации реформ, осуществление государственной политики в сферах стратегического планирования, государственной статистической деятельности, участие в совершенствовании системы государствен
C24: 637 | E24: Қазақстан Республикасы Конституциялық Сотының Аппараты | F24: 292.20671 | G24: Аппарат Конституционного Суда Республики Казахстан
C25: 637 | D25: 001 | E25: Республика аумағында Қазақстан Республикасы Конституциясының үстемдігін қамтамасыз ету | F25: 292.20671 | G25: Обеспечение верховенства Конституции Республики Казахстан на территории Республики
C26: 690 | E26: Қазақстан Республикасының Орталық сайлау комиссиясы | F26: 714.10583 | G26: Центральная избирательная комиссия Республики Казахстан
C27: 690 | D27: 001 | E27: Сайлау өткізуді ұйымдастыру | F27: 148.90815 | G27: Организация проведения выборов
D28: 002 | E28: Сайлау өткізу | F28: 565.19768 | G28: Проведение выборов
D29: 004 | E29: Облыстық бюджеттерге аудандардың (облыстық маңызы бар қалалардың) әкімдерін сайлауды қамтамасыз етуге және өткізуге берілетін ағымдағы нысаналы трансферттер | F29: 0 | G29: Целевые текущие трансферты областным бюджетам на обеспечение и проведение выборов акимов районов (городов областного значения)
C30: 693 | E30: Материалдық-техникалық қамтамасыз ету басқармасы | F30: 3155.5009 | G30: Управление материально-технического обеспечения
C31: 693 | D31: 001 | E31: Қазақстан Республикасы Парламентінің қызметін қамтамасыз ету жөніндегі көрсетілетін қызметтер | F31: 3155.5009 | G31: Услуги по обеспечению деятельности Парламента Республики Казахстан
C32: 694 | E32: Қазақстан Республикасы Президентiнiң Іс басқармасы | F32: 25185.286 | G32: Управление Делами Президента Республики Казахстан
C33: 694 | D33: 001 | E33: Қазақстан Республикасы Президенті Іс Басқармасының мемлекеттік функциялары мен өкілеттіктерін жүзеге асыруды қамтамасыз ету жөніндегі қызметтер | F33: 11906.841 | G33: Услуги по обеспечению осуществления государственных функцийи полномочий Управления делами Президента Республики Казахстан
D34: 009 | E34: Қазақстан Республикасы Президенттік орталығының қызметін қамтамасыз ету жөніндегі көрсетілетін қызметтер | F34: 179.60433 | G34: Услуги по обеспечению деятельности Президентского центра Республики Казахстан
D35: 139 | E35: Қазақстан Республикасы Үкіметінің шұғыл шығындарға арналғанрезервінің есебінен дамуға бағытталған іс-шаралар өткізу | F35: 13098.84 | G35: Проведение мероприятий, направленных на развитие за счет резерва Правительства Республики Казахстан на неотложные затраты
B36: 2 | E36: Қаржылық қызмет | F36: 2666.3859 | G36: Финансовая деятельность
C37: 217 | E37: Қазақстан Республикасының Қаржы министрлiгi | F37: 1965.4307 | G37: Министерство финансов Республики Казахстан
B38: 2 | C38: 217 | D38: 002 | E38: Халықаралық қаржы ұйымдары қаржыландыратын инвестициялық жобалардың аудитiн жүзеге асыру | F38: 0 | G38: Осуществление аудита инвестиционных проектов, финансируемыхмеждународными финансовыми организациями
D39: 094 | E39: Мемлекеттік активтерді басқару | F39: 7.054391 | G39: Управление государственными активами
D40: 205 | E40: Шекарадағы өткізу пункттерін жаңғырту және техникалық толықжарақтандыру | F40: 1958.3763 | G40: Модернизация и техническое дооснащение пунктов пропуска на границе
C41: 406 | E41: Қазақстан Республикасының Жоғары аудиторлық палатасы | F41: 700.95524 | G41: Высшая аудиторская палата Республики Казахстан
C42: 406 | D42: 001 | E42: Қазақстан Республикасы Жоғары аудиторлық палатасының қызметін қамтамасыз ету жөніндегі көрсетілетін қызметтер | F42: 700.95524 | G42: Услуги по обеспечению деятельности Высшей аудиторской палаты Республики Казахстан
D43: 101 | E43: Өкілдiк шығындарға арналған қаражат есебiнен іс-шаралар өткізу | F43: 0 | G43: Проведение мероприятий за счет средств на представительскиезатраты
B44: 3 | E44: Сыртқы саяси қызмет | F44: 18487.54 | G44: Внешнеполитическая деятельность
...

Sheet табл 9
B2: Кесте 9 | D2: Таблица 9
B3: ШЫҒЫСТАРДЫҢ ВЕДОМСТВОЛЫҚ | D3: ИСПОЛНЕНИЕ РЕСПУБЛИКАНСКОГО БЮДЖЕТА
B4: СЫНЫПТАМАСЫ БОЙЫНША | D4: ПО ВЕДОМСТВЕННОЙ
B5: РЕСПУБЛИКАЛЫҚ БЮДЖЕТТІҢ АТҚАРАЛУЫ | D5: КЛАССИФИКАЦИИ РАСХОДОВ
B6: (млн. теңге) | D6: (млн. тенге)
B8: Бағдарламалард_x000D_ ың_x000D_ əкімшісі/_x000D_ Администратор_x000D_ программ | C8: Атауы | D8: 2025 ж. қаңтар-ақпан есеп/_x000D_ январь-февраль 2025 г. | E8: Наименование
B9: 1 | C9: 2 | D9: 3 | E9: 4
C10: БАРЛЫҒЫ | D10: 3658804.3 | E10: ВСЕГО
B11: 101 | C11: Қазақстан Республикасы Президентінің Әкімшілігі | D11: 2447.5945 | E11: Администрация Президента Республики Казахстан
B12: 106 | C12: Адам құқықтары жөніндегі ұлттық орталық | D12: 292.40694 | E12: Национальный центр по правам человека
B13: 107 | C13: Қазақстан Республикасы Жоғары Сот Кеңесінің Аппараты | D13: 298.27046 | E13: Аппарат Высшего Судебного Совета Республики Казахстан
B14: 109 | C14: Қазақстан Республикасы үкіметінің Аппараты_x000D_ | D14: 1113.2111 | E14: Аппарат Правительства Республики Казахстан
B15: 201 | C15: Қазақстан Республикасының Iшкi iстер министрлiгi | D15: 78191.833 | E15: Министерство внутренних дел Республики Казахстан
B16: 202 | C16: Қазақстан Республикасының Төтенше жағдайлар министрлiгi | D16: 14381.322 | E16: Министерство по чрезвычайным ситуациям Республики Казахстан
B17: 204 | C17: Қазақстан Республикасының Сыртқы iстер министрлiгi | D17: 18660.04 | E17: Министерство иностранных дел Республики Казахстан
B18: 207 | C18: Қазақстан Республикасының Экология және табиғи ресурстар министрлігі | D18: 17315.548 | E18: Министерство экологии и природных ресурсов Республики Казахстан
B19: 208 | C19: Қазақстан Республикасының Қорғаныс министрлiгi | D19: 73148.999 | E19: Министерство обороны Республики Казахстан
B20: 211 | C20: Қазақстан Республикасының Сауда және интеграция министрлігі | D20: 4220.2585 | E20: Министерство торговли и интеграции Республики Казахстан
B21: 212 | C21: Қазақстан Республикасының Ауыл шаруашылығы министрлiгi | D21: 36351.498 | E21: Министерство сельского хозяйства Республики Казахстан
B22: 213 | C22: Қазақстан Республикасының Еңбек және халықты әлеуметтiк қорғау министрлiгi | D22: 1014858.9 | E22: Министерство труда и социальной защиты населения РеспубликиКазахстан
... B49: 694 | C49: Қазақстан Республикасы Президентiнiң Іс басқармасы | D49: 39503.229 | E49: Управление Делами Президента Республики Казахстан

Sheet табл 10
A1: 10-кесте ШЫҒЫНДАРДЫҢ ЭКОНОМИКАЛЫҚ ЖІКТЕМЕСІ БОЙЫНША РЕСПУБЛИКАЛЫҚ БЮДЖЕТТІК ОРЫНДАЛУЫ (млн.теңге) | E1: Таблица 10 ИСПОЛНЕНИЕ РЕСПУБЛИКАНСКОГО БЮДЖЕТА ПО ЭКОНОМИЧЕСКОЙ КЛАССИФИКАЦИИ РАСХОДОВ (млн. тенге)
A3: Cанаты/_x000D_ Категория | B3: Iшкi сыныбы/_x000D_ Подкласс | C3: Ерекшелiгi/_x000D_ Специфика | D3: Атауы | F3: 2025 ж. қаңтар-ақпан/_x000D_ январь-февраль отчет 2025 г. | G3: Наименование
A4: 1 | B4: 2 | C4: 3 | D4: 4 | F4: 5 | G4: 6
D5: БАРЛЫҒЫ | F5: 3658804.3 | G5: ВСЕГО
A6: 1 | D6: Ағымдағы шығындар | F6: 3521478.6 | G6: Текущие затраты
A7: L01 Категория расходов | B7: 110 | D7: Жалақы | F7: 180170.78 | G7: Заработная плата
A8: 1 | B8: 110 | C8: 111 | D8: Еңбекке ақы төлеу | F8: 133384.19 | G8: Оплата труда
A9: 1 | C9: 112 | D9: Қосымша ақшалай төлемдер | F9: 22843.147 | G9: Дополнительные денежные выплаты
A10: 1 | C10: 113 | D10: Өтемақы төлемдері | F10: 22600.828 | G10: Компенсационные выплаты
A11: 1 | C11: 114 | D11: Міндетті кәсіптік зейнетақы жарналары | F11: 31.979699 | G11: Обязательные профессиональные пенсионные взносы
A12: 1 | C12: 116 | D12: Жұмыс берушілердің міндетті зейнетақы жарналары | F12: 1310.6316 | G12: Обязательные пенсионные взносы работодателей
A13: L01 Категория расходов | B13: 120 | D13: Жұмыс берушілердің жарналары | F13: 11315.499 | G13: Взносы работодателей
A14: 1 | B14: 120 | C14: 121 | D14: Әлеуметтік салық | F14: 4130.7945 | G14: Социальный налог
A15: 1 | C15: 122 | D15: Мемлекеттiк әлеуметтiк сақтандыру қорына әлеуметтiк аударымдар | F15: 5475.5657 | G15: Социальные отчисления в Государственный фонд социального страхования
A16: 1 | C16: 123 | D16: Мiндеттi сақтандыру жарналары | F16: 54.506088 | G16: Взносы на обязательное страхование
A17: 1 | C17: 124 | D17: Міндетті әлеуметтік медициналық сақтандыруға аударымдар | F17: 1654.6328 | G17: Отчисления на обязательное социальное медицинское страхование
A18: L01 Категория расходов | B18: 130 | D18: Қазақстан Республикасының заңнамалық актілеріне сәйкес азаматтардың жекелеген санаттарына жалақы төлеу және жарналар аудару | F18: 10064.033 | G18: Выплата заработной платы отдельным категориям граждан и отчисления взносов в соответствии с законодательными актами Республики Казахстан
A19: 1 | B19: 130 | C19: 131 | D19: Техникалық персоналдың еңбегіне ақы төлеу | F19: 8835.8075 | G19: Оплата труда технического персонала
A20: 1 | C20: 134 | D20: Алқа билерге сыйақылар төлеу | F20: 63.507774 | G20: Выплата вознаграждений присяжным заседателям
A21: 1 | C21: 135 | D21: Техникалық персонал бойынша жұмыс берушілердің жарналары | F21: 1109.4462 | G21: Взносы работодателей по техническому персоналу
A22: 1 | C22: 136 | D22: Техникалық персоналдың ел iшiндегi iссапарлары мен қызметтiк сапарлары | F22: 53.718961 | G22: Командировки и служебные разъезды внутри страны технического персонала
A23: 1 | C23: 137 | D23: Қорғаушы мәжілістердің қызметтiк сапарлар | F23: 1.552628 | G23: Командировочные расходы присяжных заседателей
A24: L01 Категория расходов | B24: 140 | D24: Қорлар сатып алу | F24: 15844.86 | G24: Приобретение запасов
A25: 1 | B25: 140 | C25: 141 | D25: Азық-түлiк өнiмдерiн сатып алу | F25: 11313.272 | G25: Приобретение продуктов питания
A26: 1 | C26: 142 | D26: Дәрілік заттар және медициналық мақсаттағы өзге де бұйымдарды сатып алу | F26: 164.19109 | G26: Приобретение лекарственных средств и прочих изделий медицинского назначения
A27: 1 | C27: 143 | D27: Заттай мүлiктердi, басқа да киім нысанын және арнаулы киім-кешектер сатып алу, тiгу және жөндеу | F27: 105.3942 | G27: Приобретение, пошив и ремонт предметов вещевого имущества идругого форменного и специального обмундирования
A28: 1 | C28: 144 | D28: Отын, жанар-жағар май материалдарын сатып алу | F28: 2986.3304 | G28: Приобретение топлива, горюче-смазочных материалов
A29: 1 | C29: 149 | D29: Өзге де қорларды сатып алу | F29: 1275.6723 | G29: Приобретение прочих запасов
A30: L01 Категория расходов | B30: 150 | D30: Қызметтер мен жұмыстарды сатып алу | F30: 231812.73 | G30: Приобретение услуг и работ
A31: 1 | B31: 150 | C31: 151 | D31: Коммуналдық қызметтерге ақы төлеу | F31: 7725.203 | G31: Оплата коммунальных услуг
A32: 1 | C32: 152 | D32: Байланыс қызметтерiне ақы төлеу | F32: 598.91959 | G32: Оплата услуг связи
A33: 1 | C33: 153 | D33: Көлiктiк қызмет көрсетулерге ақы төлеу | F33: 2128.309 | G33: Оплата транспортных услуг
A34: 1 | C34: 154 | D34: Зерттеулер бойынша қызметтерге ақы төлеу | F34: 48442.469 | G34: Оплата услуг по исследованиям
A35: 1 | C35: 156 | D35: Консалтингтік қызметтерге ақы төлеу | F35: 25.551938 | G35: Оплата консалтинговых услуг
A36: 1 | C36: 157 | D36: Форумдар, семинарлар, конференциялар өткізуге және имидждік іс-шараларға арналған қызметтерге ақы төлеу | F36: 2.599 | G36: Оплата услуг на проведение форумов, семинаров, конференций и на имиджевые мероприятия
A37: 1 | C37: 158 | D37: Ақпараттандыру саласындағы жұмыстар мен қызметтерге ақы төлеу | F37: 2787.6358 | G37: Оплата работ и услуг в сфере информатизации
A38: 1 | C38: 159 | D38: Өзге де қызметтер мен жұмыстарға ақы төлеу | F38: 170102.05 | G38: Оплата прочих услуг и работ
A39: L01 Категория расходов | B39: 160 | D39: Басқа да ағымдағы шығындар | F39: 244531.44 | G39: Другие текущие затраты
A40: 1 | B40: 160 | C40: 161 | D40: Ел iшiндегi iссапарлар мен қызметтiк сапарлар | F40: 2432.1186 | G40: Командировки и служебные разъезды внутри страны
A41: 1 | C41: 162 | D41: Елден тыс жерлерге iссапарлар мен қызметтiк сапарлар | F41: 1255.2853 | G41: Командировки и служебные разъезды за пределы страны
...

Sheet таб 11
A1: 11-кесте ШЫҒЫНДАРДЫҢ ЭКОНОМИКАЛЫҚ ЖІКТЕМЕСІ БОЙЫНША ЖЕРГІЛІКТІ БЮДЖЕТТІК ОРЫНДАЛУЫ (млн.теңге) | E1: Таблица 11 ИСПОЛНЕНИЕ МЕСТНОГО БЮДЖЕТА ПО ЭКОНОМИЧЕСКОЙ КЛАССИФИКАЦИИ РАСХОДОВ (млн. тенге)
A3: Cанаты/_x000D_ Категория | B3: Iшкi сыныбы/_x000D_ Подкласс | C3: Ерекшелiгi/_x000D_ Специфика | D3: Атауы | F3: 2025 ж. қаңтар-ақпан/_x000D_ январь-февраль отчет 2025 г. | G3: Наименование
A4: 1 | B4: 2 | C4: 3 | D4: 4 | F4: 5 | G4: 6
D5: БАРЛЫҒЫ | F5: 1874984.8 | G5: ВСЕГО
A6: 1 | D6: Ағымдағы шығындар | F6: 1578448.4 | G6: Текущие затраты
A7: L01 Категория расходов | B7: 110 | D7: Жалақы | F7: 511819.52 | G7: Заработная плата
A8: 1 | B8: 110 | C8: 111 | D8: Еңбекке ақы төлеу | F8: 472592.14 | G8: Оплата труда
A9: 1 | C9: 112 | D9: Қосымша ақшалай төлемдер | F9: 21419.752 | G9: Дополнительные денежные выплаты
A10: 1 | C10: 113 | D10: Өтемақы төлемдері | F10: 10493.932 | G10: Компенсационные выплаты
A11: 1 | C11: 114 | D11: Міндетті кәсіптік зейнетақы жарналары | F11: 0.848984 | G11: Обязательные профессиональные пенсионные взносы
A12: 1 | C12: 116 | D12: Жұмыс берушілердің міндетті зейнетақы жарналары | F12: 7312.8429 | G12: Обязательные пенсионные взносы работодателей
A13: L01 Категория расходов | B13: 120 | D13: Жұмыс берушілердің жарналары | F13: 57371.922 | G13: Взносы работодателей
A14: 1 | B14: 120 | C14: 121 | D14: Әлеуметтік салық | F14: 25666.402 | G14: Социальный налог
A15: 1 | C15: 122 | D15: Мемлекеттiк әлеуметтiк сақтандыру қорына әлеуметтiк аударымдар | F15: 19157.278 | G15: Социальные отчисления в Государственный фонд социального страхования
A16: 1 | C16: 123 | D16: Мiндеттi сақтандыру жарналары | F16: 81.107866 | G16: Взносы на обязательное страхование
A17: 1 | C17: 124 | D17: Міндетті әлеуметтік медициналық сақтандыруға аударымдар | F17: 12467.134 | G17: Отчисления на обязательное социальное медицинское страхование
A18: L01 Категория расходов | B18: 130 | D18: Қазақстан Республикасының заңнамалық актілеріне сәйкес азаматтардың жекелеген санаттарына жалақы төлеу және жарналар аудару | F18: 15225.243 | G18: Выплата заработной платы отдельным категориям граждан и отчисления взносов в соответствии с законодательными актами Республики Казахстан
A19: 1 | B19: 130 | C19: 131 | D19: Техникалық персоналдың еңбегіне ақы төлеу | F19: 13222.357 | G19: Оплата труда технического персонала
A20: 1 | C20: 133 | D20: Негізгі жұмыс орны бойынша мәслихат депутаттарына орташа жалақыны өтеу | F20: 0.146834 | G20: Возмещение средней заработной платы депутатам маслихата по их основному месту работы
A21: 1 | C21: 135 | D21: Техникалық персонал бойынша жұмыс берушілердің жарналары | F21: 1731.3604 | G21: Взносы работодателей по техническому персоналу
A22: 1 | C22: 136 | D22: Техникалық персоналдың ел iшiндегi iссапарлары мен қызметтiк сапарлары | F22: 271.37879 | G22: Командировки и служебные разъезды внутри страны технического персонала
A23: L01 Категория расходов | B23: 140 | D23: Қорлар сатып алу | F23: 28940.247 | G23: Приобретение запасов
