Workbook
Name \E: #REF!
Name \E: #REF!
Name \E: #REF!
Name \E: #REF!
Name \E: #REF!
Name _____________________MS798: #REF!
Name _____________________MS798: #REF!
Name _____________________tab1: #REF!
Name _____________________tab2: #REF!
Name _____________________tab6798: #REF!
Name ____________________MS798: #REF!
Name ____________________tab1: #REF!
Name ____________________tab2: #REF!
Name ____________________tab6798: #REF!
Name ___________________MS798: #REF!
Name ___________________tab1: #REF!
Name ___________________tab2: #REF!
Name ___________________tab6798: #REF!
Name __________________MS798: #REF!
Name __________________tab1: #REF!
Name __________________tab2: #REF!
Name __________________tab6798: #REF!
Name _________________MS798: #REF!
Name _________________prt1: #N/A
Name _________________prt2: #N/A
Name _________________prt3: #N/A
Name _________________prt4: #N/A
Name _________________prt5: #N/A
Name _________________prt6: #N/A
Name _________________prt7: #N/A
Name _________________prt8: #N/A
Name _________________tab1: #REF!
Name _________________tab2: #REF!
Name _________________tab6798: #REF!
Name ________________MS798: #REF!
Name ________________prt1: #N/A
Name ________________prt2: #N/A
Name ________________prt3: #N/A
Name ________________prt4: #N/A
Name ________________prt5: #N/A
Name ________________prt6: #N/A
Name ________________prt7: #N/A
Name ________________prt8: #N/A
Name ________________tab1: #REF!
Name ________________tab2: #REF!
Name ________________tab6798: #REF!
Name _______________MS798: #REF!
Name _______________prt1: #N/A
Name _______________prt2: #N/A
Name _______________prt3: #N/A
Name _______________prt4: #N/A
Name _______________prt5: #N/A
Name _______________prt6: #N/A
Name _______________prt7: #N/A
Name _______________prt8: #N/A
Name _______________tab1: #REF!
Name _______________tab2: #REF!
Name _______________tab6798: #REF!
Name ______________MS798: #REF!
Name ______________prt1: #N/A

Sheet табл 1
A1: 1-кесте | J1: Таблица 1
A3: НЕГІЗГІ МАКРОЭКОНОМИКАЛЫҚ ИНДИКАТОРЛАР/
A4: ОСНОВНЫЕ МАКРОЭКОНОМИЧЕСКИЕ ИНДИКАТОРЫ
A6: Атауы | B6: 2019 жыл/ 2019 год | C6: 2020 жыл/ 2020 год | D6: 2021 жыл/ 2021 год | E6: 2022 жыл/ 2022 год | F6: 2023 жыл/ 2023 год | G6: 2024 жыл/ 2024 год | H6: 2025 жыл/ 2025 год | I6: 2026 ж. 1 наурыздағы есеп/ отчет на 1 марта 2026 г. | J6: Наименование
A7: 1 | B7: 2 | C7: 3 | D7: 4 | E7: 5 | F7: 6 | G7: 7 | H7: 8 | I7: 9 | J7: 10
A8: Жалпы ішкi өнiм, млрд. теңге | B8: 69532.626 | C8: 70649 | D8: 83951.587 | E8: 65487.797 | F8: 120561.1 | G8: 84962.621 | H8: 99724.898 | I8: 159561.35 | J8: Валовой внутренний продукт, млрд.тенге январь-декабрь 2025 года (оперативные данные)
A9: өткен жылдың тиiстi кезеңiндегi нақты есептеудегi %-бен | B9: 104.5 | C9: 97.5 | D9: 103.3 | E9: 103 | F9: 105.1 | G9: 104.1 | H9: 106.3 | I9: 106.5 | J9: в % к соответствующему периоду предыдущего года
A10: Өнеркәсiп өнiмiнiң көлемi, млрд. теңге | B10: 29380.342 | C10: 26743.4 | D10: 37047.6 | E10: 4157.4 | F10: 46401.716 | G10: 50124.86 | H10: 61560.646 | I10: 9140.065 | J10: Объем промышленного производства, млрд.тенге (февраль 2026г.)
A11: өткен жылдың тиiстi кезеңiне %-бен | B11: 104.1 | C11: 99.3 | D11: 103.8 | E11: 97.2 | F11: 104.3 | G11: 102.8 | H11: 107.5 | I11: 96.9 | J11: % февраль 2026г. к февралю 2025г.
A12: Мембюджетке кірістер, млрд. теңге | B12: 12758.479 | C12: 14521.191 | D12: 15847.431 | E12: 20248.101 | F12: 24917.246 | G12: ='[46]табл 2 '!C8/1000 -> 27132.165 | H12: ='[47]табл 2 '!C8/1000 -> 29871.048 | I12: ='табл 2 '!C8/1000 -> 5055.9969 | J12: Доходы в госбюджет, млрд.тенге
A13: ЖIӨ-ге %-бен | B13: 18.502241 | C13: 20.535071 | D13: =D12/D8*100 -> 18.876869 | E13: =E12/E8*100 -> 30.918891 | G13: =G12/G8*100 -> 31.934237 | H13: =H12/H8*100 -> 29.95345 | I13: =I12/I8*100 -> 3.1686853 | J13: в % к ВВП
A14: Мембюджеттен шығындар, млрд. теңге | B14: 13535.581 | C14: 16725.097 | D14: 17951.888 | E14: 21532.543 | F14: 26760 | G14: ='[46]табл 2 '!C18/1000 -> 30318.236 | H14: ='[47]табл 2 '!C18/1000 -> 33442.829 | I14: ='табл 2 '!C19/1000 -> 4642.1966 | J14: Затраты из госбюджета, млрд. тенге
A15: ЖIӨ-ге %-бен | B15: 19.629188 | C15: 23.651714 | D15: =D14/D8*100 -> 21.38362 | E15: =E14/E8*100 -> 32.880238 | F15: 35.421743 | G15: =G14/G8*100 -> 35.684206 | H15: =H14/H8*100 -> 33.535084 | I15: =I14/I8*100 -> 2.9093491 | J15: в % к ВВП
A16: Таза бюджеттік кредит беру, млрд. теңге | B16: 262.88084 | C16: 261.98101 | D16: 267.33754 | E16: 592.68034 | F16: 466.44174 | G16: ='[46]табл 2 '!C34/1000 -> 198.40855 | H16: ='[47]табл 3'!E34/1000 -> 286.23027 | I16: ='табл 2 '!C35/1000 -> -10.995265 | J16: Чистое бюджетное кредитование, млрд. тенге
A17: ЖIӨ-ге %-бен | B17: 0.38122761 | C17: 0.37047917 | D17: =D16/D8*100 -> 0.31844251 | E17: =E16/E8*100 -> 0.9050241 | F17: 0.61742075 | G17: =G16/G8*100 -> 0.23352452 | H17: =H16/H8*100 -> 0.28701987 | I17: =I16/I8*100 -> -0.0068909324 | J17: в % к ВВП
A18: Қаржылық активтермен болатын операциялар бойынша сальдо, млрд. теңге | B18: 245.32373 | C18: 340.26326 | D18: 163.01136 | E18: 292.00158 | F18: 501.9047 | G18: ='[46]табл 2 '!C37/1000 -> 201.56181 | H18: ='[47]табл 3'!E37/1000 -> 525.85985 | I18: ='табл 2 '!C38/1000 -> 49.443517 | J18: Сальдо по операциям с финансовыми активами, млрд.тенге
A19: ЖIӨ-ге %-бен | B19: 0.35576643 | C19: 0.48118163 | D19: =D18/D8*100 -> 0.19417306 | E19: =E18/E8*100 -> 0.44588701 | F19: 0.66436244 | G19: =G18/G8*100 -> 0.23723586 | H19: =H18/H8*100 -> 0.52731049 | I19: =I18/I8*100 -> 0.030987152 | J19: в % к ВВП
A20: Мембюджеттiң тапшылығы (-) / профицитi (+), млрд. теңге | B20: -1285.3067 | C20: -2806.1502 | D20: -2534.8062 | E20: -2169.1247 | F20: -2811.1006 | G20: ='[46]табл 2 '!C40/1000 -> -3586.0419 | H20: ='[47]табл 3'!E40/1000 -> -4383.8711 | I20: ='табл 2 '!C41/1000 -> 375.35206 | J20: Дефицит (-) / профицит (+) госбюджета, млрд.тенге
A21: ЖIӨ-ге %-бен | B21: -1.8639412 | C21: -3.9683036 | D21: =D20/D8*100 -> -3.0193666 | E21: =E20/E8*100 -> -3.3122579 | F21: -3.7210045 | G21: =G20/G8*100 -> -4.2207288 | H21: =H20/H8*100 -> -4.3959645 | I21: =I20/I8*100 -> 0.23523997 | J21: в % к ВВП
A22: Тұтыну бағаларының индексі өткен жылдың айына, %-бен | B22: 105.4 | C22: 107.5 | D22: 108.4 | E22: 120.3 | F22: 109.5 | G22: 108.9 | H22: 112.2 | I22: 111 | J22: Индекс потребительских цен январь 2026
A23: орташа есеппен өткен жылдың тиiстi кезеңiндегi кезге арналған, %-бен | B23: 105.3 | C23: 106.8 | D23: 108 | E23: 115 | G23: 108.6 | H23: 103.9 | I23: 106.4 | J23: в % февраль 2026г. к февралю 2025г.
A24: Орташа айлық атаулы жалақы 1 қызметкердың, теңге | B24: 186815 | C24: 220848 | D24: 268051 | E24: 303055 | F24: 350542 | G24: 390328 | H24: 429368 | I24: 429368 | J24: Среднемесячная номинальная заработная плата 1 работника, тенге (3 квартал 2025г.)
A25: өткен жылдың тиiстi кезеңiне %-бен | B25: 114.8 | C25: 104.4 | D25: 115.3 | E25: 112.2 | F25: 116.9 | G25: 111.3 | H25: 110 | I25: 110 | J25: в % к соответствующему периоду предыдущего года
A26: Экспорт, млн. АҚШ долл. | B26: 58065.6 | C26: 46 949,7 2 | D26: 54549.5 | E26: ____ | F26: 71274.7 | G26: 73884.5 | H26: 71135.7 | I26: 6326.9 | J26: Экспорт, млн. долл. США (январь 2026г.)
A27: Импорт, млн. АҚШ долл. | B27: 39709.3 | C27: 38 081,4 2 | D27: 36825.9 | E27: ____ | F27: 54643.5 | G27: 53590.3 | H27: 57666.9 | I27: 4684.8 | J27: Импорт, млн. долл. США (январь 2026г.)
A28: Сауда балансының сальдосы, млн. АҚШ долл. | B28: 18356.3 | C28: 8969 | D28: 17723.6 | E28: ____ | F28: 16631.2 | G28: =G26-G27 -> 20294.2 | H28: =H26-H27 -> 13468.8 | I28: =I26-I27 -> 1642.1 | J28: Сальдо торгового баланса, млн. долл. США
A29: Теңгенiң АҚШ долларына қарағандағы ресми айырбас бағамы: | J29: Официальный обменный курс тенге к доллару США:
A30: кезеңнiң аяғындағы | B30: 381.18 | C30: 420.71 | D30: 433.83 | E30: 459.92 | F30: 448.17 | G30: 525.11 | H30: 521.59 | I30: 497.56 | J30: на конец периода
A31: кезең бойынша орташа | B31: 382.75 | C31: 412.95 | D31: 433.66 | E31: 460.48 | F31: 451.28 | G31: 469.44 | H31: 502.57 | I31: 495.89 | J31: в среднем за февраль 2026 года
A33: Ақпарат көзi: / Источник:
A34: Қазақстан Республикасының Қаржы министрлiгi / Министерство финансов Республики Казахстан.
A35: Ұлттық статистика бюросы Қазақстан Республикасының Стратегиялық жоспарлау және реформалар агенттігі / Бюро национальной статистики Агентства по стратегическому планированию и реформам Республики Казахстан
A36: Қазақстан Республикасының Ұлттық Банкi / Национальный Банк Республики Казахстан.
A37: Ескерту: / Примечание:
A38: 1 - Ұлттық статистика бюросы Қазақстан Республикасының Стратегиялық жоспарлау және реформалар агенттігінің деректері бойынша /Объем ВВП по отчетным данным Бюро национальной статистики Агентства по стратегическому планированию и реформам Республики Казахстан
A39: 2 - Ұлттық статистика бюросы Қазақстан Республикасының Стратегиялық жоспарлау және реформалар агенттігінің деректері бойынша /По данным Бюро национальной статистики Агентства по стратегическому планированию и реформам Республики Казахстан
A40: 3 - Ұлттық статистика бюросы Қазақстан Республикасының Стратегиялық жоспарлау және реформалар агенттігінің деректері бойынша /По данным Бюро национальной статистики Агентства по стратегическому планированию и реформам Республики Казахстан

Sheet табл 2 
A1: 2-кесте | F1: Таблица - 2
A2: МЕМЛЕКЕТТІК ЖӘНЕ РЕСПУБЛИКАЛЫҚ | F2: СРАВНИТЕЛЬНЫЙ АНАЛИЗ ИСПОЛНЕНИЯ
A3: БЮДЖЕТТЕР АТҚАРЫЛУЫНЫҢ САЛЫСТЫРМА ТАЛДАУЫ | F3: ГОСУДАРСТВЕННОГО И РЕСПУБЛИКАНСКОГО БЮДЖЕТОВ
A5: Атауы | B5: Мемлекеттік бюджет / Государственный бюджет | F5: Республикалық бюджет / Республиканский бюджет | J5: Наименование
B6: 2026 жылға түзету енгізілген бюджет (млн. теңге)/ скорректированный бюджет на 2026 год (млн.тенге) | C6: 2026 жылғы қаңтар-ақпан атқарылуы (млн. теңге)/ исполнение за январь-февраль 2026 года (млн.тенге) | D6: бір жылға түзету енгізілген бюджеттің атқарылу %-ы/% исполнения к скорректированному бюджету на год | E6: 2025 ж. қаңтар-ақпан %-бен 2026 ж. қаңтар-ақпанына/ 2026 г. январь-февраль в % к январю-февралю 2025 г. | F6: 2026 жылға түзету енгізілген бюджет (млн. теңге)/ скорректированный бюджет на 2026 год (млн.тенге) | G6: 2026 жылғы қаңтар-ақпан атқарылуы (млн. теңге)/ исполнение за январь-февраль 2026 года (млн.тенге) | H6: бір жылға түзету енгізілген бюджеттің атқарылу %-ы/% исполнения к скорректированному бюджету на год | I6: 2025 ж. қаңтар-ақпан %-бен 2026 ж. қаңтар-ақпанына/ 2026 г. январь-февраль в % к январю-февралю 2025 г.
A7: 1 | B7: 2 | C7: 3 | D7: 4 | E7: 5 | F7: 6 | G7: 7 | H7: 8 | I7: 9 | J7: 10
A8: I. КІРІСТЕР | B8: 32384706 | C8: 5055996.9 | D8: 15.612298 | E8: 100.69074 | F8: 22889278 | G8: 3646026.1 | H8: 15.928969 | I8: 100.36746 | J8: I. ДОХОДЫ
A9: Салықтық түсімдер оның iшiнде: | B9: 28699405 | C9: 4442281.2 | D9: 15.478652 | E9: 119.19988 | F9: 18886019 | G9: 2979003.4 | H9: 15.773591 | I9: 129.66463 | J9: Налоговые поступления, в том числе:
A10: корпоративтік табыс салығы | B10: 6975954.1 | C10: 997978.36 | D10: 14.305977 | E10: 107.45389 | F10: 5184046.5 | G10: 814528.08 | H10: 15.712206 | I10: 116.9339 | J10: корпоративный подоходный налог
A11: жеке табыс салығы | B11: 3322766.7 | C11: 546738.39 | D11: 16.454312 | E11: 109.20757 | F11: 0 | G11: 0 | H11: 0 | I11: 0 | J11: индивидуальный подоходный налог
A12: әлеуметтік салық | B12: 2084024.4 | C12: 363934.9 | D12: 17.463082 | E12: 106.72556 | F12: 0 | G12: 0 | H12: 0 | I12: 0 | J12: социальный налог
A13: қосылған құн салығы | B13: 10013329 | C13: 1534499.2 | D13: 15.324566 | E13: 138.76128 | F13: 10013329 | G13: 1534499.2 | H13: 15.324566 | I13: 138.76128 | J13: налог на добавленную стоимость
A14: акциздер | B14: 1518756 | C14: 165944.63 | D14: 10.926352 | E14: 119.96786 | F14: 151773.43 | G14: 12138.185 | H14: 7.9975693 | I14: 66.69697 | J14: акцизы
A15: Салықтық емес түсімдер | B15: 433946.26 | C15: 96221.599 | D15: 22.173621 | E15: 36.27583 | F15: 330736.78 | G15: 36144.023 | H15: 10.928335 | I15: 20.461552 | J15: Неналоговые поступления
A16: Негізгі капиталды сатудан түсетін түсімдер | B16: 264629.16 | C16: 22019.204 | D16: 8.3207778 | E16: 75.11765 | F16: 2200 | G16: 257.17461 | H16: 11.689755 | I16: 46.079421 | J16: Поступления от продажи основного капитала
A17: Арнаулы түсімдер | B17: 216725.81 | C17: 35474.932 | D17: 16.368577 | E17: 3.13844 | F17: 20375.447 | G17: 608.16748 | H17: 2.9848056 | I17: - | J17: Специальные поступления
A18: Трансферттердің түсімдері | B18: 2770000 | C18: 460000 | D18: 16.606498 | F18: 3649947.1 | G18: 630013.31 | H18: 17.260889 | I18: 54.787487 | J18: Поступление трансфертов
A19: II. ШЫҒЫНДАР | B19: 35473282 | C19: 4642196.6 | D19: 13.086459 | E19: 105.98054 | F19: 26275333 | G19: 3751106.4 | H19: 14.276152 | I19: 103.08841 | J19: II. ЗАТРАТЫ
A20: 1. Жалпы сипаттағы мемлекеттiк қызметтер | B20: 1688231 | C20: 235766.18 | D20: 13.965279 | E20: 82.58201 | F20: 1224564.3 | G20: 152984.97 | H20: 12.493012 | I20: 73.15937 | J20: 1. Государственные услуги общего характера
A21: 2. Қорғаныс | B21: 1522804.6 | C21: 118102.58 | D21: 7.7555966 | E21: 127.87882 | F21: 1427833.2 | G21: 113974.93 | H21: 7.98237 | I21: 140.9775 | J21: 2. Оборона
A22: 3. Қоғамдық тәртіп, қауіпсіздік, құқықтық, сот, қылмыстық-атқару қызметі | B22: 1972792.2 | C22: 235075.81 | D22: 11.915893 | E22: 116.26201 | F22: 1503838 | G22: 183079.87 | H22: 12.174175 | I22: 115.65243 | J22: 3. Общественный порядок, безопасность, правовая, судебная, уголовно-исполнительная деятельность
A23: 4. Бiлiм беру | B23: 6961191.7 | C23: 902264.14 | D23: 12.961346 | E23: 97.22035 | F23: 812335.1 | G23: 82306.333 | H23: 10.132067 | I23: 40.95525 | J23: 4. Образование
A24: 5. Денсаулық сақтау | B24: 3120196.6 | C24: 404090.53 | D24: 12.950803 | E24: 103.88535 | F24: 2731840.1 | G24: 368596.01 | H24: 13.492591 | I24: 101.43188 | J24: 5. Здравоохранение
A25: 6. Әлеуметтiк көмек және әлеуметтiк қамсыздандыру | B25: 7650723.4 | C25: 1225238.6 | D25: 16.014676 | E25: 112.7424 | F25: 6833009.5 | G25: 1148432.3 | H25: 16.807123 | I25: 113.1723 | J25: 6. Социальная помощь и социальное обеспечение
A26: 7. Тұрғын үй-коммуналдық шаруашылық | B26: 2004027.3 | C26: 182975.41 | D26: 9.1303851 | E26: 114.03763 | F26: 95156.925 | G26: 14367.408 | H26: 15.098647 | I26: 209.17481 | J26: 7. Жилищно-коммунальное хозяйство
A27: 8. Мәдениет, спорт, туризм және ақпараттық кеңістiк | B27: 1180949.7 | C27: 138144.96 | D27: 11.697785 | E27: 90.18876 | F27: 236604.46 | G27: 35433.353 | H27: 14.975775 | I27: 69.36705 | J27: 8. Культура, спорт, туризм и информационное пространство
A28: 9. Отын-энергетика кешенi және жер қойнауын пайдалану | B28: 259709.64 | C28: 33239.305 | D28: 12.798641 | E28: 87.28034 | F28: 128415.45 | G28: 14716.763 | H28: 11.460274 | I28: 175.1251 | J28: 9. Топливно-энергетический комплекс и недропользование
A29: 10. Ауыл, су, орман, балық шаруашылығы, ерекше қорғалатын табиғи аумақтар, қоршаған ортаны және жануарлар дүниесін қорғау, жер қатынастары | B29: 1624154.3 | C29: 232857.26 | D29: 14.337139 | E29: 126.01333 | F29: 708055.7 | G29: 39086.262 | H29: 5.5202242 | I29: 86.97626 | J29: 10. Сельское, водное, лесное, рыбное хозяйство, особо охраняемые природные территории, охрана окружающей среды и животного мира, земельные отношения
A30: 11. Өнеркәсіп, сәулет, қала құрылысы және құрылыс қызметі | B30: 76485.702 | C30: 7135.876 | D30: 9.3296861 | E30: 122.52903 | F30: 29050.311 | G30: 531.06884 | H30: 1.8281004 | I30: 327.51855 | J30: 11. Промышленность, архитектурная, градостроительная и строительная деятельность
... A33: 14. Борышқа қызмет көрсету | B33: 3580348.6 | C33: 617844.23 | D33: 17.256538 | E33: 116.08709 | F33: 3471233.6 | G33: 615160.39 | H33: 17.721665 | I33: 116.15459 | J33: 14. Обслуживание долга
F34: 5171567.8 | G34: 840915.97 | H34: 16.260368 | I34: 108.28857 | J34: 15. Трансферты
A35: III. ТАЗА БЮДЖЕТТІК КРЕДИТ БЕРУ | B35: 992685.92 | C35: -10995.265 | D35: -1.1076277 | E35: -87.69781 | F35: 858213.36 | G35: -3338.2677 | H35: -0.38897876 | I35: 100.15316 | J35: III. ЧИСТОЕ БЮДЖЕТНОЕ КРЕДИТОВАНИЕ
A36: Бюджеттік кредиттер | B36: 1262790.3 | C36: 3400 | D36: 0.26924503 | E36: 13.52562 | F36: 1104500 | G36: 11000 | H36: 0.99592576 | I36: 55 | J36: Бюджетные кредиты
A37: Бюджеттік кредиттерді өтеу | B37: 270104.34 | C37: 14395.265 | D37: 5.32952 | E37: 114.24984 | F37: 246286.64 | G37: 14338.268 | H37: 5.8217806 | I37: 135.57562 | J37: Погашение бюджетных кредитов
A38: IV. ҚАРЖЫ АКТИВТЕРІМЕН ОПЕРАЦИЯЛАР БОЙЫНША САЛЬДО - ҚАРЖЫ АК | B38: 573230.15 | C38: 49443.517 | D38: 8.6254216 | E38: 72.65305 | F38: 350436.62 | G38: 5124.5272 | H38: 1.4623264 | I38: 6677.3017 | J38: IV. САЛЬДО ПО ОПЕРАЦИЯМ С ФИНАНСОВЫМИ АКТИВАМИ
A39: Қаржылық активтерді сатып алу | B39: 573346.75 | C39: 49932.035 | D39: 8.708872 | E39: 73.16401 | F39: 350436.62 | G39: 5124.5272 | H39: 1.4623264 | I39: 6677.3017 | J39: Приобретение финансовых активов
A40: Мемлекеттің қаржы активтерін сатудан түсетін түсімдер | B40: 116.6 | C40: 488.51744 | D40: 418.96864 | E40: 253.87923 | F40: 0 | G40: 0 | H40: 0 | I40: - | J40: Поступления от продажи финансовых активов государства
A41: V. БЮДЖЕТ ТАПШЫЛЫҒЫ (ПРОФИЦИТІ) | B41: -4654492.1 | C41: 375352.06 | D41: -8.0642969 | E41: 66.96905 | F41: -4594705.2 | G41: -106866.61 | H41: 2.3258644 | I41: -783.71479 | J41: V. ДЕФИЦИТ (ПРОФИЦИТ) БЮДЖЕТА
A42: VI. БЮДЖЕТТІҢ МҰНАЙҒА ҚАТЫСТЫ ЕМЕС ТАПШЫЛЫҒЫ (ПРОФИЦИТІ) | B42: -9119012.1 | C42: -138938.67 | D42: 1.5236154 | E42: -24.8929 | F42: -9059225.2 | G42: -621157.35 | H42: 6.8566277 | I42: -54.8596 | J42: VI. НЕНЕФТЯНОЙ ДЕФИЦИТ (ПРОФИЦИТ) БЮДЖЕТА

Sheet табл 3
A1: 3-кесте | E1: Таблица 3
A2: МЕМЛЕКЕТТІК БЮДЖЕТТІҢ АТҚАРЫЛУЫ | E2: ИСПОЛНЕНИЕ ГОСУДАРСТВЕННОГО БЮДЖЕТА
A3: (млн.теңге) | E3: (млн. тенге)
A5: Атауы | B5: 2023 ж. есеп/ 2023 г. отчет | C5: 2024 ж. есеп/ 2024 г. отчет | D5: 2025 ж. есеп/ 2025 г. отчет | F5: 2026 ж. қантар-ақпан есеп/январь-феврал отчет 2026 г. | G5: Наименование
D6: жылдық/ годовой | E6: қантар-ақпан/январь-феврал
A7: 1 | B7: 2 | C7: 3 | D7: 4 | E7: 5 | F7: 6 | G7: 7
A8: I. КІРІСТЕР | B8: 24917246 | C8: 27132165 | D8: 29871048 | E8: 5021312.6 | F8: 5055996.9 | G8: I. ДОХОДЫ
A9: Салықтық түсімдер_x000D_ оның iшiнде: | B9: 18912204 | C9: 19700517 | D9: 23188179 | E9: 3726749.7 | F9: 4442281.2 | G9: Налоговые поступления,_x000D_ в том числе:
A10: корпоративтік табыс салығы | B10: 5045696.1 | C10: 5213291.4 | D10: 6322629 | E10: 928750.33 | F10: 997978.36 | G10: корпоративный подоходный налог
A11: жеке табыс салығы | B11: 1992384.9 | C11: 2451640 | D11: 2859192.4 | E11: 500641.49 | F11: 546738.39 | G11: индивидуальный подоходный налог
A12: әлеуметтік салық | B12: 1321272.8 | C12: 1579329.4 | D12: 1866744.5 | E12: 341000.69 | F12: 363934.9 | G12: социальный налог
A13: қосылған құн салығы | B13: 5674110.6 | C13: 5179378.1 | D13: 6111842.3 | E13: 1105855.5 | F13: 1534499.2 | G13: налог на добавленную стоимость
A14: акциздер | B14: 840215.7 | C14: 844909.98 | D14: 1039998.8 | E14: 138324.24 | F14: 165944.63 | G14: акцизы
A15: Салықтық емес түсімдер | B15: 1822932.9 | C15: 1630378.8 | D15: 1248358.7 | E15: 265249.93 | F15: 96221.599 | G15: Неналоговые поступления
A16: Негізгі капиталды сатудан түсетін түсімдер | B16: 182108.73 | C16: 201680.05 | D16: 184510.46 | E16: 29312.957 | F16: 22019.204 | G16: Поступления от продажи основного капитала
A17: Арнаулы түсімдер | B17: 4000000 | C17: 6006003.1 | D17: 5250000 | E17: 1130336.3 | F17: 35474.932 | G17: Специальные поступления
A18: Трансферттердің түсімдері | F18: 460000 | G18: Поступления трансфертов
A19: II. ШЫҒЫНДАР | B19: 26760000 | C19: 30318236 | D19: 33442829 | E19: 4380234.8 | F19: 4642196.6 | G19: II. ЗАТРАТЫ
A20: 1. Жалпы сипаттағы мемлекеттiк қызметтер | B20: 1489124.1 | C20: 1766404.2 | D20: 1862411.1 | E20: 285493.39 | F20: 235766.18 | G20: 1. Государственные услуги общего характера
A21: 2. Қорғаныс | B21: 1169572.2 | C21: 1184492.1 | D21: 1318214 | E21: 92355.081 | F21: 118102.58 | G21: 2. Оборона
A22: 3. Қоғамдық тәртіп, қауіпсіздік, құқықтық, сот, қылмыстық-атқару қызметі | B22: 1611950.5 | C22: 1670629.3 | D22: 1823270.4 | E22: 202194.87 | F22: 235075.81 | G22: 3. Общественный порядок, безопасность, правовая, судебная, уголовно-исполнительная деятельность
A23: 4. Бiлiм беру | B23: 5807649.5 | C23: 6707200.2 | D23: 7100858.9 | E23: 928060.96 | F23: 902264.14 | G23: 4. Образование
A24: 5. Денсаулық сақтау | B24: 2503067.6 | C24: 2499780.2 | D24: 2847071 | E24: 388977.41 | F24: 404090.53 | G24: 5. Здравоохранение
A25: 6. Әлеуметтiк көмек және әлеуметтiк қамсыздандыру | B25: 5283759.1 | C25: 6034950.1 | D25: 6703136.5 | E25: 1086759.3 | F25: 1225238.6 | G25: 6. Социальная помощь и социальное обеспечение
A26: 7. Тұрғын үй-коммуналдық шаруашылық | B26: 1917632.4 | C26: 2380383.1 | D26: 2698913.5 | E26: 160451.78 | F26: 182975.41 | G26: 7. Жилищно-коммунальное хозяйство
A27: 8. Мәдениет, спорт, туризм және ақпараттық кеңістiк | B27: 877497.76 | C27: 1003471.8 | D27: 1230536.4 | E27: 153173.14 | F27: 138144.96 | G27: 8. Культура, спорт, туризм и информационное пространство
A28: 9. Отын-энергетика кешенi және жер қойнауын пайдалану | B28: 343550.37 | C28: 434088.47 | D28: 444295.67 | E28: 38083.38 | F28: 33239.305 | G28: 9. Топливно-энергетический комплекс и недропользование
A29: 10. Ауыл, су, орман, балық шаруашылығы, ерекше қорғалатын табиғи аумақтар, қоршаған ортаны және жануарлар дүниесін қорғау, жер қатынастары | B29: 986080.04 | C29: 1041493.9 | D29: 1309579.2 | E29: 184787.8 | F29: 232857.26 | G29: 10. Сельское, водное, лесное, рыбное хозяйство, особо охраняемые природные территории, охрана окружающей среды и животного мира, земельные отношения
A30: 11. Өнеркәсіп, сәулет, қала құрылысы және құрылыс қызметі | B30: 106051.45 | C30: 222978.62 | D30: 113850.65 | E30: 5823.8248 | F30: 7135.876 | G30: 11. Промышленность, архитектурная, градостроительная и строительная деятельность
... A46: Сыртқы | B46: -410730.11 | C46: 292070.8 | D46: 522904.09 | E46: -41383.205 | F46: -51794.771 | G46: Внешнее
A47: Түсімдер | B47: 251872.16 | C47: 1447223.5 | D47: 2231117.1 | E47: 65311.787 | F47: - | G47: Поступление
A48: Өтеу | B48: 662602.27 | C48: 1155152.7 | D48: 1708213 | E48: 106694.99 | F48: 51794.771 | G48: Погашение

Sheet табл 4
A1: 4-кесте | G1: Таблица 4
A3: МЕМЛЕКЕТТІК БЮДЖЕТКЕ ТҮСІМДЕР/_x000D_ ПОСТУПЛЕНИЯ В ГОСУДАРСТВЕННЫЙ БЮДЖЕТ
A5: (млн.теңге) | G5: (млн.тенге)
A7: Санаты/ Категория | B7: Сыныбы/ Класс | C7: Сыныпшасы/ Подкласс | D7: Ерешелігі/ Специфика | E7: Атауы | F7: 2026 ж. қаңтар-ақпан есеп/_x000D_ январь-февраль отчет 2026 г. | G7: Наименование
A8: 1 | B8: 2 | C8: 3 | D8: 4 | E8: 5 | F8: 6 | G8: 7
E9: ТҮСІМДЕР | F9: 5070880.7 | G9: ПОСТУПЛЕНИЯ
E10: оның ішінде: | G10: в том числе:
E11: КІРІСТЕР | F11: 5055996.9 | G11: ДОХОДЫ
A12: 1 | B12: L01 Класс дохода | C12: L01 Подкласс дохода | D12: L01 Специфика дохода | E12: Салықтық түсімдер | F12: 4442281.2 | G12: Налоговые поступления
A13: L01 Категория дохода | B13: 01 | C13: L01 Подкласс дохода | D13: L01 Специфика дохода | E13: Табыс салығы | F13: 1544716.8 | G13: Подоходный налог
A14: L01 Категория дохода | B14: L01 Класс дохода | C14: 1 | D14: L01 Специфика дохода | E14: Корпоративтік табыс салығы | F14: 997978.36 | G14: Корпоративный подоходный налог
A15: 1 | B15: 01 | C15: 1 | D15: 10 | E15: Мұнай секторы ұйымдарынан түсетін түсімдерді қоспағанда, ірі кәсіпкерлік субъектілерінен – заңды тұлғалардан алынатын корпоративтік табыс салығы | F15: 814528.08 | G15: Корпоративный подоходный налог с юридических лиц – субъектов крупного предпринимательства, за исключением поступлений от организаций нефтяного сектора
D16: 11 | E16: Ірі кәсіпкерлік субъектілерінен және мұнай секторы ұйымдарынан түсетін түсімдерді қоспағанда, заңды тұлғалардан алынатын корпоративтік табыс салығы | F16: 183450.29 | G16: Корпоративный подоходный налог с юридических лиц, за исключением поступлений от субъектов крупного предпринимательства и организаций нефтяного сектора
A17: L01 Категория дохода | B17: L01 Класс дохода | C17: 2 | D17: L01 Специфика дохода | E17: Жеке табыс салығы | F17: 546738.39 | G17: Индивидуальный подоходный налог
C18: 2 | D18: 01 | E18: Төлем көзінен салық салынатын табыстардан ұсталатын жеке табыс салығы | F18: 360359.77 | G18: Индивидуальный подоходный налог с доходов, облагаемых у источника выплаты
D19: 02 | E19: Төлем көзінен салық салынбайтын табыстардан ұсталатын жеке табыс салығы | F19: 182675.49 | G19: Индивидуальный подоходный налог с доходов, не облагаемых у источника выплаты
D20: 05 | E20: Төлем көзінен салық салынбайтын шетелдік азаматтар табыстарынан ұсталатын жеке табыс салығы | F20: 3703.142 | G20: Индивидуальный подоходный налог с доходов иностранных граждан, не облагаемых у источника выплаты
A21: L01 Категория дохода | B21: 03 | C21: L01 Подкласс дохода | D21: L01 Специфика дохода | E21: Әлеуметтiк салық | F21: 363934.9 | G21: Социальный налог
A22: L01 Категория дохода | B22: L01 Класс дохода | C22: 1 | D22: L01 Специфика дохода | E22: Әлеуметтік салық | F22: 363934.9 | G22: Социальный налог
B23: 03 | C23: 1 | D23: 01 | E23: Әлеуметтік салық | F23: 363934.9 | G23: Социальный налог
A24: L01 Категория дохода | B24: 04 | C24: L01 Подкласс дохода | D24: L01 Специфика дохода | E24: Меншiкке салынатын салықтар | F24: 139556.26 | G24: Hалоги на собственность
A25: L01 Категория дохода | B25: L01 Класс дохода | C25: 1 | D25: L01 Специфика дохода | E25: Мүлiкке салынатын салықтар | F25: 134519.21 | G25: Налоги на имущество
B26: 04 | C26: 1 | D26: 01 | E26: Заңды тұлғалардың және жеке кәсіпкерлердің мүлкіне салынатын салық | F26: 133931.35 | G26: Налог на имущество юридических лиц и индивидуальных предпринимателей
D27: 02 | E27: Жеке тұлғалардың мүлкiне салынатын салық | F27: 587.85449 | G27: Hалог на имущество физических лиц
A28: L01 Категория дохода | B28: L01 Класс дохода | C28: 3 | D28: L01 Специфика дохода | E28: Жер салығы | F28: 1667.6153 | G28: Земельный налог
C29: 3 | D29: 02 | E29: Жер салығы | F29: 1667.6153 | G29: Земельный налог
A30: L01 Категория дохода | B30: L01 Класс дохода | C30: 4 | D30: L01 Специфика дохода | E30: Көлiк құралдарына салынатын салық | F30: 2517.2629 | G30: Налог на транспортные средства
C31: 4 | D31: 01 | E31: Заңды тұлғалардан көлік құралы салығы | F31: 249.0277 | G31: Hалог на транспортные средства с юридических лиц
D32: 02 | E32: Жеке тұлғалардан көлік құралы салығы | F32: 2268.2352 | G32: Hалог на транспортные средства с физических лиц
A33: L01 Категория дохода | B33: L01 Класс дохода | C33: 5 | D33: L01 Специфика дохода | E33: Бірыңғай жер салығы | F33: 852.17205 | G33: Единый земельный налог
C34: 5 | D34: 01 | E34: Бірыңғай жер салығы | F34: 852.17205 | G34: Единый земельный налог
A35: L01 Категория дохода | B35: 05 | C35: L01 Подкласс дохода | D35: L01 Специфика дохода | E35: Тауарларға, жұмыстарға және көрсетілетін қызметтерге салынатын iшкi салықтар | F35: 2086540.2 | G35: Внутренние налоги на товары, работы и услуги
A36: L01 Категория дохода | B36: L01 Класс дохода | C36: 1 | D36: L01 Специфика дохода | E36: Қосылған құн салығы | F36: 1534499.2 | G36: Налог на добавленную стоимость
B37: 05 | C37: 1 | D37: 01 | E37: Қазақстан Республикасының аумағында өндiрiлген тауарларға, орындалған жұмыстарға және көрсетілген қызметтерге салынатынқосылған құн салығы | F37: 934340.34 | G37: Hалог на добавленную стоимость на произведенные товары, выполненные работы и оказанные услуги на территории Республики Казахстан
D38: 02 | E38: Ресей Федерациясы және Беларусь Республикасының аумағынан импортталатын тауарларға салынатын қосылған құн салығынан басқа, Қазақстан Республикасының аумағына импортталатын тауарларға салынатын қосылған құн салығы | F38: 327967.51 | G38: Hалог на добавленную стоимость на товары, импортируемые на территорию Республики Казахстан, кроме налога на добавленнуюстоимость на товары, импортируемые с территории Российской Федерации и Республики Беларусь
D39: 04 | E39: Резидент емес үшін қосылған құн салығы | F39: 66820.044 | G39: Налог на добавленную стоимость за нерезидента
D40: 14 | E40: Салық төлеушінің бұрын бюджеттен қайтарылған және салықтықтексеру жүргізу барысында қайтарылуы расталмаған қосылған құн салығының асып кеткен сомасын аударуы (қайтаруы), өсімпұл сомасын аударуы | F40: 348.08616 | G40: Перечисление (возврат) налогоплательщиком суммы превышения налога на добавленную стоимость, ранее возвращенной из бюджета и не подтвержденной к возврату при проведении налоговой проверки, перечисление суммы пени
D41: 15 | E41: Еуразиялық экономикалық одаққа мүше мемлекеттер аумағынан импортталған тауарларға қосылған құн салығы | F41: 186556.46 | G41: Налог на добавленную стоимость на товары, импортированные стерритории государств-членов Евразийского экономического союза
D42: 16 | E42: Тауарлармен электрондық сауданы жүзеге асыру, жеке тұлғаларға электрондық нысанда қызметтер көрсету кезінде шетелдік компаниялардан түсетін қосылған құн салығы | F42: 18466.768 | G42: Налог на добавленную стоимость с иностранных интернет компаний при осуществлении электронной торговли товарами, оказании услуг в электронной форме физическим лицам
A43: L01 Категория дохода | B43: L01 Класс дохода | C43: 2 | D43: L01 Специфика дохода | E43: Акциздер | F43: 165944.63 | G43: Акцизы
...

Sheet табл 5
B2: Кесте 5 | D2: Таблица 5
B3: ШЫҒЫСТАРДЫҢ ВЕДОМСТВОЛЫҚ | D3: ИСПОЛНЕНИЕ ГОСУДАРСТВЕННОГО БЮДЖЕТА
B4: СЫНЫПТАМАСЫ БОЙЫНША | D4: ПО ВЕДОМСТВЕННОЙ
B5: МЕМЛЕКЕТТІК БЮДЖЕТТІҢ АТҚАРАЛУЫ | D5: КЛАССИФИКАЦИИ РАСХОДОВ
B6: (млн. теңге) | D6: (млн. тенге)
B8: Бағдарламалард_x000D_ ың_x000D_ əкімшісі/_x000D_ Администратор_x000D_ программ | C8: Атауы | D8: 2026 ж. қаңтар-ақпан есеп/_x000D_ январь-февраль 2026 г. | E8: Наименование
B9: 1 | C9: 2 | D9: 3 | E9: 4
C10: БАРЛЫҒЫ | D10: 4695528.6 | E10: ВСЕГО
B11: 101 | C11: Қазақстан Республикасы Президентінің Әкімшілігі | D11: 2572.8359 | E11: Администрация Президента Республики Казахстан
B12: 106 | C12: Адам құқықтары жөніндегі ұлттық орталық | D12: 275.72606 | E12: Национальный центр по правам человека
B13: 107 | C13: Қазақстан Республикасы Жоғары Сот Кеңесінің Аппараты | D13: 333.9979 | E13: Аппарат Высшего Судебного Совета Республики Казахстан
B14: 109 | C14: Қазақстан Республикасы Үкіметінің Аппараты | D14: 1270.0248 | E14: Аппарат Правительства Республики Казахстан
B15: 110 | C15: Облыс мәслихатының аппараты | D15: 503.27799 | E15: Аппарат маслихата области
B16: 111 | C16: Республикалық маңызы бар қала, астана мәслихатының аппараты | D16: 108.63485 | E16: Аппарат маслихата города республиканского значения, столицы
B17: 112 | C17: Аудан (облыстық маңызы бар қала) мәслихатының аппараты | D17: 2419.9522 | E17: Аппарат маслихата района (города областного значения)
B18: 120 | C18: Облыс әкімінің аппараты | D18: 7434.7206 | E18: Аппарат акима области
B19: 121 | C19: Республикалық маңызы бар қала, астана әкімінің аппараты | D19: 1617.2878 | E19: Аппарат акима города республиканского значения, столицы
B20: 122 | C20: Аудан (облыстық маңызы бар қала) әкімінің аппараты | D20: 15287.958 | E20: Аппарат акима района (города областного значения)
B21: 123 | C21: Қаладағы аудан әкімінің аппараты | D21: 39199.853 | E21: Аппарат акима района в городе
B22: 124 | C22: Аудандық маңызы бар қала, ауыл, кент, ауылдық округ әкімінің аппараты | D22: 39075.012 | E22: Аппарат акима города районного значения, села, поселка, сельского округа
... B220: 821 | C220: Ауданның (облыстық маңызы бар қаланың) қоғамдық даму бөлімі | D220: 161.82292 | E220: Отдел общественного развития района (города областного значения)

Sheet табл 6
A1: 6-кесте | D1: Таблица 6
A2: ШЫҒЫНДАРДЫҢ ЭКОНОМИКАЛЫҚ ЖІКТЕМЕСІ | D2: ИСПОЛНЕНИЕ ГОСУДАРСТВЕННОГО БЮДЖЕТА ПО
A3: БОЙЫНША МЕМЛЕКЕТТІК БЮДЖЕТТІК ОРЫНДАЛУЫ | D3: ЭКОНОМИЧЕСКОЙ КЛАССИФИКАЦИИ РАСХОДОВ
A4: (млн.теңге) | D4: (млн.тенге)
A5: Cанаты/_x000D_ Категория | B5: Iшкi сыныбы/_x000D_ Подкласс | C5: Атауы | D5: 2026 ж. қаңтар-ақпан/январь-февраль отчет 2026 г. | E5: Наименование
A7: 1 | B7: 2 | C7: 3 | D7: 4 | E7: 5
C8: БАРЛЫҒЫ | D8: 4695528.6 | E8: ВСЕГО
A9: 1 | C9: Ағымдағы шығындар | D9: 4338634.7 | E9: Текущие затраты
A10: 1 | B10: 110 | C10: Жалақы | D10: 696054.96 | E10: Заработная плата
B11: 120 | C11: Жұмыс берушілердің жарналары | D11: 71168.859 | E11: Взносы работодателей
B12: 130 | C12: Қазақстан Республикасының заңнамалық актілеріне сәйкес азаматтардың жекелеген санаттарына жалақы төлеу және жарналар аудару | D12: 23873.583 | E12: Выплата заработной платы отдельным категориям граждан и отчисления взносов в соответствии с законодательными актами Республики Казахстан
B13: 140 | C13: Қорлар сатып алу | D13: 33756.994 | E13: Приобретение запасов
B14: 150 | C14: Қызметтер мен жұмыстарды сатып алу | D14: 558728.02 | E14: Приобретение услуг и работ
B15: 160 | C15: Басқа да ағымдағы шығындар | D15: 406000.8 | E15: Другие текущие затраты
B16: 210 | C16: Ішкі қарыздар бойынша сыйақы төлемдері | D16: 580992.89 | E16: Выплаты вознаграждений по внутренним займам
B17: 220 | C17: Сыртқы заемдар бойынша сыйақылар төлеу | D17: 36851.342 | E17: Выплаты вознаграждений по внешним займам
B18: 310 | C18: Бюджеттік субсидиялар | D18: 332599.08 | E18: Бюджетные субсидии
B19: 320 | C19: Жеке тұлғаларға берілетін трансферттер | D19: 1252915.4 | E19: Трансферты физическим лицам
B20: 340 | C20: Шетелге берiлетiн ағымдағы трансферттер | D20: 18.004743 | E20: Текущие трансферты за границу
B21: 360 | C21: Нысаналы жарна | D21: 345674.81 | E21: Целевой взнос
A22: 2 | C22: Күрделі шығындар | D22: 269681.08 | E22: Капитальные затраты
A23: 2 | B23: 410 | C23: Негiзгi құралдарды, материалдық емес және биологиялық активтерді сатып алу | D23: 70818.313 | E23: Приобретение основных средств, нематериальных и биологических активов
B24: 420 | C24: Негізгі қаражатты күрделі жөндеу | D24: 22316.273 | E24: Капитальный ремонт основных средств
B25: 430 | C25: Дамуға бағытталған күрделі шығындар | D25: 176546.5 | E25: Капитальные затраты, направленные на развитие
A26: 3 | C26: Бюджеттік кредиттер | D26: 3400 | E26: Бюджетные кредиты
A27: 3 | B27: 510 | C27: Ішкі бюджеттік кредиттер | D27: 3400 | E27: Внутренние бюджетные кредиты
A28: 4 | C28: Қаржы активтерін сатып алу | D28: 49932.035 | E28: Приобретение финансовых активов
A29: 4 | B29: 610 | C29: Қаржы активтерін сатып алу | D29: 49836.637 | E29: Приобретение финансовых активов
B30: 620 | C30: Елден тысқары жерлерден қаржы активтерін сатып алу | D30: 95.397215 | E30: Приобретение финансовых активов за пределами страны
A31: 6 | C31: Мемлекеттік-жекешелік әріптестік жобалар бойынша мемлекеттік міндеттемелерді орындау | D31: 33880.751 | E31: Выполнение государственных обязательств по проектам государственно-частного партнерства
A32: 6 | B32: 810 | C32: Мемлекеттік концессиялық міндеттемелерді орындау | D32: 33880.751 | E32: Выполнение государственных концессионных обязательств

Sheet табл 7
A1: 7-кесте | E1: Таблица 7
A2: РЕСПУБЛИКАЛЫҚ БЮДЖЕТТІҢ АТҚАРЫЛУЫ | E2: ИСПОЛНЕНИЕ РЕСПУБЛИКАНСКОГО БЮДЖЕТА
A3: (млн.теңге) | E3: (млн. тенге)
A5: Атауы | B5: 2023 ж. есеп/ 2023 г. отчет | C5: 2024 ж. есеп/ 2024 г. отчет | D5: 2025 ж. есеп/ 2025 г. отчет | F5: 2026 ж. қантар-ақпан есеп/январь-феврал отчет 2026 г. | G5: Наименование
D6: жылдық/ годовой | E6: қантар-ақпан/январь-феврал
A7: 1 | B7: 2 | C7: 3 | D7: 4 | E7: 5 | F7: 6 | G7: 7
A8: I. КІРІСТЕР | B8: 19037979 | C8: 19624012 | D8: 21090148 | E8: 3634592.6 | F8: 3646026.1 | G8: I. ДОХОДЫ
A9: Салықтық түсімдер_x000D_ оның iшiнде: | B9: 12912428 | C9: 12307810 | D9: 14463081 | E9: 2301508.5 | F9: 2979003.4 | G9: Налоговые поступления,_x000D_ в том числе:
A10: корпоративтік табыс салығы | B10: 3889594.5 | C10: 3653190.8 | D10: 4532987.5 | E10: 696571.35 | F10: 814528.08 | G10: корпоративный подоходный налог
A11: қосылған құн салығы | B11: 5674110.6 | C11: 5179378.1 | D11: 6111842.3 | E11: 1105855.5 | F11: 1534499.2 | G11: налог на добавленную стоимость
A12: акциздер | B12: 161890.43 | C12: 125189.66 | D12: 117407.4 | E12: 18199.007 | F12: 12138.185 | G12: акцизы
A13: Салықтық емес түсімдер | B13: 1617610.1 | C13: 1201438.2 | D13: 823130.62 | E13: 182604.09 | F13: 36144.023 | G13: Неналоговые поступления
A14: Негізгі капиталды сатудан түсетін түсімдер | B14: 735.69631 | C14: 6170.4309 | D14: 12039.586 | E14: 558.11164 | F14: 257.17461 | G14: Поступления от продажи основного капитала
A15: Арнаулы түсімдер | B15: 4507205 | C15: 6108593.6 | D15: 5791896.9 | E15: 1149921.9 | F15: 608.16748 | G15: Специальные поступления
A16: Трансферттердің түсімдері | F16: 630013.31 | G16: Поступления трансфертов
A17: II. ШЫҒЫНДАР | B17: 21547819 | C17: 23106552 | D17: 24958709 | E17: 3638727.6 | F17: 3751106.4 | G17: II. ЗАТРАТЫ
A18: 1. Жалпы сипаттағы мемлекеттiк қызметтер | B18: 1137687.2 | C18: 1293447.3 | D18: 1334753.4 | E18: 209111.92 | F18: 152984.97 | G18: 1. Государственные услуги общего характера
A19: 2. Қорғаныс | B19: 1100070.9 | C19: 1038491.2 | D19: 1149535.1 | E19: 80846.186 | F19: 113974.93 | G19: 2. Оборона
A20: 3. Қоғамдық тәртіп, қауіпсіздік, құқықтық, сот, қылмыстық-атқару қызметі | B20: 1275903.8 | C20: 1287986.9 | D20: 1366266.2 | E20: 158301.8 | F20: 183079.87 | G20: 3. Общественный порядок, безопасность, правовая, судебная, уголовно-исполнительная деятельность
A21: 4. Бiлiм беру | B21: 1284728.3 | C21: 1687045.7 | D21: 1459703.2 | E21: 200966.48 | F21: 82306.333 | G21: 4. Образование
A22: 5. Денсаулық сақтау | B22: 2214672.2 | C22: 2234191.1 | D22: 2427736.7 | E22: 363392.64 | F22: 368596.01 | G22: 5. Здравоохранение
A23: 6. Әлеуметтiк көмек және әлеуметтiк қамсыздандыру | B23: 4660172.8 | C23: 5330622.6 | D23: 5935107 | E23: 1014764.5 | F23: 1148432.3 | G23: 6. Социальная помощь и социальное обеспечение
A24: 7. Тұрғын үй-коммуналдық шаруашылық | B24: 593617.31 | C24: 443664.38 | D24: 259922.86 | E24: 6868.613 | F24: 14367.408 | G24: 7. Жилищно-коммунальное хозяйство
A25: 8. Мәдениет, спорт, туризм және ақпараттық кеңістiк | B25: 259425.87 | C25: 278898.26 | D25: 290983.39 | E25: 51080.958 | F25: 35433.353 | G25: 8. Культура, спорт, туризм и информационное пространство
A26: 9. Отын-энергетика кешенi және жер қойнауын пайдалану | B26: 189027.58 | C26: 158442.55 | D26: 112560.1 | E26: 8403.5715 | F26: 14716.763 | G26: 9. Топливно-энергетический комплекс и недропользование
A27: 10. Ауыл, су, орман, балық шаруашылығы, ерекше қорғалатын табиғи аумақтар, қоршаған ортаны және жануарлар дүниесін қорғау, жер қатынастары | B27: 383214.73 | C27: 384242.74 | D27: 612199.22 | E27: 44939.002 | F27: 39086.262 | G27: 10. Сельское, водное, лесное, рыбное хозяйство, особо охраняемые природные территории, охрана окружающей среды и животного мира, земельные отношения
A28: 11. Өнеркәсіп, сәулет, қала құрылысы және құрылыс қызметі | B28: 58013.972 | C28: 20458.387 | D28: 17293.935 | E28: 162.14924 | F28: 531.06884 | G28: 11. Промышленность, архитектурная, градостроительная и строительная деятельность
... A44: Сыртқы | B44: -408849.23 | C44: 292939.56 | D44: 522904.09 | E44: -41383.205 | F44: -51794.771 | G44: Внешнее
A45: Түсімдер | B45: 251872.16 | C45: 1447223.5 | D45: 2231117.1 | E45: 65311.787 | F45: - | G45: Поступление
A46: Өтеу | B46: 660721.39 | C46: 1154283.9 | D46: 1708213 | E46: 106694.99 | F46: 51794.771 | G46: Погашение

Sheet табл 8 (дох)
B2: 8-кесте | H2: Таблица 8
F3: РЕСПУБЛИКАЛЫҚ БЮДЖЕТТІҢ АТҚАРЫЛУЫ/ ИСПОЛНЕНИЕ РЕСПУБЛИКАНСКОГО БЮДЖЕТА
B4: (млн.теңге) | H4: (млн.тенге)
B5: Санаты/ Категория | C5: Сыныбы/ Класс | D5: Сыныпшасы/ Подкласс | E5: Ерешелігі/ Специфика | F5: Атауы | G5: 2026 ж. қаңтар-ақпан есеп/_x000D_ январь-февраль отчет 2026 г. | H5: Наименование
B6: 1 | C6: 2 | D6: 3 | E6: 4 | F6: 5 | G6: 6 | H6: 7
F7: ТҮСІМДЕР | G7: 3660364.4 | H7: ПОСТУПЛЕНИЯ
F8: оның ішінде: | H8: в том числе:
F9: КІРІСТЕР | G9: 3646026.1 | H9: ДОХОДЫ
B10: 1 | F10: Салықтық түсімдер | G10: 2979003.4 | H10: Налоговые поступления
C11: 01 | F11: Табыс салығы | G11: 814528.08 | H11: Подоходный налог
D12: 1 | F12: Корпоративтік табыс салығы | G12: 814528.08 | H12: Корпоративный подоходный налог
B13: 1 | C13: 01 | D13: 1 | E13: 10 | F13: Мұнай секторы ұйымдарынан түсетін түсімдерді қоспағанда, ірі кәсіпкерлік субъектілерінен – заңды тұлғалардан алынатын корпоративтік табыс салығы | G13: 814528.08 | H13: Корпоративный подоходный налог с юридических лиц – субъектов крупного предпринимательства, за исключением поступлений от организаций нефтяного сектора
C14: 05 | F14: Тауарларға, жұмыстарға және көрсетілетін қызметтерге салынатын iшкi салықтар | G14: 1890602.8 | H14: Внутренние налоги на товары, работы и услуги
D15: 1 | F15: Қосылған құн салығы | G15: 1534499.2 | H15: Налог на добавленную стоимость
C16: 05 | D16: 1 | E16: 01 | F16: Қазақстан Республикасының аумағында өндiрiлген тауарларға, орындалған жұмыстарға және көрсетілген қызметтерге салынатынқосылған құн салығы | G16: 934340.34 | H16: Hалог на добавленную стоимость на произведенные товары, выполненные работы и оказанные услуги на территории Республики Казахстан
E17: 02 | F17: Ресей Федерациясы және Беларусь Республикасының аумағынан импортталатын тауарларға салынатын қосылған құн салығынан басқа, Қазақстан Республикасының аумағына импортталатын тауарларға салынатын қосылған құн салығы | G17: 327967.51 | H17: Hалог на добавленную стоимость на товары, импортируемые на территорию Республики Казахстан, кроме налога на добавленнуюстоимость на товары, импортируемые с территории Российской Федерации и Республики Беларусь
E18: 04 | F18: Резидент емес үшін қосылған құн салығы | G18: 66820.044 | H18: Налог на добавленную стоимость за нерезидента
E19: 14 | F19: Салық төлеушінің бұрын бюджеттен қайтарылған және салықтықтексеру жүргізу барысында қайтарылуы расталмаған қосылған құн салығының асып кеткен сомасын аударуы (қайтаруы), өсімпұл сомасын аударуы | G19: 348.08616 | H19: Перечисление (возврат) налогоплательщиком суммы превышения налога на добавленную стоимость, ранее возвращенной из бюджета и не подтвержденной к возврату при проведении налоговой проверки, перечисление суммы пени
E20: 15 | F20: Еуразиялық экономикалық одаққа мүше мемлекеттер аумағынан импортталған тауарларға қосылған құн салығы | G20: 186556.46 | H20: Налог на добавленную стоимость на товары, импортированные стерритории государств-членов Евразийского экономического союза
E21: 16 | F21: Тауарлармен электрондық сауданы жүзеге асыру, жеке тұлғаларға электрондық нысанда қызметтер көрсету кезінде шетелдік компаниялардан түсетін қосылған құн салығы | G21: 18466.768 | H21: Налог на добавленную стоимость с иностранных интернет компаний при осуществлении электронной торговли товарами, оказании услуг в электронной форме физическим лицам
D22: 2 | F22: Акциздер | G22: 12138.185 | H22: Акцизы
D23: 2 | E23: 76 | F23: Қазақстан Республикасының аумағына Еуразиялық экономикалық одағына мүше мемлекеттердің аумағынан әкелінетін темекі өнімдері | G23: 769.32945 | H23: Табачные изделия, ввозимые на территорию Республики Казахстан с территории государств-членов Евразийского экономического союза
E24: 77 | F24: Қазақстан Республикасының аумағына Еуразиялық экономикалық одағына мүше мемлекеттердің аумағынан әкелінетін спирттiң және (немесе) шарап материалының, алкоголь өнімдерінің барлық түрлерi | G24: 1941.863 | H24: Все виды спирта и (или) виноматериала, алкогольной продукции, ввозимых на территорию Республики Казахстан с территории государств-членов Евразийского экономического союза
E25: 78 | F25: Қазақстан Республикасының аумағына Еуразиялық экономикалық одағына мүше мемлекеттердің аумағынан әкелінетін акцизделетін өнімнің өзге түрлері | G25: 33.988414 | H25: Прочие виды подакцизной продукции, ввозимой на территорию Республики Казахстан с территории государств-членов Евразийского экономического союза
E26: 79 | F26: Қазақстан Республикасы аумағына Еуразиялық экономикалық одағына мүше мемлекеттердің аумағынан әкелінетін бензин (авиациялықты қоспағанда) және дизель отыны | G26: 3105.7734 | H26: Бензин (за исключением авиационного) и дизельное топливо, ввозимых на территорию Республики Казахстан с территории государств-членов Евразийского экономического союза
E27: 80 | F27: Еуразиялық экономикалық одағына мүше болып табылмайтын мемлекеттердің аумағынан әкелінетін, Қазақстан Республикасының аумағына импортталатын спирттің және (немесе) шарап материалының, алкоголь өнімдерінің барлық түрлері | G27: 2380.5468 | H27: Все виды спирта и (или) виноматериала, алкогольной продукции, импортируемых на территорию Республики Казахстан с территории государств, не являющихся членами Евразийского экономического союза
E28: 81 | F28: Еуразиялық экономикалық одағына мүше болып табылмайтын мемлекеттердің аумағынан әкелінетін, Қазақстан Республикасының аумағына импортталатын темекі өнімдері | G28: 3127.5135 | H28: Табачные изделия, импортируемые на территорию Республики Казахстан с территории государств, не являющихся членами Евразийского экономического союза
E29: 82 | F29: Еуразиялық экономикалық одағына мүше болып табылмайтын мемлекеттердің аумағынан әкелінетін, Қазақстан Республикасының аумағына импортталатын акцизделетін өнімдердің өзге түрлері | G29: 762.74809 | H29: Прочие виды подакцизных продукций, импортируемые на территорию Республики Казахстан с территории государств, не являющихся членами Евразийского экономического союза
E30: 83 | F30: Еуразиялық экономикалық одағына мүше болып табылмайтын мемлекеттер аумағынан әкелінетін, Қазақстан Республикасының аумағына импортталатын бензин (авиациялықты қоспағанда) және дизель отыны | G30: 16.422732 | H30: Бензин (за исключением авиационного) и дизельное топливо, импортируемых на территорию Республики Казахстан с территориигосударств, не являющихся членами Евразийского экономического союза
D31: 3 | F31: Табиғи және басқа да ресурстарды пайдаланғаны үшiн түсетiн түсiмдер | G31: 343944.98 | H31: Поступления за использование природных и других ресурсов
D32: 3 | E32: 01 | F32: Қалааралық және (немесе) халықаралық телефон байланысын, сондай-ақ ұялы байланысты бергені үшін төлемақы | G32: 3.0573348 | H32: Плата за предоставление междугородной и (или) международнойтелефонной связи, а также сотовой связи
E33: 02 | F33: Мұнай секторы ұйымдарынан түсетін түсімдерді қоспағанда, үстеме пайдаға салынатын салық | G33: 164.9201 | H33: Налог на сверхприбыль, за исключением поступлений от организаций нефтяного сектора
E34: 05 | F34: Мұнай секторы ұйымдарынан түсетін түсімдерді қоспағанда, бонустар | G34: 239.67501 | H34: Бонусы, за исключением поступлений от организаций нефтяногосектора
E35: 06 | F35: Кең таралған пайдалы қазбаларды, жерасты суларын, емдік балшықтарды және мұнай секторы ұйымдарынан түсетін түсімдерді қоспағанда, пайдалы қазбаларды өндіру салығы | G35: 345410.75 | H35: Налог на добычу полезных ископаемых, за исключением общераспространенных полезных ископаемых, подземных вод, лечебных грязей и поступлений от организаций нефтяного сектора
E36: 07 | F36: Мұнай секторы ұйымдарынан түсетін түсімдерді қоспағанда, экспортқа рента салығы | G36: 324.16676 | H36: Рентный налог на экспорт, за исключением поступлений от организаций нефтяного сектора
E37: 08 | F37: Мұнай секторы ұйымдарынан түсетін түсімдерді қоспағанда, жасалған келісімшарттар бойынша өнімді бөлу жөніндегі Қазақстан Республикасының үлесі | G37: 0.001 | H37: Доля Республики Казахстан по разделу продукции по заключенным контрактам, за исключением поступлений от организаций нефтяного сектора
E38: 09 | F38: Радиожиілік спектрін пайдаланғаны үшін төлем | G38: -2197.5481 | H38: Плата за использование радиочастотного спектра
E39: 12 | F39: Мұнай секторы ұйымдарынан түсетін түсімдерді қоспағанда, өнімді бөлу туралы келісімшарт бойынша қызметті жүзеге асыратын жер қойнауын пайдаланушының қосымша төлемі және баламалы салық | G39: -0.044681 | H39: Дополнительный платеж недропользователя, осуществляющего деятельность по контракту о разделе продукции, и альтернативный налог, за исключением поступлений от организаций нефтяногосектора
D40: 4 | F40: Кәсiпкерлiк және кәсiби қызметтi жүргiзгенi үшiн алынатын алымдар | G40: 20.386601 | H40: Сборы за ведение предпринимательской и профессиональной деятельности
D41: 4 | E41: 28 | F41: Республикалық бюджетке төленетін тіркелгені үшін алым | G41: 16.110916 | H41: Регистрационный сбор, зачисляемый в республиканский бюджет
...

Sheet табл 8 (расх)
G2: (млн. тенге)
A3: (млн.теңге)
A5: Санаты/ Категория | B5: Сыныбы/ Класс | C5: Сыныпшасы/ Подкласс | D5: Ерешелігі/ Специфика | E5: Атауы | F5: 2026 қаңтар-ақпан есеп/_x000D_ январь-февраль отчет 2026г. | G5: Наименование
A6: 1 | B6: 2 | C6: 3 | D6: 4 | E6: 5 | F6: 6 | G6: 7
E7: ШЫҒЫСТАР | F7: 3767231 | G7: РАСХОДЫ
E8: оның ішінде: | G8: в том числе:
E9: II. ШЫҒЫНДАР | F9: 3751106.4 | G9: II. ЗАТРАТЫ
A10: 01 | E10: Жалпы сипаттағы мемлекеттiк қызметтер | F10: 152984.97 | G10: Государственные услуги общего характера
B11: 1 | E11: Мемлекеттiк басқарудың жалпы функцияларын орындайтын өкiлдi, атқарушы және басқа органдар | F11: 32037.208 | G11: Представительные, исполнительные и другие органы, выполняющие общие функции государственного управления
C12: 101 | E12: Қазақстан Республикасы Президентінің Әкімшілігі | F12: 2572.8359 | G12: Администрация Президента Республики Казахстан
A13: 01 | B13: 1 | C13: 101 | D13: 001 | E13: Мемлекет басшысының қызметін қамтамасыз ету | F13: 2572.8359 | G13: Обеспечение деятельности Главы государства
C14: 106 | E14: Адам құқықтары жөніндегі ұлттық орталық | F14: 275.72606 | G14: Национальный центр по правам человека
C15: 106 | D15: 001 | E15: Адамның және азаматтың құқықтары мен бостандықтарының сақталуын қадағалау жөніндегі көрсетілетін қызметтер | F15: 275.72606 | G15: Услуги по наблюдению за соблюдением прав и свобод человека и гражданина
C16: 107 | E16: Қазақстан Республикасы Жоғары Сот Кеңесінің Аппараты | F16: 224.84225 | G16: Аппарат Высшего Судебного Совета Республики Казахстан
C17: 107 | D17: 001 | E17: Қазақстан Республикасы Жоғары Сот Кеңесінің қызметін қамтамасыз ету жөніндегі көрсетілетін қызметтер | F17: 224.84225 | G17: Услуги по обеспечению деятельности Высшего Судебного СоветаРеспублики Казахстан
C18: 109 | E18: Қазақстан Республикасы Үкіметінің Аппараты | F18: 882.03769 | G18: Аппарат Правительства Республики Казахстан
C19: 109 | D19: 001 | E19: Қазақстан Республикасы Премьер-Министрінің қызметін қамтамасыз ету жөніндегі көрсетілетін қызметтер | F19: 882.03769 | G19: Услуги по обеспечению деятельности Премьер-Министра Республики Казахстан
C20: 626 | E20: Қазақстан Республикасының Стратегиялық жоспарлау және реформалар агенттігі | F20: 4413.2544 | G20: Агентство по стратегическому планированию и реформам Республики Казахстан
C21: 626 | D21: 001 | E21: Реформаларды қалыптастыруға және тиімді іске асыруға жәрдемдесу жөніндегі көрсетілетін қызметтер, стратегиялық жоспарлау, мемлекеттік статистикалық қызмет салаларында мемлекеттік саясатты жүзеге асыру, мемлекеттік басқару жүйесі мен квазиме | F21: 4413.2544 | G21: Услуги по содействию в формировании и эффективной реализации реформ, осуществление государственной политики в сферах стратегического планирования, государственной статистической деятельности, участие в совершенствовании системы государствен
C22: 637 | E22: Қазақстан Республикасы Конституциялық Сотының Аппараты | F22: 329.7195 | G22: Аппарат Конституционного Суда Республики Казахстан
C23: 637 | D23: 001 | E23: Республика аумағында Қазақстан Республикасы Конституциясының үстемдігін қамтамасыз ету | F23: 329.7195 | G23: Обеспечение верховенства Конституции Республики Казахстан на территории Республики
C24: 690 | E24: Қазақстан Республикасының Орталық сайлау комиссиясы | F24: 907.95355 | G24: Центральная избирательная комиссия Республики Казахстан
C25: 690 | D25: 001 | E25: Сайлау өткізуді ұйымдастыру | F25: 153.61053 | G25: Организация проведения выборов
D26: 002 | E26: Сайлау өткізу | F26: 525.51134 | G26: Проведение выборов
D27: 109 | E27: Қазақстан Республикасы Үкіметінің шұғыл шығындарға арналғанрезервінің есебінен ағымды іс-шаралар өткізу | F27: 228.83168 | G27: Проведение текущих мероприятий за счет резерва Правительства Республики Казахстан на неотложные затраты
C28: 693 | E28: Материалдық-техникалық қамтамасыз ету басқармасы | F28: 4370.4348 | G28: Управление материально-технического обеспечения
C29: 693 | D29: 001 | E29: Қазақстан Республикасы Парламентінің қызметін қамтамасыз ету жөніндегі көрсетілетін қызметтер | F29: 4370.4348 | G29: Услуги по обеспечению деятельности Парламента Республики Казахстан
C30: 694 | E30: Қазақстан Республикасы Президентiнiң Іс Басқармасы | F30: 18060.404 | G30: Управление Делами Президента Республики Казахстан
C31: 694 | D31: 001 | E31: Қазақстан Республикасы Президенті Іс Басқармасының мемлекеттік функциялары мен өкілеттіктерін жүзеге асыруды қамтамасызету жөніндегі көрсетілетін қызметтер | F31: 13580.516 | G31: Услуги по обеспечению осуществления государственных функцийи полномочий Управления Делами Президента Республики Казахстан
D32: 009 | E32: Қазақстан Республикасы Президенттік орталығының қызметін қамтамасыз ету жөніндегі көрсетілетін қызметтер | F32: 206.07933 | G32: Услуги по обеспечению деятельности Президентского центра Республики Казахстан
D33: 167 | E33: Қазақстан Республикасы Президентінің бастамаларына арналғанрезервінің есебінен бюджеттік инвестициялық жобаларды іске асыру | F33: 4273.8093 | G33: Реализация бюджетных инвестиционных проектов за счет резерва на инициативы Президента Республики Казахстан
B34: 2 | E34: Қаржылық қызмет | F34: 853.19133 | G34: Финансовая деятельность
C35: 217 | E35: Қазақстан Республикасының Қаржы министрлігі | F35: 15.334379 | G35: Министерство финансов Республики Казахстан
B36: 2 | C36: 217 | D36: 002 | E36: Халықаралық қаржы ұйымдары қаржыландыратын инвестициялық жобалардың аудитiн жүзеге асыру | F36: 0 | G36: Осуществление аудита инвестиционных проектов, финансируемыхмеждународными финансовыми организациями
D37: 094 | E37: Мемлекеттік активтерді басқару | F37: 15.334379 | G37: Управление государственными активами
C38: 406 | E38: Қазақстан Республикасының Жоғары аудиторлық палатасы | F38: 837.85696 | G38: Высшая аудиторская палата Республики Казахстан
C39: 406 | D39: 001 | E39: Қазақстан Республикасы Жоғары аудиторлық палатасының қызметін қамтамасыз ету жөніндегі көрсетілетін қызметтер | F39: 837.85696 | G39: Услуги по обеспечению деятельности Высшей аудиторской палаты Республики Казахстан
B40: 3 | E40: Сыртқы саяси қызмет | F40: 18798.139 | G40: Внешнеполитическая деятельность
C41: 204 | E41: Қазақстан Республикасының Сыртқы iстер министрлiгi | F41: 18798.139 | G41: Министерство иностранных дел Республики Казахстан
B42: 3 | C42: 204 | D42: 001 | E42: Сыртқы саяси қызметті үйлестіру жөніндегі көрсетілетін қызметтер | F42: 17656.836 | G42: Услуги по координации внешнеполитической деятельности
...

Sheet табл 9
B2: Кесте 9 | D2: Таблица 9
B3: ШЫҒЫСТАРДЫҢ ВЕДОМСТВОЛЫҚ | D3: ИСПОЛНЕНИЕ РЕСПУБЛИКАНСКОГО БЮДЖЕТА
B4: СЫНЫПТАМАСЫ БОЙЫНША | D4: ПО ВЕДОМСТВЕННОЙ
B5: РЕСПУБЛИКАЛЫҚ БЮДЖЕТТІҢ АТҚАРАЛУЫ | D5: КЛАССИФИКАЦИИ РАСХОДОВ
B6: (млн. теңге) | D6: (млн. тенге)
B8: Бағдарламалард_x000D_ ың_x000D_ əкімшісі/_x000D_ Администратор_x000D_ программ | C8: Атауы | D8: 2026 ж. қаңтар-ақпан есеп/_x000D_ январь-февраль 2026 г. | E8: Наименование
B9: 1 | C9: 2 | D9: 3 | E9: 4
C10: БАРЛЫҒЫ | D10: 3767231 | E10: ВСЕГО
B11: 101 | C11: Қазақстан Республикасы Президентінің Әкімшілігі | D11: 2572.8359 | E11: Администрация Президента Республики Казахстан
B12: 106 | C12: Адам құқықтары жөніндегі ұлттық орталық | D12: 275.72606 | E12: Национальный центр по правам человека
B13: 107 | C13: Қазақстан Республикасы Жоғары Сот Кеңесінің Аппараты | D13: 333.9979 | E13: Аппарат Высшего Судебного Совета Республики Казахстан
B14: 109 | C14: Қазақстан Республикасы Үкіметінің Аппараты | D14: 1270.0248 | E14: Аппарат Правительства Республики Казахстан
B15: 201 | C15: Қазақстан Республикасының Ішкі істер министрлігі | D15: 94562.188 | E15: Министерство внутренних дел Республики Казахстан
B16: 202 | C16: Қазақстан Республикасының Төтенше жағдайлар министрлiгi | D16: 20426.595 | E16: Министерство по чрезвычайным ситуациям Республики Казахстан
B17: 204 | C17: Қазақстан Республикасының Сыртқы iстер министрлiгi | D17: 18970.639 | E17: Министерство иностранных дел Республики Казахстан
B18: 207 | C18: Қазақстан Республикасының Экология және табиғи ресурстар министрлігі | D18: 17007.014 | E18: Министерство экологии и природных ресурсов Республики Казахстан
B19: 208 | C19: Қазақстан Республикасының Қорғаныс министрлігі | D19: 95480.584 | E19: Министерство обороны Республики Казахстан
B20: 211 | C20: Қазақстан Республикасының Сауда және интеграция министрлігі | D20: 1779.642 | E20: Министерство торговли и интеграции Республики Казахстан
B21: 212 | C21: Қазақстан Республикасының Ауыл шаруашылығы министрлiгi | D21: 37257.227 | E21: Министерство сельского хозяйства Республики Казахстан
B22: 213 | C22: Қазақстан Республикасының Еңбек және халықты әлеуметтiк қорғау министрлiгi | D22: 1148432.3 | E22: Министерство труда и социальной защиты населения РеспубликиКазахстан
... B49: 694 | C49: Қазақстан Республикасы Президентiнiң Іс Басқармасы | D49: 42343.838 | E49: Управление Делами Президента Республики Казахстан

Sheet табл 10
A1: 10-кесте ШЫҒЫНДАРДЫҢ ЭКОНОМИКАЛЫҚ ЖІКТЕМЕСІ БОЙЫНША РЕСПУБЛИКАЛЫҚ БЮДЖЕТТІК ОРЫНДАЛУЫ (млн.теңге) | E1: Таблица 10 ИСПОЛНЕНИЕ РЕСПУБЛИКАНСКОГО БЮДЖЕТА ПО ЭКОНОМИЧЕСКОЙ КЛАССИФИКАЦИИ РАСХОДОВ (млн. тенге)
A3: Cанаты/_x000D_ Категория | B3: Iшкi сыныбы/_x000D_ Подкласс | C3: Ерекшелiгi/_x000D_ Специфика | D3: Атауы | F3: 2026 ж. қаңтар-ақпан/_x000D_ январь-февраль отчет 2026 г. | G3: Наименование
A4: 1 | B4: 2 | C4: 3 | D4: 4 | F4: 5 | G4: 6
D5: БАРЛЫҒЫ | F5: 3767231 | G5: ВСЕГО
A6: 1 | D6: Ағымдағы шығындар | F6: 3667713.7 | G6: Текущие затраты
A7: L01 Категория расходов | B7: 110 | D7: Жалақы | F7: 154771.97 | G7: Заработная плата
A8: 1 | B8: 110 | C8: 111 | D8: Еңбекке ақы төлеу | F8: 109597.71 | G8: Оплата труда
A9: 1 | C9: 112 | D9: Қосымша ақшалай төлемдер | F9: 26200.74 | G9: Дополнительные денежные выплаты
A10: 1 | C10: 113 | D10: Өтемақы төлемдері | F10: 17024.732 | G10: Компенсационные выплаты
A11: 1 | C11: 114 | D11: Міндетті кәсіптік зейнетақы жарналары | F11: 33.903378 | G11: Обязательные профессиональные пенсионные взносы
A12: 1 | C12: 116 | D12: Жұмыс берушілердің міндетті зейнетақы жарналары | F12: 1914.8907 | G12: Обязательные пенсионные взносы работодателей
A13: L01 Категория расходов | B13: 120 | D13: Жұмыс берушілердің жарналары | F13: 10472.848 | G13: Взносы работодателей
A14: 1 | B14: 120 | C14: 121 | D14: Әлеуметтік салық | F14: 3915.3026 | G14: Социальный налог
A15: 1 | C15: 122 | D15: Мемлекеттiк әлеуметтiк сақтандыру қорына әлеуметтiк аударымдар | F15: 4561.219 | G15: Социальные отчисления в Государственный фонд социального страхования
A16: 1 | C16: 123 | D16: Мiндеттi сақтандыру жарналары | F16: 55.086353 | G16: Взносы на обязательное страхование
A17: 1 | C17: 124 | D17: Міндетті әлеуметтік медициналық сақтандыруға аударымдар | F17: 1941.2405 | G17: Отчисления на обязательное социальное медицинское страхование
A18: L01 Категория расходов | B18: 130 | D18: Қазақстан Республикасының заңнамалық актілеріне сәйкес азаматтардың жекелеген санаттарына жалақы төлеу және жарналар аудару | F18: 7724.2276 | G18: Выплата заработной платы отдельным категориям граждан и отчисления взносов в соответствии с законодательными актами Республики Казахстан
A19: 1 | B19: 130 | C19: 131 | D19: Техникалық персоналдың және келісімшарттық қызметшілердің еңбегіне ақы төлеу | F19: 6790.5272 | G19: Оплата труда технического персонала и контрактных служащих
A20: 1 | C20: 134 | D20: Алқа билерге сыйақылар төлеу | F20: 43.169567 | G20: Выплата вознаграждений присяжным заседателям
A21: 1 | C21: 135 | D21: Техникалық персонал және келісімшарттық қызметшілер бойыншажұмыс берушілердің жарналары | F21: 829.81324 | G21: Взносы работодателей по техническому персоналу и контрактным служащим
A22: 1 | C22: 136 | D22: Техникалық персоналдың және келісімшарттық қызметшілердің ел ішіндегі іссапарлары мен қызметтiк жол жүрулері | F22: 55.272922 | G22: Командировки и служебные разъезды внутри страны технического персонала и контрактных служащих
A23: 1 | C23: 137 | D23: Алқабилердің іссапарлық шығыстары | F23: 5.444609 | G23: Командировочные расходы присяжных заседателей
